Workbook
Name _Hlk157872730: 文字計畫資訊!$B$389
Name _Hlk161528044: 文字計畫資訊!$A$235
Name _Toc383670581: 文字計畫資訊!$B$74

Sheet 計畫經費彙總表
A1: 五常物業規劃顧問股份(閉鎖型)有限公司
A2: 經費累計表(應按月編制)
A3: 中華民國113年07月01日至114年06月30日
M4: 金額單位：元
B5: 計畫預算數 | E5: 上期累計支用數(列印時請隱藏此欄位) | H5: 本期支用數 | K5: 累計支用數
A6: 預算科目 | B6: 補助款 | C6: 自籌款 | D6: 小計 | E6: 補助款 | F6: 自籌款 | G6: 小計 | H6: 補助款 | I6: 自籌款 | J6: 小計 | K6: 補助款 | L6: 自籌款 | M6: 小計
A7: 一、人事費
A8: 1.計畫人員 | B8: =計畫架構圖表!F105*1000*0.45 -> 463712.4 | C8: =計畫架構圖表!F105*1000*0.55 -> 566759.6 | D8: =B8+C8 -> 1030472 | G8: =E8+F8 -> 0 | H8: =IF(J8+G8>=D8,B8-E8,ROUND(J8/D8*B8,0)) -> 48450 | I8: =J8-H8 -> 59216 | J8: =ROUND(人事費!I13,0) -> 107666 | K8: =E8+H8 -> 48450 | L8: =F8+I8 -> 59216 | M8: =K8+L8 -> 107666
A9: 2.顧問 | B9: =計畫架構圖表!F103*0.45*1000 -> 90000 | C9: =計畫架構圖表!F103*0.55*1000 -> 110000 | D9: =B9+C9 -> 200000 | G9: =E9+F9 -> 0 | H9: =IF(J9+G9>=D9,B9-E9,ROUND(J9/D9*B9,0)) -> 9000 | I9: =J9-H9 -> 11000 | J9: =ROUND(顧問!E15,0) -> 20000 | K9: =E9+H9 -> 9000 | L9: =F9+I9 -> 11000 | M9: =K9+L9 -> 20000
A10: 二、消耗性器材及原材料費 | B10: =計畫架構圖表!F98*1000*0.45 -> 117000 | C10: =計畫架構圖表!F98*1000*0.55 -> 143000 | D10: =B10+C10 -> 260000 | G10: =E10+F10 -> 0 | H10: =IF(J10+G10>=D10,B10-E10,ROUND(J10/D10*B10,0)) -> 1706 | I10: =J10-H10 -> 2084 | J10: =ROUND(材料費!J27,0) -> 3790 | K10: =E10+H10 -> 1706 | L10: =F10+I10 -> 2084 | M10: =K10+L10 -> 3790
A11: 三、研發設備使用費 | B11: =計畫架構圖表!F99*1000/60*12/0.45 -> 65502.222 | C11: =計畫架構圖表!F99*1000/60*12*0.55 -> 16211.8 | D11: =B11+C11 -> 81714.022 | G11: =E11+F11 -> 0 | H11: =IF(J11+G11>=D11,B11-E11,ROUND(J11/D11*B11,0)) -> 4770 | I11: =J11-H11 -> 3180 | J11: =ROUND(設備使用費!K29,0) -> 7950 | K11: =E11+H11 -> 4770 | L11: =F11+I11 -> 3180 | M11: =K11+L11 -> 7950
A12: 四、研發設備維護費 | B12: =計畫架構圖表!F99*1000*0.05*0.45 -> 3316.05 | C12: =計畫架構圖表!F99*1000*0.05*0.55 -> 4052.95 | D12: =B12+C12 -> 7369 | G12: =E12+F12 -> 0 | H12: =IF(J12+G12>=D12,B12-E12,ROUND(J12/D12*B12,0)) -> 0 | I12: =J12-H12 -> 0 | J12: =ROUND(設備維護費!M16,0) -> 0 | K12: =E12+H12 -> 0 | L12: =F12+I12 -> 0 | M12: =K12+L12 -> 0
A13: 五、技術移轉費
A14: 1.技術或智慧財產權購買費 | B14: =計畫架構圖表!F101*1000*0.45 -> 450000 | C14: =計畫架構圖表!F101*1000*0.55 -> 550000 | D14: =B14+C14 -> 1000000 | G14: =E14+F14 -> 0 | H14: =IF(J14+G14>=D14,B14-E14,ROUND(J14/D14*B14,0)) -> 135000 | I14: =J14-H14 -> 165000 | J14: =ROUND(技術購買費!F15,0) -> 300000 | K14: =E14+H14 -> 135000 | L14: =F14+I14 -> 165000 | M14: =K14+L14 -> 300000
A15: 2.委託研究費 | B15: =計畫架構圖表!F100*1000*0.45 -> 225000 | C15: =計畫架構圖表!F100*1000*0.55 -> 275000 | D15: =B15+C15 -> 500000 | G15: =E15+F15 -> 0 | H15: =IF(J15+G15>=D15,B15-E15,ROUND(J15/D15*B15,0)) -> 157500 | I15: =J15-H15 -> 192500 | J15: =ROUND(委託研究費!F15,0) -> 350000 | K15: =E15+H15 -> 157500 | L15: =F15+I15 -> 192500 | M15: =K15+L15 -> 350000
A16: 3.委託勞務費 | B16: =計畫架構圖表!F98*1000*45% -> 117000 | C16: =計畫架構圖表!F98*1000*55% -> 143000 | D16: =B16+C16 -> 260000 | G16: =E16+F16 -> 0 | H16: =IF(J16+G16>=D16,B16-E16,ROUND(J16/D16*B16,0)) -> 117000 | I16: =J16-H16 -> 283000 | J16: =ROUND(委託勞務費!F15,0) -> 400000 | K16: =E16+H16 -> 117000 | L16: =F16+I16 -> 283000 | M16: =K16+L16 -> 400000
A17: 六、差旅費
A18: 1.國內差旅費 | B18: 5000 | C18: 10000 | D18: =B18+C18 -> 15000 | G18: =E18+F18 -> 0 | H18: =IF(J18+G18>=D18,B18-E18,ROUND(J18/D18*B18,0)) -> 617 | I18: =J18-H18 -> 1233 | J18: =ROUND(國內差旅費!N14,0) -> 1850 | K18: =E18+H18 -> 617 | L18: =F18+I18 -> 1233 | M18: =K18+L18 -> 1850
A19: 2.國外差旅費 | C19: 0 | D19: =B19+C19 -> 0 | G19: =E19+F19 -> 0 | H19: 0 | I19: =J19-H19 -> 2000 | J19: =ROUND(國外差旅費!N14,0) -> 2000 | K19: =E19+H19 -> 0 | L19: =F19+I19 -> 2000 | M19: =K19+L19 -> 2000
A20: 七、市場驗證費 | B20: =計畫架構圖表!F102*1000*0.45 -> 253890 | C20: =計畫架構圖表!F102*1000*0.55 -> 310310 | D20: =B20+C20 -> 564200 | G20: =E20+F20 -> 0 | H20: =IF(J20+G20>=D20,B20-E20,ROUND(J20/D20*B20,0)) -> 3240 | I20: =J20-H20 -> 3960 | J20: =ROUND(市場驗證費!J18,0) -> 7200 | K20: =E20+H20 -> 3240 | L20: =F20+I20 -> 3960 | M20: =K20+L20 -> 7200
A21: 合 計 | B21: =SUM(B8:B20) -> 1790420.7 | C21: =SUM(C8:C20) -> 2128334.4 | D21: =SUM(D8:D20) -> 3918755 | E21: =SUM(E8:E20) -> 0 | F21: =SUM(F8:F20) -> 0 | G21: =SUM(G8:G20) -> 0 | H21: =SUM(H8:H20) -> #VALUE! | I21: =SUM(I8:I20) -> #VALUE! | ... M21: =SUM(M8:M20) -> #VALUE!
A23: 註1:金額以元為單位。
A24: 註2:補助款及自籌款出現#DIV/0!之欄位請填0。
A25: 註3:請填寫綠色填滿之欄位，電腦會自動編列小計。
A26: 註4:列印時請隱藏「上期累計實支數」之欄位
A28: 公司負責人: | C28: 計畫主持人: | H28: 主辦會計: | K28: 填表人：

Sheet 計畫架構圖表
B1: 創新AI系統整合營運中心服務機制開發運用計畫
P2: 單位/千元
B3: 計畫項目 | C3: =人事費!A7 -> 1.阮氏泉 | E3: 7月 | F3: 8月 | G3: 9月 | H3: 10月 | I3: 11月 | J3: 12月 | K3: 1月 | L3: 2月 | M3: 3月 | N3: 4月 | O3: 5月 | P3: 6月
C4: A分項計畫 商業資訊中心設置計畫 | Q4: 合計 | R4: 細項小計及權重
C5: A1直營商店營運權力取得及技術轉移7/10 | D5: 人 | E5: 0.25 | J5: 0.25 | Q5: =SUM(E5:P5)*49.849 -> 24.9245 | R5: =Q5+Q6 -> 1024.9245
D6: 費 | E6: 500 | J6: 500 | Q6: =SUM(E6:E6:P6) -> 1000 | R6: =R5/F106 -> 0.27243762
C7: A2直營咖啡店營運、進行員工教學及產品開發研究、並導入點餐系統8/1 | D7: 人 | F7: 0.4 | G7: 0.4 | H7: 0.4 | I7: 0.4 | J7: 0.4 | K7: 0.4 | L7: 0.4 | M7: 0.4 | N7: 0.4 | O7: 0.4 | P7: 0.5 | Q7: =SUM(E7:P7)*49.849 -> 224.3205 | R7: =Q7+Q8 -> 484.3205
D8: 費 | F8: 26 | G8: 26 | H8: 26 | I8: 26 | J8: 26 | K8: 26 | L8: 26 | M8: 26 | N8: 26 | O8: 26 | Q8: =SUM(E8:P8) -> 260 | R8: =R7/F106 -> 0.12873839
C9: A3轄內商業資訊收集建檔及資料分析11/1 | D9: 人 | F9: 0.25 | G9: 0.25 | H9: 0.25 | I9: 0.25 | Q9: =SUM(E9:P9)*49.849 -> 49.849 | R9: =Q9+Q10 -> 49.849
D10: 費 | Q10: =SUM(E10:P10) -> 0 | R10: =R9/F106 -> 0.013250481
C11: A4開發商業會員參與聯合營運計畫10/1 | D11: 人 | E11: 0.25 | F11: 0.25 | G11: 0.25 | H11: 0.25 | Q11: =SUM(E11:P11)*49.849 -> 49.849 | R11: =Q11+Q10 -> 49.849
D12: 費 | Q12: =SUM(E12:P12) -> 0 | R12: =R11/F106 -> 0.013250481
C13: A5完成全區域內商業分析報告及擬定顧問企劃，提高直營商業營業額至每月20萬元。4/1 | D13: 人 | J13: 0.25 | K13: 0.25 | Q13: =SUM(E13:P13)*49.9849 -> 24.99245 | R13: =Q13+Q14 -> 24.99245
D14: 費 | Q14: =SUM(E14:P14) -> 0 | R14: =R13/F106 -> 0.0066433026
C15: A6出席研討會並收集本分項計畫有關之訊息6/10 | D15: 人 | O15: 0.25 | P15: 0.25 | Q15: =SUM(E15:P15)*49.849 -> 24.9245 | R15: =Q15+Q16 -> 24.9245
D16: 費 | Q16: =SUM(E16:P16) -> 0 | R16: =R15/F106 -> 0.0066252407
C17: 合計人月 | E17: =E5+E7+E9+E11+E13+E15 -> 0.5 | F17: =F5+F7+F9+F11+F13+F15 -> 0.9 | G17: =G5+G7+G9+G11+G13+G15 -> 0.9 | H17: =H5+H7+H9+H11+H13+H15 -> 0.9 | I17: =I5+I7+I9+I11+I13+I15 -> 0.65 | J17: =J5+J7+J9+J11+J13+J15 -> 0.9 | K17: =K5+K7+K9+K11+K13+K15 -> 0.65 | L17: =L5+L7+L9+L11+L13+L15 -> 0.4 | ... P17: =P5+P7+P9+P11+P13+P15 -> 0.75 | Q17: =SUM(E17:P17) -> 8
C18: 合計薪資 | E18: =E17*49.849 -> 24.9245 | F18: =F17*49.849 -> 44.8641 | G18: =G17*49.849 -> 44.8641 | H18: =H17*49.849 -> 44.8641 | I18: =I17*49.849 -> 32.40185 | J18: =J17*49.849 -> 44.8641 | K18: =K17*49.849 -> 32.40185 | L18: =L17*49.849 -> 19.9396 | ... Q18: =Q17*49.849 -> 398.792 | S18: 113年度 | T18: =SUM(E18:J19) -> 1366.7828
C19: 非屬薪資 | E19: =E6+E8+E10+E12+E14+E16 -> 500 | F19: =F6+F8+F10+F12+F14+F16 -> 26 | G19: =G6+G8+G10+G12+G14+G16 -> 26 | H19: =H6+H8+H10+H12+H14+H16 -> 26 | I19: =I6+I8+I10+I12+I14+I16 -> 26 | J19: =J6+J8+J10+J12+J14+J16 -> 526 | K19: =K6+K8+K10+K12+K14+K16 -> 26 | L19: =L6+L8+L10+L12+L14+L16 -> 26 | ... Q19: =Q6+Q8+Q10+Q12+Q14+Q16 -> 1260 | S19: 114年度 | T19: =SUM(K18:P19) -> 292.00925
C20: 費用小計 | E20: =SUM(E18:E19) -> 524.9245 | F20: =SUM(F18:F19) -> 70.8641 | G20: =SUM(G18:G19) -> 70.8641 | H20: =SUM(H18:H19) -> 70.8641 | I20: =SUM(I18:I19) -> 58.40185 | J20: =SUM(J18:J19) -> 570.8641 | K20: =SUM(K18:K19) -> 58.40185 | L20: =SUM(L18:L19) -> 45.9396 | ... O20: =SUM(O18:O19) -> 58.40185 | P20: 分項合計 | Q20: =SUM(Q18:Q19) -> 1658.792 | T20: =T18+T19 -> 1658.792
B22: 計畫項目 | C22: =人事費!A9 -> 3.蔣明諺 | E22: 7月 | F22: 8月 | G22: 9月 | H22: 10月 | I22: 11月 | J22: 12月 | K22: 1月 | L22: 2月 | M22: 3月 | N22: 4月 | O22: 5月 | P22: 6月
C23: B分項計畫 物業安全中心設置 | R23: 細項小計及權重
C24: B1物業管理及保全協力廠商探詢及轄內物業管理8/1 | D24: 人 | E24: 0.25 | F24: 0.5 | G24: 0.25 | Q24: =SUM(E24:P24)*人事費!E9/1000 -> 43.84 | R24: =Q24+Q25 -> 43.84
D25: 費 | Q25: =SUM(E25:P25) -> 0 | R25: =R24/F106 -> 0.011653215
C26: B2分析各管委會及承攬物業資訊製作物業資訊庫10/1 | D26: 人 | E26: 0.25 | G26: 0.25 | Q26: =SUM(E26:P26)*人事費!E9/1000 -> 21.92 | R26: =Q26+Q27 -> 21.92
D27: 費 | Q27: =SUM(E27:P27) -> 0 | R27: =R26/F106 -> 0.0058266074
C28: B3選定5家測試合作業物業並前往洽談合作事宜10/15 | D28: 人 | G28: 0.25 | H28: 0.25 | Q28: =SUM(E28:P28)*人事費!E9/1000 -> 21.92 | R28: =Q28+Q29 -> 21.92
D29: 費 | Q29: =SUM(E29:P29) -> 0 | R29: =R28/F106 -> 0.0058266074
C30: B4進行全區域的物業拜訪開拓創新社區安全網業務11/1 | D30: 人 | I30: 0.25 | J30: 0.25 | K30: 0.25 | L30: 0.25 | M30: 0.25 | N30: 0.25 | O30: 0.25 | P30: 0.25 | Q30: =SUM(E30:P30)*人事費!E9/1000 -> 87.68 | R30: =Q30+Q27 -> 87.68
D31: 費 | Q31: =SUM(E31:P31) -> 0 | R31: =R30/F106 -> 0.02330643
C32: B5完成全區域內物業分析報告及擬定安保顧問企劃3/11 | D32: 人 | L32: 0.25 | M32: 0.25 | Q32: =SUM(E32:P32)*人事費!E9/1000 -> 21.92 | R32: =Q32+Q86 -> 21.92
D33: 費 | Q33: =SUM(E33:P33) -> 0 | R33: =R32/F106 -> 0.0058266074
C34: B6出席研討會並收集本分項計畫有關之訊息6/10 | D34: 人 | O34: 0.25 | P34: 0.25 | Q34: =SUM(E34:P34)*人事費!E9/1000 -> 21.92 | R34: =Q34+Q35 -> 21.92
D35: 費 | Q35: =SUM(E35:P35) -> 0 | R35: =R34/F106 -> 0.0058266074
C36: 合計人月 | E36: =E24+E26+E28+E30+E32+E34 -> 0.5 | F36: =F24+F26+F28+F30+F32+F34 -> 0.5 | G36: =G24+G26+G28+G30+G32+G34 -> 0.75 | H36: =H24+H26+H28+H30+H32+H34 -> 0.25 | I36: =I24+I26+I28+I30+I32+I34 -> 0.25 | J36: =J24+J26+J28+J30+J32+J34 -> 0.25 | K36: =K24+K26+K28+K30+K32+K34 -> 0.25 | L36: =L24+L26+L28+L30+L32+L34 -> 0.5 | ... P36: =P24+P26+P28+P30+P32+P34 -> 0.5 | Q36: =SUM(E36:P36) -> 5
C37: 合計薪資 | E37: =E36*人事費!E9/1000 -> 21.92 | F37: =F36*人事費!E9/1000 -> 21.92 | G37: =G36*人事費!E9/1000 -> 32.88 | H37: =H36*人事費!E9/1000 -> 10.96 | I37: =I36*人事費!E9/1000 -> 10.96 | J37: =J36*人事費!E9/1000 -> 10.96 | K37: =K36*人事費!E9/1000 -> 10.96 | L37: =L36*人事費!E9/1000 -> 21.92 | M37: =N36*人事費!E9/1000 -> 10.96 | N37: =N36*人事費!E9/1000 -> 10.96 | O37: =O36*人事費!E9/1000 -> 21.92 | P37: =P36*人事費!E9/1000 -> 21.92 | Q37: =Q36*人事費!E9/1000 -> 219.2 | S37: 113年度 | T37: =SUM(E37:K38) -> 120.56
C38: 非屬薪資 | E38: =E25+E27+E29+E31+E33+E35 -> 0 | F38: =F25+F27+F29+F31+F33+F35 -> 0 | G38: =G25+G27+G29+G31+G33+G35 -> 0 | H38: =H25+H27+H29+H31+H33+H35 -> 0 | I38: =I25+I27+I29+I31+I33+I35 -> 0 | J38: =J25+J27+J29+J31+J33+J35 -> 0 | K38: =K25+K27+K29+K31+K33+K35 -> 0 | L38: =L25+L27+L29+L31+L33+L35 -> 0 | ... Q38: =Q25+Q27+Q29+Q31+Q33+Q35 -> 0 | S38: 114年度 | T38: =SUM(K37:P38) -> 98.64
C39: 費用小計 | E39: =SUM(E37:E38) -> 21.92 | F39: =SUM(F37:F38) -> 21.92 | G39: =SUM(G37:G38) -> 32.88 | H39: =SUM(H37:H38) -> 10.96 | I39: =SUM(I37:I38) -> 10.96 | J39: =SUM(J37:J38) -> 10.96 | K39: =SUM(K37:K38) -> 10.96 | L39: =SUM(L37:L38) -> 21.92 | ... O39: =SUM(O37:O38) -> 21.92 | P39: 分項合計 | Q39: =SUM(Q37:Q38) -> 219.2 | T39: =T37+T38 -> 219.2
B41: 計畫項目 | C41: =人事費!A11 -> 5.李道翔 | E41: 7月 | F41: 8月 | G41: 9月 | H41: 10月 | I41: 11月 | J41: 12月 | K41: 1月 | L41: 2月 | M41: 3月 | N41: 4月 | O41: 5月 | P41: 6月
C42: C分項計畫 資訊、勞務系統開發 | R42: 細項小計及權重
...

Sheet 文字計畫資訊
F2: 限閱文件
B3: 經濟部科技研究發展專案
B5: 產業升級創新平台輔導計畫(新興育成)
B8: 運用AI智能系統整合勞務產能有效降低物業(商業)安全維護(聯合雲端銷售)成本並提高服務品質開發計畫(草 案)
B15: 計畫期間：自113 年 7月 1日至 114年 7 月 1 日止
B22: 公司名稱：五常物業規劃管理顧問股份有限公司
B23: 計畫管理單位：財團法人台灣中小企業聯合輔導基金會
B26: 中 華 民 國113年 4月
D29: 運用AI智能系統整合勞務產能有效降低物業(商業)安全維護(聯合雲端銷售)成本並提高服務品質開發計畫︵草案︶ 公司名稱 五常物業規劃顧問股份有限公司
A73: 計劃書摘要表
B74: 綜合資料
F75: 金額單位：千元
A76: 計畫名稱 | C76: 運用AI智能系統整合勞務產能有效降低物業(商業)安全維護(聯合雲端銷售)成本並提高服務品質開發計畫
A77: 公司名稱 | C77: 五常物業管理規劃顧問股份有限公司 | F77: 通訊地址：24151新北市三重區五常里28鄰仁義街161號1樓
A78: 法人名稱 | C78: 新北市三重區五常社區發展協會 | F78: 通訊地址：24151新北市三重區五常里28鄰仁義街161號1樓
A79: 計畫起～訖時間 | C79: 113年7月1日～114年7月1日 （共12個月）
A80: 計畫主持人 | C80: 姓名 | D80: 江政隆 | F80: 電話 | I80: (02)29866856
C81: 職稱 | D81: 營運長 | F81: 電子信箱 | I81: wuchang1100606355@gmail.com
A82: 協同計畫主持人 | C82: 姓名 | D82: 林詩妘 | F82: 電話 | I82: 907565121
C83: 職稱 | D83: 協理 | F83: 電子信箱
A84: 年度經費 | C84: 政 府 | E84: 公 司 | H84: 計 畫
C85: 補助款 | E85: 自籌款 | H85: 總經費
A86: 113年度 | C86: =H86-E86 -> 1165.0548 | E86: =H86*0.55 -> 1423.9559 | H86: =計畫架構圖表!L100 -> 2589.0107
C87: (法人)
A88: 114年度 | C88: =H88-E88 -> 410.56444 | E88: =H88*65% -> 762.47681 | H88: =計畫架構圖表!M100 -> 1173.0412
C89: (法人)
A90: ＸＸ年度 | C90: (公司)
C91: (法人)
A92: 合 計
A93: 占 總 經 | C93: 0.45 | E93: 0.55 | H93: 1
A94: 費 比 重%
A95: 計畫聯絡人 | C95: 姓名 | D95: 周誼芬 | F95: 電話 | I95: (02)29866856
C96: 職稱 | D96: 財務協理 | F96: 電子信箱
A97: 一、公司簡介
B98: (一)公司名稱：五常物業管理規劃顧問股份有限公司
B99: (二)核准設立日期：113年 月 日
B100: (三)代表人：阮氏泉
B101: (四)主要營業項目：
B102: 物業及商業管理規劃顧問業、法人或公司行政業務承攬業、餐飲服務及加工業、物業管理或商業經營衍生服務產業、區域健康照護業務規劃業、廢棄物清理業、人力資源規劃業
A103: 二、產業與市場需求
...

Sheet 營運財務規劃預測
A1: 五常物業規劃股份有限公司營運預算書
A2: 借方統計表 單位：新台幣元
A3: 門 | B3: 款 | C3: 項 | D3: 科目 | E3: 第一年 | F3: 第二年 | G3: 備註
A4: 1 | B4: 1 | C4: 1 | D4: 商業收入 | E4: =2400000/2+90000 -> 1290000 | F4: =3000000+180000 -> 3180000 | G4: 按聊閣重新店經驗每月編列20萬元
D5: 商業顧問服務費 | E5: 0 | F5: =3000*3*12 -> 108000 | K5: 咖啡店
A6: 1 | B6: 1 | C6: 2 | D6: 物業及委託收入 | E6: =1200000/2 -> 600000 | F6: 1800000 | G6: 協會全年計畫規模約為200萬元，依合約收入20萬元 | K6: =E4-E30-E31-E39-E42-E51+120000 -> 512360.8
G7: 物業合約目前僅有1案全年36萬元 | K7: 初期成本
A8: 1 | B8: 2 | C8: 1 | D8: 補助收入 | E8: =計畫架構圖表!L100*1000*40% -> 1035604.3 | F8: =(計畫架構圖表!M100*40%*1000)+510000+200000 -> 1179216.5 | G8: SIIR計畫114年度餘額加上3.4萬X15=51萬元；及銀髮、婦女各10萬元業務費用 | K8: =E46+E47+E48-200000 -> 1006900
A9: 營業收入項小計 | E9: =SUM(E4:E8) -> 2925604.3 | F9: =SUM(F4:F8) -> 6267216.5
A10: 1 | B10: 2 | C10: 2 | D10: 其他收入 | G10: 不做預估 | K10: 政隆
A11: 1 | B11: 2 | C11: 3 | D11: 代收款項 | G11: 勞健保勞工負擔及勞退自提 | K11: 需出資額 | L11: 半年收益 | M11: 平均月收益
A12: 1 | B12: 2 | C12: 4 | D12: 孳息 | G12: 不做預估 | K12: =K8*60% -> 604140 | L12: =K6*60% -> 307416.48 | M12: =L12/6 -> 51236.08
D13: 資本公積
A14: 資本項目
A15: 3 | B15: 3 | C15: 1 | D15: 股本收入 | E15: 6000000 | G15: 一般股500,000股，面額10元 | K15: 明諺
G16: 特別股 100,000股，面額10元 | K16: 需出資額 | L16: 半年收益 | M16: 平均月收益
A17: 1 | B17: 4 | C17: 1 | D17: 永續發展基金(法定盈餘) | E17: 0 | G17: 不做預估
B18: 3 | C18: 3 | D18: 上期結餘 | E18: 0 | F18: =E70 -> 2069919 | G18: 不做預估 | K18: =60/0.4 -> 150
A19: 資本項小計 | E19: =SUM(E15:E18) -> 6000000 | F19: =SUM(F15:F18) -> 2069919
A20: 1 | B20: 4 | C20: 2 | D20: 勞工組織發展基金 | E20: 0 | F20: 0 | G20: 由勞工組織決定額度，本司提撥相同金額騎出暫定每名/月提撥500元，本項由盈餘勞工分配額提撥
A21: 1 | B21: 4 | C21: 3 | D21: 代管基金 | E21: 0 | F21: 0 | G21: 收託代管基金，如大樓管委會託管、五常社區發展基金
A22: 各類基金項小計 | E22: =SUM(E20:E21) -> 0 | F22: =SUM(F20:F21) -> 0
A23: 借方總計 | E23: =E9+E19+E22 -> 8925604.3 | F23: =F9+F19+F22 -> 8337135.5
A24: 貸方統計表 單位：新台幣元
A26: 2 | D26: 營業費用
A27: 2 | B27: 1 | D27: 人事費
A28: 2 | B28: 1 | C28: 1 | D28: 薪資支出A項 | E28: =SUM(人事費!B7:B12)*6 -> 835200 | F28: =SUM(人事費!B7:B12)*12 -> 1670400 | G28: 27,740*5
A29: 2 | B29: 1 | C29: 2 | D29: 薪資支出B項 | E29: =SUM(人事費!C7:C12)*6 -> 492000 | F29: =SUM(人事費!C7:C12)*12 -> 984000 | G29: 董事長20營運長18經理16協理14高等專員12初等專員10
A30: 2 | B30: 1 | C30: 3 | D30: 勞工保險費 | E30: =(E28+E29)*0.11*0.6 -> 87595.2 | F30: =(F28+F29)*0.11*0.6 -> 175190.4 | G30: 董事長1、營運長1、經理1、協理1、初專1
A31: 2 | B31: 1 | C31: 4 | D31: 勞工健保費 | E31: =(E28+E29)*0.02 -> 26544 | F31: =(F28+F29)*0.02 -> 53088 | G31: 董事長1、營運長1、經理1、協理1、初專1
A32: 2 | B32: 1 | C32: 5 | D32: 勞工組織費 | E32: 15000 | F32: 30000 | G32: 每人500
A33: 2 | B33: 1 | C33: 6 | D33: 勞工分紅及福利費用 | E33: 0 | F33: 0
A34: 2 | B34: 1 | C34: 7 | D34: 勞工教育訓練費 | E34: =計畫架構圖表!E84+計畫架構圖表!F84*1000 -> 30030 | F34: 80000
A35: 人事費用小計 | E35: =SUM(E28:E34) -> 1486369.2 | F35: =SUM(F28:F34) -> 2992678.4
A36: 2 | B36: 2 | D36: 辦公費
A37: 2 | B37: 2 | C37: 1 | D37: 辦公設備維護 | E37: =(E48-400000)*0.05 -> 16845 | F37: 20000 | G37: 筆電3X50K=150K,桌椅20K | M37: =365*500 -> 182500
B38: 2 | C38: 2 | D38: 行政耗材費 | E38: 5000 | F38: 5000 | G38: 文具、影印紙、文書器材
B39: 2 | C39: 3 | D39: 水電費 | E39: =12000*6 -> 72000 | F39: =12000*12 -> 144000 | G39: 每月1.2萬計
B40: 2 | C40: 4 | D40: 勞工副食費 | E40: =F40/2 -> 91250 | F40: =365*500 -> 182500 | G40: 每人每日100計，用餘歸直營商店營收
D41: 設備維護費 | E41: =E37*0.05/2 -> 421.125 | F41: =E37*0.05 -> 842.25
...

Sheet 人事費
A1: =計畫經費彙總表!A1 -> 五常物業規劃顧問股份(閉鎖型)有限公司
A2: SIIR計畫－計畫人員薪資計算表 (113年07月)
I3: 金額單位:元
A4: 傳票日期 | C4: 傳票編號
A5: 計畫人員姓 名 | B5: 本(底)薪 A | C5: 職務加給或 技術津貼 B | D5: 主管加給 C | E5: 月薪小計 D=A+B+C | F5: 投入比率 (註1) I | G5: 可列入本計畫之薪餉J=D*I | H5: 本計畫加班費 K | I5: 應計入本計畫薪資 L=J+K
A7: 1.阮氏泉 | B7: 27840 | C7: 20000 | D7: 2000 | E7: =SUM(B7:D7) -> 49840 | F7: =計畫架構圖表!E17 -> 0.5 | G7: =ROUND(E7*F7,0) -> 24920 | H7: =加班記錄!I5 -> 0 | I7: =SUM(G7:H7) -> 24920
A8: 2.江政隆 | B8: 27840 | C8: 18000 | D8: 1000 | E8: =SUM(B8:D8) -> 46840 | F8: =計畫架構圖表!E93 -> 0.4 | G8: =E8*F8 -> 18736 | H8: =加班記錄!I6 -> 0 | I8: =SUM(G8:H8) -> 18736
A9: 3.蔣明諺 | B9: 27840 | C9: 16000 | D9: 0 | E9: =SUM(B9:D9) -> 43840 | F9: =計畫架構圖表!E36 -> 0.5 | G9: =ROUND(E9*F9,0) -> 21920 | H9: =加班記錄!I7 -> 0 | I9: =SUM(G9:H9) -> 21920
A10: 4.林詩妘 | B10: 27840 | C10: 14000 | D10: 0 | E10: =SUM(B10:D10) -> 41840 | F10: =計畫架構圖表!E55 -> 0.75 | G10: =ROUND(E10*F10,0) -> 31380 | H10: =加班記錄!I8 -> 0 | I10: =SUM(G10:H10) -> 31380
A11: 5.李道翔 | B11: 27840 | C11: 14000 | D11: 1000 | E11: =SUM(B11:D11) -> 42840 | F11: =計畫架構圖表!E74 -> 0.25 | G11: =ROUND(E11*F11,0) -> 10710 | H11: =加班記錄!I9 -> 0 | I11: =SUM(G11:H11) -> 10710
D12: 0 | E12: =SUM(B12:D12) -> 0 | F12: =工時記錄表!AI10 -> 0 | G12: =ROUND(E12*F12,0) -> 0 | H12: =加班記錄!I10 -> 0 | I12: =SUM(G12:H12) -> 0
A13: 合 計 | B13: =SUM(B6:B12) -> 139200 | C13: =SUM(C7:C12) -> 82000 | D13: =SUM(D7:D12) -> 4000 | E13: =SUM(E7:E12) -> 225200 | F13: =SUM(F7:F12) -> 2.4 | G13: =SUM(G7:G12) -> 107666 | H13: =SUM(H7:H12) -> 0 | I13: =ROUND(SUM(I6:I12),0) -> 107666
A15: 註1：投入比率應與工時記錄表合計當月份一致。每月投入比率以1為上限。
A16: 註2：帳務查核時應備妥下列文件備查: 1.薪資清冊(內容包含：發放之薪資結構明細計算)
A17: 2.銀行轉帳記錄或印領清冊
A19: 計畫主持人: | E19: 主辦會計: | I19: 填表人：

Sheet 加班記錄
A1: =計畫經費彙總表!A1 -> 五常物業規劃顧問股份(閉鎖型)有限公司
A2: SIIR計畫人員加班記錄總表 (112年××月)
I3: 金額單位:元
A4: 計畫人員姓 名 | B4: 加班事由 | F4: 加班時數 | G4: 加班費計算公式 | I4: 本計畫之加班費 | J4: 計畫人員簽名
A5: =人事費!A7 -> 1.阮氏泉
A6: =人事費!A8 -> 2.江政隆
A7: =人事費!A9 -> 3.蔣明諺
A8: =人事費!A10 -> 4.林詩妘
A9: =人事費!A11 -> 5.李道翔
A10: =人事費!A12 -> 0
A11: 合 計 | I11: =ROUND(SUM(I5:I10),0) -> 0
A13: 計畫主持人: | D13: 主辦會計: | H13: 填表人：

Sheet 顧問
A1: =計畫經費彙總表!A1 -> 五常物業規劃顧問股份(閉鎖型)有限公司
A2: SIIR計畫－顧問費(113年6月)
E3: 金額單位:元
A4: 姓名 | B4: 傳票日期 | C4: 傳票編號 | D4: 摘要 | E4: 合 計
A6: 官釗鈱 | E6: 10000
A7: 官釗鈱 | E7: 10000
A8: 官釗鈱
A9: 官釗鈱
A10: 官釗鈱
A11: 官釗鈱
A12: 官釗鈱
A15: 合 計 | E15: =ROUND(SUM(E6:E14),0) -> 20000
A17: 註1：帳務查核時應備妥下列文件備查:1.領款收據（應書明受領事由、受領人名、地址、
A18: 身份證編號，由受領人簽名 或蓋章） 2.證明支付金額之文件(ex:銀行匯款單據)
A19: 註2：顧問任職單位同意函。
A21: 計畫主持人: | C21: 主辦會計: | E21: 填表人：

Sheet 工時記錄表
A1: =計畫經費彙總表!A1 -> 五常物業規劃顧問股份(閉鎖型)有限公司
A2: SIIR計畫工時記錄表(112年07月)
A3: 姓名 | B3: 1 | C3: 2 | D3: 3 | E3: 4 | F3: 5 | G3: 6 | H3: 7 | I3: 8 | J3: 9 | K3: 10 | L3: 11 | M3: 12 | N3: 13 | O3: 14 | P3: 15 | Q3: 16 | R3: 17 | S3: 18 | T3: 19 | U3: 20 | V3: 21 | W3: 22 | X3: 23 | Y3: 24 | Z3: 25 | AA3: 26 | AB3: 27 | AC3: 28 | AD3: 29 | AE3: 30 | AF3: 31 | AG3: 合計 | AH3: 正常工作時數 | AI3: 投入 比率 | AJ3: 簽名欄
A5: =人事費!A7 -> 1.阮氏泉 | AG5: =SUM(B5:AF5) -> 0 | AH5: 160 | AI5: =AG5/AH5 -> 0
A6: =人事費!A8 -> 2.江政隆 | AG6: =SUM(B6:AF6) -> 0 | AH6: 160 | AI6: =AG6/AH6 -> 0
A7: =人事費!A9 -> 3.蔣明諺 | AG7: =SUM(B7:AF7) -> 0 | AH7: 160 | AI7: =AG7/AH7 -> 0
A8: =人事費!A10 -> 4.林詩妘 | AG8: =SUM(B8:AF8) -> 0 | AH8: 160 | AI8: =AG8/AH8 -> 0
A9: =人事費!A11 -> 5.李道翔
A17: 合計 | B17: =SUM(B5:B16) -> 0 | C17: =SUM(C5:C16) -> 0 | D17: =SUM(D5:D16) -> 0 | E17: =SUM(E5:E16) -> 0 | F17: =SUM(F5:F16) -> 0 | G17: =SUM(G5:G16) -> 0 | H17: =SUM(H5:H16) -> 0 | I17: =SUM(I5:I16) -> 0 | ... AG17: =SUM(AG5:AG16) -> 0 | AI17: =SUM(AI5:AI16) -> 0
A19: 註1.請假不論事由，請假時數均不得列入本計畫投入工時計算。
A20: 註2.公司加班如另發加班費則上表所統計之工時不含加班時數；如採補休方式則加班時數應計入，補休時則視同請假處理。
A21: 註3.每月投入比率最高為1.00。
A22: 註4.請計畫人員確認工時記錄後於簽名欄位簽名
E24: 計畫主持人: | S24: 主辦會計: | AD24: 填表人：

Sheet 材料費
A1: =計畫經費彙總表!A1 -> 五常物業規劃顧問股份(閉鎖型)有限公司
A2: SIIR計畫－消耗性器材及原材料費(113年7月)
J3: 金額單位:元
A4: 傳票日期 | B4: 傳票號碼 | C4: 發票日期 (領料日期) | D4: 發票編號 (領料單號) | E4: 供應商 | F4: 發票品名 (註2) | G4: 對照計畫書所列項目 (註1) | H4: 數量 | I4: 單價(材料明細或分攤表) | J4: 金額 (不含營業稅)
A6: 113.7.1 | B6: 1120424002 | C6: 112.7.01 | D6: AA001 | E6: ×× | F6: 招牌咖啡豆 | G6: 咖啡豆 | H6: 5 | I6: 200 | J6: =I6*H6 -> 1000
A7: 113.7.1 | B7: 1120424002 | C7: 113.7.01 | D7: AB001 | E7: ×× | F7: 品黃奶精 | G7: 奶精 | H7: 1 | I7: 1130 | J7: =I7*H7 -> 1130
A8: 113.7.1 | B8: 1120424002 | C8: 113.7.01 | D8: AB002 | F8: 光泉鮮奶 | G8: 鮮奶 | H8: 20 | I8: 53 | J8: =I8*H8 -> 1060
A9: 113.7.1 | B9: 1120424002 | C9: 113.7.01 | D9: AC001 | F9: 冷杯S | G9: 外帶杯 | H9: 50 | I9: 2 | J9: =I9*H9 -> 100
A10: 113.7.1 | B10: 1120424002 | C10: 113.7.01 | D10: AC002 | F10: 冷杯M | G10: 外帶杯 | H10: 50 | I10: 2 | J10: =I10*H10 -> 100
A11: 113.7.1 | B11: 1120424002 | C11: 112.7.01 | D11: AC003 | F11: 冷杯L | G11: 外帶杯 | H11: 50 | I11: 2 | J11: =I11*H11 -> 100
A12: 113.7.1 | B12: 1120424002 | C12: 113.7.01 | D12: AC011 | F12: 熱杯S | G12: 外帶杯 | H12: 50 | I12: 2 | J12: =I12*H12 -> 100
A13: 113.7.1 | B13: 1120424002 | C13: 113.7.01 | D13: AC012 | F13: 熱杯M | G13: 外帶杯 | H13: 50 | I13: 2 | J13: =I13*H13 -> 100
A14: 113.7.1 | B14: 1120424002 | C14: 113.7.01 | D14: AC013 | F14: 熱杯L | G14: 外帶杯 | H14: 50 | I14: 2 | J14: =I14*H14 -> 100
J15: =I15*H15 -> 0
J16: =I16*H16 -> 0
J17: =I17*H17 -> 0
J18: =I18*H18 -> 0
J19: =I19*H19 -> 0
J20: =I20*H20 -> 0
J21: =I21*H21 -> 0
J22: =I22*H22 -> 0
J23: =I23*H23 -> 0
J24: =I24*H24 -> 0
J25: =I25*H25 -> 0
J26: =I26*H26 -> 0
A27: 合 計 | J27: =ROUND(SUM(J5:J26),0) -> 3790
A29: 註1：「對照計畫書所列項目」名稱需與計畫書所列之材料項目名稱一致。
A30: 註2：「發票品名」請依發票填寫所列項目。
A31: 註3：如屬公司共通性材料領用，發票日期、發票號碼請改填寫領料單日期、領料單號碼
A32: 註4：營業稅不得報支。
A33: 註5：辦公室所需之事務性耗材不得報支。
A34: 註6：帳務查核時應備妥下列文件備查:1.為專案計畫採購者應提供統一發票、收據或進口結匯單據與invoice、 及內部轉帳傳票、請購單、採購單
A35: 及驗收單足以證明之憑證。 2.自共通性器材領料應提供：領料單、材料明細帳或分攤表。3.涉及外幣支付時應附當時之外幣匯率表。
B37: 計畫主持人: | F37: 主辦會計: | I37: 填表人：

Sheet 設備使用費
A1: =計畫經費彙總表!A1 -> 五常物業規劃顧問股份(閉鎖型)有限公司
A2: SIIR計畫－設備使用費(1)---已有設備(112年××月)
K3: 金額單位:元
A4: 傳票日期 | C4: 傳票編號
A5: 財產編號 | B5: 設備名稱 | C5: 對照計畫書所列項目 | D5: 取得日期 | E5: 購入成本 (單套) | F5: 套數 A1 | G5: 投入時 單套帳面價值 （未折減餘額） A2 | H5: 剩餘使用月數 | I5: 每月攤提使用費 A3=A1*A2*/剩餘使用月數 (詳如註3) | J5: 本期投入比率 A4 | K5: 本期使用費 A5=A3*A4
A7: (1)1130001 | B7: 筆記型電腦 | C7: 筆記型電腦 | D7: 112.10.20 | E7: 80000 | F7: 1 | G7: 80000 | H7: 55 | I7: =IF(H7,G7/H7,0) -> 1454.5455 | J7: =設備使用記錄表!AJ6 -> 0.7 | K7: =ROUND(I7*J7,E83) -> 1018
A8: (1)1130002 | B8: 桌上型電腦 | C8: 桌上型電腦 | D8: 110.01.30 | E8: 35000 | F8: 1 | G8: 35000 | H8: 30 | I8: =IF(H8,G8/H8,0) -> 1166.6667 | J8: =設備使用記錄表!AJ7 -> 1 | K8: =ROUND(I8*J8,0) -> 1167
A9: (2)1130003 | B9: 電冰箱 | C9: 電冰箱 | D9: 110.07.25 | E9: 30000 | F9: 1 | G9: 30000 | H9: 30 | I9: =IF(H9,G9/H9,0) -> 1000 | J9: =設備使用記錄表!AJ8 -> 1 | K9: =ROUND(I9*J9,0) -> 1000
I10: =IF(H10,G10/H10,0) -> 0 | J10: =設備使用記錄表!AJ9 -> 0 | K10: =ROUND(I10*J10,0) -> 0
I11: =IF(H11,G11/H11,0) -> 0 | J11: =設備使用記錄表!AJ10 -> 0 | K11: =ROUND(I11*J11,0) -> 0
I12: =IF(H12,G12/H12,0) -> 0 | J12: =設備使用記錄表!AJ11 -> 0 | K12: =ROUND(I12*J12,0) -> 0
A13: 小計 | K13: =ROUND(SUM(K6:K12),0) -> 3185
A15: SIIR計畫－設備使用費(2)---新增設備(112年××月)
K16: 金額單位:元
A17: 財產編號 | B17: 設備名稱 | C17: 對照計畫書所列項目 | D17: 取得日期 | E17: 購入成本 (單套) | F17: 套數 B1 | G17: 投入時 單套帳面價值 （未折減餘額） B2 | I17: 每月攤提使用費 B3=B1*B2*/60 (詳如註3) | J17: 本期投入比率 B4 | K17: 本期使用費 B5=B3*B4
A19: (1)1130004 | B19: 商用咖啡機 | C19: 商用咖啡機 | D19: 112.07.01 | E19: 250000 | F19: 1 | G19: 150000 | I19: =F19*G19/60 -> 2500 | J19: =設備使用記錄表!AJ13 -> 1 | K19: =ROUND(I19*J19,0) -> 2500
A20: (2)1130005 | B20: 磨豆機(大) | C20: 磨豆機 | D20: 112.07.01 | E20: 3000 | F20: 1 | G20: 3000 | I20: =F20*G20/60 -> 50 | J20: =設備使用記錄表!AJ14 -> 1 | K20: =ROUND(I20*J20,0) -> 50
A21: (2)1130006 | B21: 磨豆機(中) | C21: 磨豆機 | D21: 112.07.01 | E21: 3000 | F21: 1 | G21: 3000 | I21: =F21*G21/60 -> 50 | J21: =設備使用記錄表!AJ15 -> 0 | K21: =ROUND(I21*J21,0) -> 0
A22: (2)1130007 | B22: 磨豆機(時間型) | C22: 磨豆機 | D22: 112.07.01 | E22: 9000 | F22: 1 | G22: 3000 | I22: =F22*G22/60 -> 50 | J22: =設備使用記錄表!AJ16 -> 0.15625 | K22: =ROUND(I22*J22,0) -> 8
A23: (2)1130008 | B23: 製冰機 | C23: 製冰機 | D23: 112.07.01 | E23: 48000 | F23: 1 | G23: 48000 | I23: =F23*G23/60 -> 800 | J23: =設備使用記錄表!AJ17 -> 1 | K23: =ROUND(I23*J23,0) -> 800
A24: (2)1130009 | B24: 內崁式冰箱 | C24: 內崁式冰箱 | D24: 112.07.01
A25: (2)1130010 | B25: 筆記型電腦(詩) | C25: 筆記型電腦 | D25: 112.07.01
A26: (2)1130011 | B26: 筆記型電腦(諺) | C26: 筆記型電腦
I27: =F27*G27/60 -> 0 | J27: =設備使用記錄表!AJ18 -> 0 | K27: =ROUND(I27*J27,0) -> 0
A28: 小計 | K28: =ROUND(SUM(K18:K27),0) -> 2550
A29: 合計 | K29: =K28+K13 -> 7950
A31: 註1： 「已有設備」及「新增設備」之名稱應與計畫書所列相符並依上表分開填列。
A32: 註2：「本期投入比率」應依據設備使用記錄表實際投入比率一致。
A33: 註3：帳務查核時應備妥下列文件備查:1.新增設備-請購單、採購單、驗收單、統一發票或收據、進口報關結匯單據與INVOICE。
A34: 2.已有設備-財產目錄。3.研發設備使用記錄表。4.若為分攤，應附分攤表及原始憑證影本。
B36: 計畫主持人: | E36: 主辦會計: | J36: 填表人：

Sheet 設備使用記錄表
A1: =計畫經費彙總表!A1 -> 五常物業規劃顧問股份(閉鎖型)有限公司
A2: SIIR計畫設備使用記錄表(113年07月)
B3: 設備名稱 | C3: 1 | D3: 2 | E3: 3 | F3: 4 | G3: 5 | H3: 6 | I3: 7 | J3: 8 | K3: 9 | L3: 10 | M3: 11 | N3: 12 | O3: 13 | P3: 14 | Q3: 15 | R3: 16 | S3: 17 | T3: 18 | U3: 19 | V3: 20 | W3: 21 | X3: 22 | Y3: 23 | Z3: 24 | AA3: 25 | AB3: 26 | AC3: 27 | AD3: 28 | AE3: 29 | AF3: 30 | AG3: 31 | AH3: 合計 | AI3: 正常使用時數 | AJ3: 投入 比率
A5: 已有設備
B6: =IF(設備使用費!C7<>"",設備使用費!C7,"") -> 筆記型電腦 | E6: 8 | F6: 8 | G6: 8 | H6: 8 | I6: 8 | L6: 8 | M6: 8 | N6: 8 | O6: 8 | P6: 4 | S6: 8 | T6: 8 | U6: 8 | V6: 4 | W6: 8 | AH6: =SUM(C6:AG6) -> 112 | AI6: 160 | AJ6: =AH6/AI6 -> 0.7
B7: =IF(設備使用費!C8<>"",設備使用費!C8,"") -> 桌上型電腦 | E7: 8 | F7: 8 | G7: 8 | H7: 8 | I7: 8 | L7: 8 | M7: 8 | N7: 8 | O7: 8 | P7: 8 | S7: 8 | T7: 8 | U7: 8 | V7: 8 | W7: 8 | Z7: 8 | AA7: 8 | AB7: 8 | AC7: 8 | AD7: 8 | AH7: =SUM(C7:AG7) -> 160 | AI7: 160 | AJ7: =AH7/AI7 -> 1
B8: =IF(設備使用費!C9<>"",設備使用費!C9,"") -> 電冰箱 | E8: 8 | F8: 8 | G8: 8 | H8: 8 | I8: 8 | L8: 8 | M8: 8 | N8: 8 | O8: 8 | P8: 8 | S8: 8 | T8: 8 | U8: 8 | V8: 8 | W8: 8 | Z8: 8 | AA8: 8 | AB8: 8 | AC8: 8 | AD8: 8 | AH8: =SUM(C8:AG8) -> 160 | AI8: 160 | AJ8: =AH8/AI8 -> 1
B9: =IF(設備使用費!C10<>"",設備使用費!C10,"") | AH9: =SUM(C9:AG9) -> 0 | AI9: 160 | AJ9: =AH9/AI9 -> 0
B10: =IF(設備使用費!C11<>"",設備使用費!C11,"") | AH10: =SUM(C10:AG10) -> 0 | AI10: 160 | AJ10: =AH10/AI10 -> 0
B11: =IF(設備使用費!C12<>"",設備使用費!C12,"") | AH11: =SUM(C11:AG11) -> 0 | AI11: 160 | AJ11: =AH11/AI11 -> 0
A12: 新增設備
B13: =IF(設備使用費!C19<>"",設備使用費!C19,"") -> 商用咖啡機 | E13: 8 | F13: 8 | G13: 8 | H13: 8 | I13: 8 | L13: 8 | M13: 8 | N13: 8 | O13: 8 | P13: 8 | S13: 8 | T13: 8 | U13: 8 | V13: 8 | W13: 8 | Z13: 8 | AA13: 8 | AB13: 8 | AC13: 8 | AD13: 8 | AH13: =SUM(C13:AG13) -> 160 | AI13: 160 | AJ13: =AH13/AI13 -> 1
B14: =IF(設備使用費!C20<>"",設備使用費!C20,"") -> 磨豆機 | E14: 8 | F14: 8 | G14: 8 | H14: 8 | I14: 8 | L14: 8 | M14: 8 | N14: 8 | O14: 8 | P14: 8 | S14: 8 | T14: 8 | U14: 8 | V14: 8 | W14: 8 | Z14: 8 | AA14: 8 | AB14: 8 | AC14: 8 | AD14: 8 | AH14: =SUM(C14:AG14) -> 160 | AI14: 160 | AJ14: =AH14/AI14 -> 1
B15: =IF(設備使用費!C21<>"",設備使用費!C21,"") -> 磨豆機 | E15: 3 | G15: 2 | H15: 1 | I15: 1 | L15: 1 | M15: 1 | N15: 1 | O15: 1 | P15: 1 | S15: 2 | T15: 1 | AB15: {=+AB15:AE15} -> 0 | AH15: =SUM(C15:AG15) -> 0 | AI15: 160 | AJ15: =AH15/AI15 -> 0
B16: =IF(設備使用費!C22<>"",設備使用費!C22,"") -> 磨豆機 | E16: 1 | F16: 1 | G16: 1 | H16: 1 | I16: 1 | L16: 1 | M16: 1 | N16: 1 | O16: 1 | P16: 1 | S16: 1 | T16: 1 | U16: 1 | Z16: 1 | AA16: 1 | AB16: 1 | AC16: 1 | AD16: 8 | AH16: =SUM(C16:AG16) -> 25 | AI16: 160 | AJ16: =AH16/AI16 -> 0.15625
B17: =IF(設備使用費!C23<>"",設備使用費!C23,"") -> 製冰機 | E17: 8 | F17: 8 | G17: 8 | H17: 8 | I17: 8 | L17: 8 | M17: 8 | N17: 8 | O17: 8 | P17: 8 | S17: 8 | T17: 8 | U17: 8 | V17: 8 | W17: 8 | Z17: 8 | AA17: 8 | AB17: 8 | AC17: 8 | AD17: 8 | AH17: =SUM(C17:AG17) -> 160 | AI17: 160 | AJ17: =AH17/AI17 -> 1
B18: =IF(設備使用費!C27<>"",設備使用費!C27,"") | AH18: =SUM(C18:AG18) -> 0 | AI18: 160 | AJ18: =AH18/AI18 -> 0
V19: {=+V19:KA20} -> 0
A20: 註1.當月正常使用總時數與人員上班時數相同；若設備為24小時開機者，則以24小時*當月日數，計算當月正常使用總時數。
A21: 註2.每月投入比率最高為1.00。
A22: 註3.攤提設備名稱請參照計畫書所編列設備。
C24: 計畫主持人: | O24: 主辦會計: | X24: 填表人：

Sheet 設備維護費
A1: =計畫經費彙總表!A1 -> 五常物業規劃顧問股份(閉鎖型)有限公司
A2: SIIR計畫設備維護費---已有設備(112年××月)
M3: 金額單位:元
A4: 財產編號 | C4: 設備名稱 | D4: 對照計畫書所列項目 | E4: 購入成本 | F4: 傳票日期 | G4: 傳票號碼 | H4: 發票日期 | I4: 發票編號 | J4: 品名 | K4: 數量 | L4: 單位 | M4: 金額
A16: 小 計(A) | M16: =ROUND(SUM(M5:M15),0) -> 0
A18: 註1：所列報之維護設備應與計畫書所列相符，並應出具維修廠商憑證，且所列維護費之金額應與原始憑證、費用分攤表相符。
A19: 註2：營業稅不得報支。新增設備保固期間內不得列報維護費。
A20: 註3：若屬廠商自行維修之設備，維護費不得超出原購入成本之5%。
A21: 註4：帳務查核時應備妥下列文件備查:1.請購單、驗收單、維護合約、發票或收據等。2.屬自行維修性質者應提供「設備維修時間記錄表」
A22: 及相關自行維修成本計算表。3.若為分攤，應附分攤表及原始憑證影本。4.涉及外幣支付時應附當時之外幣 匯率表。
B24: 計畫主持人: | F24: 主辦會計: | K24: 填表人：

Sheet 技術購買費
A1: =計畫經費彙總表!A1 -> 五常物業規劃顧問股份(閉鎖型)有限公司
A2: SIIR計畫－技術或智慧財產權購買費(113年07月)
A4: 1.技轉(委託)項目:咖啡製作技術、咖啡及飲品共15品項製作配方、製作工序、原料商 | B4: 咖啡製作技術、咖啡及飲品共15品項製作配方、製作工序、原料商 | E4: 2.技轉(委託)對象： | F4: 本司派出之技術承接專員
A5: 3.合約期間:00年00月00日~00年00月00日 | E5: 4.合約總額：新台幣肆拾萬元整
A6: 5.付款方式：依合約內容 | F6: 金額單位:元
A7: 付款期數 | B7: 傳票日期 | C7: 傳票號碼 | D7: 發票日期 | E7: 發票編號 | F7: 金額
A8: 第 1 期 | F8: 150000
A9: 第 2 期 | F9: 150000
A15: 合 計 | F15: =ROUND(SUM(F8:F14),0) -> 300000
A17: 註1：營業稅不得報支。
A18: 註2：技術購買之對象應與計畫書所列相符，金額應與原始憑證（如：統一發票或收據）相符。
A19: 註3：帳務查核時應備妥下列文件備查:1.技術購買契約書。(2)統一發票（或收據）、或國外之INVOICE(或RECEIPT)及匯兌水單。
A21: 計畫主持人: | D21: 主辦會計: | F21: 填表人：

Sheet 委託研究費
A1: =計畫經費彙總表!A1 -> 五常物業規劃顧問股份(閉鎖型)有限公司
A2: SIIR計畫－委託研究費(112年××月)
A4: 1.技轉(委託)項目: | E4: 2.技轉(委託)對象：
A5: 3.合約期間:113年07月01日~114年07月01日 | E5: 4.合約總額：
A6: 5.付款方式： | F6: 金額單位:元
A7: 付款期數 | B7: 傳票日期 | C7: 傳票號碼 | D7: 發票日期 | E7: 發票編號 | F7: 金額
A8: 第 1 期 | E8: AV23182456 | F8: 200000
A9: 第 2 期 | E9: EW86973745 | F9: 150000
A15: 合 計 | F15: =ROUND(SUM(F8:F14),0) -> 350000
A17: 註1：營業稅不得報支。
A18: 註2：委託研究之對象應與計畫書所列相符，金額應與原始憑證（如：統一發票或收據）相符。
A19: 註3：帳務查核時應備妥下列文件備查:1.委託研究契約書。(2)統一發票（或收據）、或國外之INVOICE(或RECEIPT)及匯兌水單。
A21: 計畫主持人: | C21: 主辦會計: | E21: 填表人：

Sheet 委託勞務費
A1: =計畫經費彙總表!A1 -> 五常物業規劃顧問股份(閉鎖型)有限公司
A2: SIIR計畫－委託勞務費(112年××月)
A4: 1.技轉(委託)項目: | E4: 2.技轉(委託)對象：
A5: 3.合約期間:00年00月00日~00年00月00日 | E5: 4.合約總額：
A6: 5.付款方式： | F6: 金額單位:元
A7: 付款期數 | B7: 傳票日期 | C7: 傳票號碼 | D7: 發票日期 | E7: 發票編號 | F7: 金額
A8: 第 1 期 | E8: AV23182456 | F8: 300000
A9: 第 2 期 | E9: EW86973745 | F9: 100000
A15: 合 計 | F15: =ROUND(SUM(F8:F14),0) -> 400000
A17: 註1：營業稅不得報支。
A18: 註2：委託勞務之對象應與計畫書所列相符，金額應與原始憑證（如：統一發票或收據）相符。
A19: 註3：帳務查核時應備妥下列文件備查:1.委託勞務契約書。(2)統一發票（或收據）、或國外之INVOICE(或RECEIPT)及匯兌水單。
A21: 計畫主持人: | D21: 主辦會計: | F21: 填表人：

Sheet 國內差旅費
A1: =計畫經費彙總表!A1 -> 五常物業規劃顧問股份(閉鎖型)有限公司
A2: SIIR計畫－國內差旅費(112年××月)
N3: 金額單元:元
A4: 姓名 | B4: 職稱 | C4: 出差期間 | D4: 天數 | E4: 地點 | F4: 事 由 | G4: 傳票日期 | H4: 傳票號碼 | I4: 機票 | J4: 車資 | K4: 住宿費 | L4: 膳雜費 | M4: 其他 | N4: 合計
B6: 經理 | C6: 3月14-15日 | D6: 2 | E6: 塑膠中心 | F6: 討論勞務規格 | J6: 300 | K6: 1000 | L6: 550 | N6: =ROUND(SUM(I6:M6),0) -> 1850
B7: 工程師 | N7: =ROUND(SUM(I7:M7),0) -> 0
N8: =ROUND(SUM(I8:M8),0) -> 0
N9: =ROUND(SUM(I9:M9),0) -> 0
N10: =ROUND(SUM(I10:M10),0) -> 0
N11: =ROUND(SUM(I11:M11),0) -> 0
N12: =ROUND(SUM(I12:M12),0) -> 0
N13: =ROUND(SUM(I13:M13),0) -> 0
A14: 合 計 | N14: =ROUND(SUM(N5:N13),0) -> 1850
A16: 註1：出差人員僅限本計畫計畫人員，且出差事由應與本專案計畫有關。
A17: 註2：差旅費之膳雜費計算應不超過營利事業所得稅查核準則規定。
A18: 註3：帳務查核時應備妥下列文件備查:(1)搭乘飛機，應檢附機票票根或登機證存根及國際線航空機票購票證明單或旅行業代收轉付收據；
A19: 其餘交通費，應檢附原始單據或旅行業代收轉付 收據。(2)乘坐輪船，應提供船票或輪船公司出具之證明。
A20: (3)火車、汽車之車資，以經手人（即出差人）之證明為憑。但包租計程車應取具車行證明及經手人或出差人證明。(4)住宿費收據或發票。
A21: (5)出差報銷單及公司差旅費報銷規定。(6)涉及外幣支付時應附當時之外幣匯率表。
B22: 計畫主持人: | F22: 主辦會計: | K22: 填表人：

Sheet 國外差旅費
A1: =計畫經費彙總表!A1 -> 五常物業規劃顧問股份(閉鎖型)有限公司
A2: SIIR計畫－國外差旅費(112年××月)
N3: 金額單元:元
A4: 姓名 | B4: 職稱 | C4: 出差期間 | D4: 天數 | E4: 地點 | F4: 事 由 | G4: 傳票日期 | H4: 傳票號碼 | I4: 機票 | J4: 車資 | K4: 住宿費 | L4: 膳雜費 | M4: 其他 | N4: 合計
A6: 1.××× | B6: 經理 | C6: 3月17-18日 | D6: 2 | E6: XX | F6: 討論勞務規格 | I6: 1000 | K6: 450 | L6: 550 | N6: =ROUND(SUM(I6:M6),0) -> 2000
A7: 2.××× | B7: 工程師 | N7: =ROUND(SUM(I7:M7),0) -> 0
N8: =ROUND(SUM(I8:M8),0) -> 0
N9: =ROUND(SUM(I9:M9),0) -> 0
N10: =ROUND(SUM(I10:M10),0) -> 0
N11: =ROUND(SUM(I11:M11),0) -> 0
N12: =ROUND(SUM(I12:M12),0) -> 0
N13: =ROUND(SUM(I13:M13),0) -> 0
A14: 合 計 | N14: =ROUND(SUM(N5:N13),0) -> 2000
A16: 註1：出差人員僅限本計畫計畫人員，且出差事由應與本專案計畫有關。
A17: 註2：差旅費之膳雜費計算應不超過營利事業所得稅查核準則規定。
A18: 註3：帳務查核時應備妥下列文件備查:(1)搭乘飛機，應檢附機票票根或登機證存根及國際線航空機票購票證明單或旅行業代收轉付收據；
A19: 其餘交通費，應檢附原始單據或旅行業代收轉付 收據。(2)乘坐輪船，應提供船票或輪船公司出具之證明。
A20: (3)火車、汽車之車資，以經手人（即出差人）之證明為憑。但包租計程車應取具車行證明及經手人或出差人證明。(4)住宿費收據或發票。
A21: (5)出差報銷單及公司差旅費報銷規定。(6)涉及外幣支付時應附當時之外幣匯率表。
B22: 計畫主持人: | F22: 主辦會計: | K22: 填表人：

Sheet 市場驗證費
A1: =計畫經費彙總表!A1 -> 五常物業規劃顧問股份(閉鎖型)有限公司
A2: SIIR計畫－市場驗證費(112年××月)
J3: 金額單位:元
A4: 傳票日期 | B4: 傳票號碼 | C4: 發票日期 | D4: 發票編號 | E4: 供應商 | F4: 發票內容 (註2) | G4: 對照計畫書所列項目 (註1) | H4: 數量 | I4: 單價 | J4: 金額 (不含營業稅)
A6: 112.4.22 | D6: AB12345678 | E6: ×× | H6: 1 | J6: 1200
A7: 112.4.25 | D7: AB13145676 | E7: ×× | H7: 3 | J7: 6000
A18: 合 計 | J18: =ROUND(SUM(J5:J17),0) -> 7200
A20: 註1：「對照計畫書所列項目」名稱需與計畫書所列之項目名稱一致。
A21: 註2：「發票內容」請依發票填寫所列項目。
A22: 註3：營業稅不得報支。
A23: 註4：帳務查核時應備妥下列文件備查:1.應提供統一發票、收據或進口結匯單據與invoice。2.涉及外幣支付時應附當時之外幣匯率表。3、廣告樣張（樣張上應印有營利事業名稱
A24: 、品牌名或與計畫有相關之資訊)。
A25: 註5：贈送樣品或商品饋贈之項目上限不得逾本科目10%，單份不得逾新台幣500元。
A26: 註6：贊助公益或體育活動具有廣告性質之各項費用應取得統一發票或合法憑證，並檢附載有活動名稱及營利事業名稱之相關廣告品。
A27: 註7：活動臨時聘用人力費用須提供如人事費科目之查核資料。
A28: 註8：活動臨時聘用人力費用，時薪不得低於政府公告最低時薪標準，且不得超過本經費科目10%。
A30: 計畫主持人: | F30: 主辦會計: | I30: 填表人：

Sheet 工作表2

Sheet 工作表1
