Workbook

Sheet 計畫經費彙總表
A1: 五常物業規劃顧問股份(閉鎖型)有限公司
A2: 經費累計表(應按月編制)
A3: 中華民國112年02月01日至112年00月00日
M4: 金額單位：元
B5: 計畫預算數 | E5: 上期累計支用數(列印時請隱藏此欄位) | H5: 本期支用數 | K5: 累計支用數
A6: 預算科目 | B6: 補助款 | C6: 自籌款 | D6: 小計 | E6: 補助款 | F6: 自籌款 | G6: 小計 | H6: 補助款 | I6: 自籌款 | J6: 小計 | K6: 補助款 | L6: 自籌款 | M6: 小計
A7: 一、人事費
A8: 1.計畫人員 | B8: =計畫架構!F104*1000*0.3 -> 270000 | C8: =計畫架構!F104*1000*0.7 -> 630000 | D8: =B8+C8 -> 900000 | G8: =E8+F8 -> 0 | H8: =IF(J8+G8>=D8,B8-E8,ROUND(J8/D8*B8,0)) -> 34905 | I8: =J8-H8 -> 81445 | J8: =ROUND(人事費!I13,0) -> 116350 | K8: =E8+H8 -> 34905 | L8: =F8+I8 -> 81445 | M8: =K8+L8 -> 116350
A9: 2.顧問 | B9: =計畫架構!F102*0.4*1000 -> 120000 | C9: =計畫架構!F102*0.6*1000 -> 180000 | D9: =B9+C9 -> 300000 | G9: =E9+F9 -> 0 | H9: =IF(J9+G9>=D9,B9-E9,ROUND(J9/D9*B9,0)) -> 8000 | I9: =J9-H9 -> 12000 | J9: =ROUND(顧問!E15,0) -> 20000 | K9: =E9+H9 -> 8000 | L9: =F9+I9 -> 12000 | M9: =K9+L9 -> 20000
A10: 二、消耗性器材及原材料費 | B10: =計畫架構!F97*1000*0.4 -> 40000 | C10: =計畫架構!F97*1000*0.6 -> 60000 | D10: =B10+C10 -> 100000 | G10: =E10+F10 -> 0 | H10: =IF(J10+G10>=D10,B10-E10,ROUND(J10/D10*B10,0)) -> 2880 | I10: =J10-H10 -> 4320 | J10: =ROUND(材料費!J27,0) -> 7200 | K10: =E10+H10 -> 2880 | L10: =F10+I10 -> 4320 | M10: =K10+L10 -> 7200
A11: 三、研發設備使用費 | B11: =計畫架構!F98*1000/60*12/4 -> 32390 | C11: =計畫架構!F98*1000/60*12/6 -> 21593.333 | D11: =B11+C11 -> 53983.333 | G11: =E11+F11 -> 0 | H11: =IF(J11+G11>=D11,B11-E11,ROUND(J11/D11*B11,0)) -> 32390 | I11: =J11-H11 -> 44943 | J11: =ROUND(設備使用費!K26,0) -> 77333 | K11: =E11+H11 -> 32390 | L11: =F11+I11 -> 44943 | M11: =K11+L11 -> 77333
A12: 四、研發設備維護費 | B12: =計畫架構!F98*1000*0.02 -> 12956 | C12: =計畫架構!F98*1000*0.03 -> 19434 | D12: =B12+C12 -> 32390 | G12: =E12+F12 -> 0 | H12: =IF(J12+G12>=D12,B12-E12,ROUND(J12/D12*B12,0)) -> 1200 | I12: =J12-H12 -> 1800 | J12: =ROUND(設備維護費!M16,0) -> 3000 | K12: =E12+H12 -> 1200 | L12: =F12+I12 -> 1800 | M12: =K12+L12 -> 3000
A13: 五、技術移轉費
A14: 1.技術或智慧財產權購買費 | B14: =計畫架構!F100*1000*0.4 -> 418000 | C14: =計畫架構!F100*1000*0.6 -> 627000 | D14: =B14+C14 -> 1045000 | G14: =E14+F14 -> 0 | H14: =IF(J14+G14>=D14,B14-E14,ROUND(J14/D14*B14,0)) -> 120000 | I14: =J14-H14 -> 180000 | J14: =ROUND(技術購買費!F15,0) -> 300000 | K14: =E14+H14 -> 120000 | L14: =F14+I14 -> 180000 | M14: =K14+L14 -> 300000
A15: 2.委託研究費 | B15: =計畫架構!F99*1000*0.4 -> 200000 | C15: =計畫架構!F99*1000*0.6 -> 300000 | D15: =B15+C15 -> 500000 | G15: =E15+F15 -> 0 | H15: =IF(J15+G15>=D15,B15-E15,ROUND(J15/D15*B15,0)) -> 140000 | I15: =J15-H15 -> 210000 | J15: =ROUND(委託研究費!F15,0) -> 350000 | K15: =E15+H15 -> 140000 | L15: =F15+I15 -> 210000 | M15: =K15+L15 -> 350000
A16: 3.委託勞務費 | B16: 100000 | C16: 200000 | D16: =B16+C16 -> 300000 | G16: =E16+F16 -> 0 | H16: =IF(J16+G16>=D16,B16-E16,ROUND(J16/D16*B16,0)) -> 100000 | I16: =J16-H16 -> 300000 | J16: =ROUND(委託勞務費!F15,0) -> 400000 | K16: =E16+H16 -> 100000 | L16: =F16+I16 -> 300000 | M16: =K16+L16 -> 400000
A17: 六、差旅費
A18: 1.國內差旅費 | B18: 5000 | C18: 10000 | D18: =B18+C18 -> 15000 | G18: =E18+F18 -> 0 | H18: =IF(J18+G18>=D18,B18-E18,ROUND(J18/D18*B18,0)) -> 617 | I18: =J18-H18 -> 1233 | J18: =ROUND(國內差旅費!N14,0) -> 1850 | K18: =E18+H18 -> 617 | L18: =F18+I18 -> 1233 | M18: =K18+L18 -> 1850
A19: 2.國外差旅費 | C19: 0 | D19: =B19+C19 -> 0 | G19: =E19+F19 -> 0 | H19: 0 | I19: =J19-H19 -> 2000 | J19: =ROUND(國外差旅費!N14,0) -> 2000 | K19: =E19+H19 -> 0 | L19: =F19+I19 -> 2000 | M19: =K19+L19 -> 2000
A20: 七、市場驗證費 | B20: =計畫架構!F101*1000*0.4 -> 197336 | C20: =計畫架構!F101*1000*0.6 -> 296004 | D20: =B20+C20 -> 493340 | G20: =E20+F20 -> 0 | H20: =IF(J20+G20>=D20,B20-E20,ROUND(J20/D20*B20,0)) -> 2880 | I20: =J20-H20 -> 4320 | J20: =ROUND(市場驗證費!J18,0) -> 7200 | K20: =E20+H20 -> 2880 | L20: =F20+I20 -> 4320 | M20: =K20+L20 -> 7200
A21: 合 計 | B21: =SUM(B8:B20) -> 1395682 | C21: =SUM(C8:C20) -> 2344031.3 | D21: =SUM(D8:D20) -> 3739713.3 | E21: =SUM(E8:E20) -> 0 | F21: =SUM(F8:F20) -> 0 | G21: =SUM(G8:G20) -> 0 | H21: =SUM(H8:H20) -> 442872 | I21: =SUM(I8:I20) -> 842061 | ... M21: =SUM(M8:M20) -> 1284933
A23: 註1:金額以元為單位。
A24: 註2:補助款及自籌款出現#DIV/0!之欄位請填0。
A25: 註3:請填寫綠色填滿之欄位，電腦會自動編列小計。
A26: 註4:列印時請隱藏「上期累計實支數」之欄位
A28: 公司負責人: | C28: 計畫主持人: | H28: 主辦會計: | K28: 填表人：

Sheet 細項計畫資訊

Sheet 計畫架構
B1: 創新AI系統整合營運中心服務機制開發運用計畫
P2: 單位/千元
B3: 計畫項目 | C3: =人事費!A7 -> 1.阮氏泉 | E3: 7月 | F3: 8月 | G3: 9月 | H3: 10月 | I3: 11月 | J3: 12月 | K3: 1月 | L3: 2月 | M3: 3月 | N3: 4月 | O3: 5月 | P3: 6月
C4: A分項計畫 商業資訊中心設置計畫 | Q4: 合計 | R4: 細項小計及權重
C5: A1直營商店營運權力取得及技術轉移7/10 | D5: 人 | E5: 0.25 | J5: 0.25 | Q5: =SUM(E5:P5)*40 -> 20 | R5: =Q5+Q6 -> 1065
D6: 費 | E6: 500 | J6: 545 | Q6: =SUM(E6:P6) -> 1045 | R6: =R5/F105 -> 0.26321383
C7: A2直營咖啡店營運、進行員工教學及產品開發研究、並導入點餐系統8/1 | D7: 人 | F7: 0.4 | G7: 0.4 | H7: 0.4 | I7: 0.4 | J7: 0.4 | K7: 0.4 | L7: 0.4 | M7: 0.4 | N7: 0.4 | O7: 0.4 | P7: 0.5 | Q7: =SUM(F7:P7)*40 -> 180 | R7: =Q7+Q8 -> 280
D8: 費 | F8: 10 | G8: 10 | H8: 10 | I8: 10 | J8: 10 | K8: 10 | L8: 10 | M8: 10 | N8: 10 | O8: 10 | Q8: =SUM(E8:P8) -> 100 | R8: =R7/F105 -> 0.069201758
C9: A3轄內商業資訊收集建檔及資料分析11/1 | D9: 人 | F9: 0.25 | G9: 0.25 | H9: 0.25 | I9: 0.25 | Q9: =SUM(F9:P9)*40 -> 40 | R9: =Q9+Q10 -> 40
D10: 費 | Q10: =SUM(E10:P10) -> 0 | R10: =R9/F105 -> 0.0098859654
C11: A4開發商業會員參與聯合營運計畫10/1 | D11: 人 | E11: 0.25 | F11: 0.25 | G11: 0.25 | H11: 0.25 | Q11: =SUM(E11:P11)*40 -> 40 | R11: =Q11+Q8 -> 140
D12: 費 | Q12: =SUM(E12:P12) -> 0 | R12: =R11/F105 -> 0.034600879
C13: A5完成全區域內商業分析報告及擬定顧問企劃。4/1 | D13: 人 | J13: 0.25 | K13: 0.25 | Q13: =SUM(F13:P13)*40 -> 20 | R13: =Q13+Q67 -> 175.4
D14: 費 | Q14: =SUM(E14:P14) -> 0 | R14: =R13/F105 -> 0.043349958
C15: A6出席研討會並收集本分項計畫有關之訊息6/10 | D15: 人 | O15: 0.25 | P15: 0.25 | Q15: =SUM(F15:P15)*40 -> 20 | R15: =Q15+Q16 -> 20
D16: 費 | Q16: =SUM(E16:P16) -> 0 | R16: =R15/F105 -> 0.0049429827
C17: 合計人月 | E17: =E5+E7+E9+E11+E13+E15 -> 0.5 | F17: =F5+F7+F9+F11+F13+F15 -> 0.9 | G17: =G5+G7+G9+G11+G13+G15 -> 0.9 | H17: =H5+H7+H9+H11+H13+H15 -> 0.9 | I17: =I5+I7+I9+I11+I13+I15 -> 0.65 | J17: =J5+J7+J9+J11+J13+J15 -> 0.9 | K17: =K5+K7+K9+K11+K13+K15 -> 0.65 | L17: =L5+L7+L9+L11+L13+L15 -> 0.4 | ... P17: =P5+P7+P9+P11+P13+P15 -> 0.75 | Q17: =SUM(E17:P17) -> 8
C18: 合計薪資 | E18: =E17*40 -> 20 | F18: =F17*40 -> 36 | G18: =G17*40 -> 36 | H18: =H17*40 -> 36 | I18: =I17*40 -> 26 | J18: =J17*40 -> 36 | K18: =K17*40 -> 26 | L18: =L17*40 -> 16 | ... Q18: =Q17*40 -> 320
C19: 非屬薪資 | E19: =E6+E8+E10+E12+E14+E16 -> 500 | F19: =F6+F8+F10+F12+F14+F16 -> 10 | G19: =G6+G8+G10+G12+G14+G16 -> 10 | H19: =H6+H8+H10+H12+H14+H16 -> 10 | I19: =I6+I8+I10+I12+I14+I16 -> 10 | J19: =J6+J8+J10+J12+J14+J16 -> 555 | K19: =K6+K8+K10+K12+K14+K16 -> 10 | L19: =L6+L8+L10+L12+L14+L16 -> 10 | ... O19: =O6+O8+O10+O12+O14+O16 -> 10 | Q19: =Q6+Q8+Q10+Q12+Q14+Q16 -> 1145
C20: 費用小計 | E20: =SUM(E18:E19) -> 520 | F20: =SUM(F18:F19) -> 46 | G20: =SUM(G18:G19) -> 46 | H20: =SUM(H18:H19) -> 46 | I20: =SUM(I18:I19) -> 36 | J20: =SUM(J18:J19) -> 591 | K20: =SUM(K18:K19) -> 36 | L20: =SUM(L18:L19) -> 26 | ... O20: =SUM(O18:O19) -> 36 | P20: 分項合計 | Q20: =SUM(Q18:Q19) -> 1465
B22: 計畫項目 | C22: =人事費!A9 -> 3.蔣明諺 | E22: 7 | F22: 8 | G22: 9 | H22: 10 | I22: 11 | J22: 12 | K22: 1 | L22: 2 | M22: 3 | N22: 4 | O22: 5 | P22: 6
C23: B分項計畫物業安全中心設置 | R23: 細項小計及權重
C24: B1物業管理及保全協力廠商探詢及轄內物業管理8/1 | D24: 人 | E24: 0.25 | F24: 0.5 | G24: 0.25 | Q24: =SUM(F24:P24)*40 -> 30 | R24: =Q24+Q25 -> 30
D25: 費 | Q25: =SUM(E25:P25) -> 0 | R25: =R24/F105 -> 0.007414474
C26: B2分析各管委會及承攬物業資訊製作物業資訊庫10/1 | D26: 人 | E26: 0.25 | G26: 0.25 | Q26: =SUM(F26:P26)*40 -> 10 | R26: =Q26+Q27 -> 10
D27: 費 | Q27: =SUM(E27:P27) -> 0 | R27: =R26/F105 -> 0.0024714913
C28: B3選定5家測試合作業物業並前往洽談合作事宜10/15 | D28: 人 | G28: 0.25 | H28: 0.25 | Q28: =SUM(F28:P28)*40 -> 20 | R28: =Q28+Q29 -> 20
D29: 費 | Q29: =SUM(E29:P29) -> 0 | R29: =R28/F105 -> 0.0049429827
C30: B4進行全區域的物業拜訪開拓創新社區安全網業務11/1 | D30: 人 | I30: 0.25 | J30: 0.25 | K30: 0.25 | L30: 0.25 | M30: 0.25 | N30: 0.25 | O30: 0.25 | P30: 0.25 | Q30: =SUM(F30:P30)*40 -> 80 | R30: =Q30+Q27 -> 80
D31: 費 | Q31: =SUM(E31:P31) -> 0 | R31: =R30/F105 -> 0.019771931
C32: B5完成全區域內物業分析報告及擬定安保顧問企劃3/11 | D32: 人 | L32: 0.25 | M32: 0.25 | Q32: =SUM(F32:P32)*40 -> 20 | R32: =Q32+Q86 -> 20
D33: 費 | Q33: =SUM(E33:P33) -> 0 | R33: =R32/F105 -> 0.0049429827
C34: B6出席研討會並收集本分項計畫有關之訊息6/10 | D34: 人 | O34: 0.25 | P34: 0.25 | Q34: =SUM(F34:P34)*40 -> 20 | R34: =Q34+Q35 -> 20
D35: 費 | Q35: =SUM(E35:P35) -> 0 | R35: =R34/F105 -> 0.0049429827
C36: 合計人月 | E36: =E24+E26+E28+E30+E32+E34 -> 0.5 | F36: =F24+F26+F28+F30+F32+F34 -> 0.5 | G36: =G24+G26+G28+G30+G32+G34 -> 0.75 | H36: =H24+H26+H28+H30+H32+H34 -> 0.25 | I36: =I24+I26+I28+I30+I32+I34 -> 0.25 | J36: =J24+J26+J28+J30+J32+J34 -> 0.25 | K36: =K24+K26+K28+K30+K32+K34 -> 0.25 | L36: =L24+L26+L28+L30+L32+L34 -> 0.5 | ... P36: =P24+P26+P28+P30+P32+P34 -> 0.5 | Q36: =SUM(E36:P36) -> 5
C37: 合計薪資 | E37: =E36*40 -> 20 | F37: =F36*40 -> 20 | G37: =G36*40 -> 30 | H37: =H36*40 -> 10 | I37: =I36*40 -> 10 | J37: =J36*40 -> 10 | K37: =K36*40 -> 10 | L37: =L36*40 -> 20 | ... O37: =O36*40 -> 20 | Q37: =Q36*40 -> 200
C38: 非屬薪資 | E38: =E25+E27+E29+E31+E33+E35 -> 0 | F38: =F25+F27+F29+F31+F33+F35 -> 0 | G38: =G25+G27+G29+G31+G33+G35 -> 0 | H38: =H25+H27+H29+H31+H33+H35 -> 0 | I38: =I25+I27+I29+I31+I33+I35 -> 0 | J38: =J25+J27+J29+J31+J33+J35 -> 0 | K38: =K25+K27+K29+K31+K33+K35 -> 0 | L38: =L25+L27+L29+L31+L33+L35 -> 0 | ... O38: =O25+O27+O29+O31+O33+O35 -> 0 | Q38: =Q25+Q27+Q29+Q31+Q33+Q35 -> 0
C39: 費用小計 | E39: =SUM(E37:E38) -> 20 | F39: =SUM(F37:F38) -> 20 | G39: =SUM(G37:G38) -> 30 | H39: =SUM(H37:H38) -> 10 | I39: =SUM(I37:I38) -> 10 | J39: =SUM(J37:J38) -> 10 | K39: =SUM(K37:K38) -> 10 | L39: =SUM(L37:L38) -> 20 | ... O39: =SUM(O37:O38) -> 20 | P39: 分項合計 | Q39: =SUM(Q37:Q38) -> 200
B41: 計畫項目 | C41: =人事費!A10 -> 4.林詩妘 | E41: 7 | F41: 8 | G41: 9 | H41: 10 | I41: 11 | J41: 12 | K41: 1 | L41: 2 | M41: 3 | N41: 4 | O41: 5 | P41: 6
C42: C分項計畫 資訊、勞務系統開發 | R42: 細項小計及權重
...

Sheet 人事費
A1: =計畫經費彙總表!A1 -> 五常物業規劃顧問股份(閉鎖型)有限公司
A2: SIIR計畫－計畫人員薪資計算表 (112年××月)
I3: 金額單位:元
A4: 傳票日期 | C4: 傳票編號
A5: 計畫人員姓 名 | B5: 本(底)薪 A | C5: 職務加給或 技術津貼 B | D5: 主管加給 C | E5: 月薪小計 D=A+B+C | F5: 投入比率 (註1) I | G5: 可列入本計畫之薪餉J=D*I | H5: 本計畫加班費 K | I5: 應計入本計畫薪資 L=J+K
A7: 1.阮氏泉 | B7: 30000 | C7: 8000 | D7: 2000 | E7: =SUM(B7:D7) -> 40000 | F7: =工時記錄表!AI5 -> 0.68 | G7: =ROUND(E7*F7,0) -> 27200 | H7: =加班記錄!I5 -> 200 | I7: =SUM(G7:H7) -> 27400
A8: 2.江政隆 | B8: 30000 | C8: 8000 | D8: 1000 | E8: =SUM(B8:D8) -> 39000 | F8: =工時記錄表!AI6 -> 1 | G8: =ROUND(E8*F8,0) -> 39000 | H8: =加班記錄!I6 -> 300 | I8: =SUM(G8:H8) -> 39300
A9: 3.蔣明諺 | B9: 30000 | C9: 8000 | D9: 1000 | E9: =SUM(B9:D9) -> 39000 | F9: =工時記錄表!AI7 -> 0.5 | G9: =ROUND(E9*F9,0) -> 19500 | H9: =加班記錄!I7 -> 400 | I9: =SUM(G9:H9) -> 19900
A10: 4.林詩妘 | B10: 30000 | C10: 8000 | D10: 1000 | E10: =SUM(B10:D10) -> 39000 | F10: =工時記錄表!AI8 -> 0.75 | G10: =ROUND(E10*F10,0) -> 29250 | H10: =加班記錄!I8 -> 500 | I10: =SUM(G10:H10) -> 29750
A11: 5.李道翔 | B11: 30000 | C11: 8000 | D11: 1000 | E11: =SUM(B11:D11) -> 39000 | G11: =ROUND(E11*F11,0) -> 0 | I11: =SUM(G11:H11) -> 0
G12: =ROUND(E12*F12,0) -> 0 | I12: =SUM(G12:H12) -> 0
A13: 合 計 | B13: =SUM(B6:B12) -> 150000 | C13: =SUM(C7:C12) -> 40000 | D13: =SUM(D7:D12) -> 6000 | E13: =SUM(E7:E12) -> 196000 | F13: =SUM(F7:F12) -> 2.93 | G13: =SUM(G7:G12) -> 114950 | H13: =SUM(H7:H12) -> 1400 | I13: =ROUND(SUM(I6:I12),0) -> 116350
A15: 註1：投入比率應與工時記錄表合計當月份一致。每月投入比率以1為上限。
A16: 註2：帳務查核時應備妥下列文件備查: 1.薪資清冊(內容包含：發放之薪資結構明細計算)
A17: 2.銀行轉帳記錄或印領清冊
A19: 計畫主持人: | E19: 主辦會計: | I19: 填表人：

Sheet 工作表3

Sheet 加班記錄
A1: =計畫經費彙總表!A1 -> 五常物業規劃顧問股份(閉鎖型)有限公司
A2: SIIR計畫人員加班記錄總表 (112年××月)
I3: 金額單位:元
A4: 計畫人員姓 名 | B4: 加班事由 | F4: 加班時數 | G4: 加班費計算公式 | I4: 本計畫之加班費 | J4: 計畫人員簽名
A5: 1.××× | I5: 200
A6: 2.××× | I6: 300
A7: 3.××× | I7: 400
A8: 4.××× | I8: 500
A11: 合 計 | I11: =ROUND(SUM(I5:I10),0) -> 1400
A13: 計畫主持人: | D13: 主辦會計: | H13: 填表人：

Sheet 顧問
A1: =計畫經費彙總表!A1 -> 五常物業規劃顧問股份(閉鎖型)有限公司
A2: SIIR計畫－顧問費(112年××月)
E3: 金額單位:元
A4: 姓名 | B4: 傳票日期 | C4: 傳票編號 | D4: 摘要 | E4: 合 計
A6: 1.××× | E6: 10000
A7: 2.××× | E7: 10000
A8: 3
A9: 4
A10: 5
A15: 合 計 | E15: =ROUND(SUM(E6:E14),0) -> 20000
A17: 註1：帳務查核時應備妥下列文件備查:1.領款收據（應書明受領事由、受領人名、地址、
A18: 身份證編號，由受領人簽名 或蓋章） 2.證明支付金額之文件(ex:銀行匯款單據)
A19: 註2：顧問任職單位同意函。
A21: 計畫主持人: | C21: 主辦會計: | E21: 填表人：

Sheet 工時記錄表
A1: =計畫經費彙總表!A1 -> 五常物業規劃顧問股份(閉鎖型)有限公司
A2: SIIR計畫工時記錄表(112年××月)
A3: 姓名 | B3: 1 | C3: 2 | D3: 3 | E3: 4 | F3: 5 | G3: 6 | H3: 7 | I3: 8 | J3: 9 | K3: 10 | L3: 11 | M3: 12 | N3: 13 | O3: 14 | P3: 15 | Q3: 16 | R3: 17 | S3: 18 | T3: 19 | U3: 20 | V3: 21 | W3: 22 | X3: 23 | Y3: 24 | Z3: 25 | AA3: 26 | AB3: 27 | AC3: 28 | AD3: 29 | AE3: 30 | AF3: 31 | AG3: 合計 | AH3: 正常工作時數 | AI3: 投入 比率 | AJ3: 簽名欄
A5: 1.××× | D5: 8 | E5: 8 | F5: 8 | G5: 8 | H5: 8 | K5: 8 | L5: 8 | M5: 8 | N5: 8 | O5: 4 | R5: 8 | S5: 8 | T5: 8 | U5: 4 | V5: 4.8 | AG5: =SUM(B5:AF5) -> 108.8 | AH5: 160 | AI5: =AG5/AH5 -> 0.68
A6: 2.××× | D6: 8 | E6: 8 | F6: 8 | G6: 8 | H6: 8 | K6: 8 | L6: 8 | M6: 8 | N6: 8 | O6: 8 | R6: 8 | S6: 8 | T6: 8 | U6: 8 | V6: 8 | Y6: 8 | Z6: 8 | AA6: 8 | AB6: 8 | AC6: 8 | AG6: =SUM(B6:AF6) -> 160 | AH6: 160 | AI6: =AG6/AH6 -> 1
A7: 3.××× | D7: 4 | E7: 4 | F7: 4 | G7: 4 | H7: 4 | K7: 4 | L7: 4 | M7: 4 | N7: 4 | O7: 4 | R7: 4 | S7: 4 | T7: 4 | U7: 4 | V7: 4 | Y7: 4 | Z7: 4 | AA7: 4 | AB7: 4 | AC7: 4 | AG7: =SUM(B7:AF7) -> 80 | AH7: 160 | AI7: =AG7/AH7 -> 0.5
A8: 4.××× | D8: 8 | E8: 8 | F8: 8 | G8: 8 | H8: 8 | K8: 8 | L8: 8 | M8: 8 | N8: 8 | O8: 8 | R8: 4 | S8: 4 | T8: 4 | U8: 4 | V8: 4 | Y8: 4 | Z8: 4 | AA8: 4 | AB8: 4 | AC8: 4 | AG8: =SUM(B8:AF8) -> 120 | AH8: 160 | AI8: =AG8/AH8 -> 0.75
A17: 合計 | B17: =SUM(B5:B16) -> 0 | C17: =SUM(C5:C16) -> 0 | D17: =SUM(D5:D16) -> 28 | E17: =SUM(E5:E16) -> 28 | F17: =SUM(F5:F16) -> 28 | G17: =SUM(G5:G16) -> 28 | H17: =SUM(H5:H16) -> 28 | I17: =SUM(I5:I16) -> 0 | ... AG17: =SUM(AG5:AG16) -> 468.8 | AI17: =SUM(AI5:AI16) -> 2.93
A19: 註1.請假不論事由，請假時數均不得列入本計畫投入工時計算。
A20: 註2.公司加班如另發加班費則上表所統計之工時不含加班時數；如採補休方式則加班時數應計入，補休時則視同請假處理。
A21: 註3.每月投入比率最高為1.00。
A22: 註4.請計畫人員確認工時記錄後於簽名欄位簽名
E24: 計畫主持人: | S24: 主辦會計: | AD24: 填表人：

Sheet 材料費
A1: =計畫經費彙總表!A1 -> 五常物業規劃顧問股份(閉鎖型)有限公司
A2: SIIR計畫－消耗性器材及原材料費(112年××月)
J3: 金額單位:元
A4: 傳票日期 | B4: 傳票號碼 | C4: 發票日期 (領料日期) | D4: 發票編號 (領料單號) | E4: 供應商 | F4: 發票品名 (註2) | G4: 對照計畫書所列項目 (註1) | H4: 數量 | I4: 單價(材料明細或分攤表) | J4: 金額 (不含營業稅)
A6: 112.4.22 | B6: 1120424002 | C6: 112.4.13 | D6: AB12345678 | E6: ×× | F6: 齒輪 | G6: 齒輪 | H6: 1 | J6: 1200
A7: 112.4.24 | B7: 1120424002 | C7: 112.4.18 | D7: AB13145676 | E7: ×× | F7: 鋼材 | G7: 鋼材 | H7: 3 | J7: 6000
A27: 合 計 | J27: =ROUND(SUM(J5:J26),0) -> 7200
A29: 註1：「對照計畫書所列項目」名稱需與計畫書所列之材料項目名稱一致。
A30: 註2：「發票品名」請依發票填寫所列項目。
A31: 註3：如屬公司共通性材料領用，發票日期、發票號碼請改填寫領料單日期、領料單號碼
A32: 註4：營業稅不得報支。
A33: 註5：辦公室所需之事務性耗材不得報支。
A34: 註6：帳務查核時應備妥下列文件備查:1.為專案計畫採購者應提供統一發票、收據或進口結匯單據與invoice、 及內部轉帳傳票、請購單、採購單
A35: 及驗收單足以證明之憑證。 2.自共通性器材領料應提供：領料單、材料明細帳或分攤表。3.涉及外幣支付時應附當時之外幣匯率表。
B37: 計畫主持人: | F37: 主辦會計: | I37: 填表人：

Sheet 設備使用費
A1: =計畫經費彙總表!A1 -> 五常物業規劃顧問股份(閉鎖型)有限公司
A2: SIIR計畫－設備使用費(1)---已有設備(112年××月)
K3: 金額單位:元
A4: 傳票日期 | C4: 傳票編號
A5: 財產編號 | B5: 設備名稱 | C5: 對照計畫書所列項目 | D5: 取得日期 | E5: 購入成本 (單套) | F5: 套數 A1 | G5: 投入時 單套帳面價值 （未折減餘額） A2 | H5: 剩餘使用月數 | I5: 每月攤提使用費 A3=A1*A2*/剩餘使用月數 (詳如註3) | J5: 本期投入比率 A4 | K5: 本期使用費 A5=A3*A4
A7: (1)8800015 | B7: 成型機 | C7: 成型機 | D7: 107.01.15 | E7: 800000 | F7: 1 | G7: 600000 | H7: 10 | I7: =IF(H7,G7/H7,0) -> 60000 | J7: =設備使用記錄表!AJ6 -> 0.675 | K7: =ROUND(I7*J7,0) -> 40500
A8: (2)8900032 | B8: 磨石機 | C8: 磨石機 | D8: 107.07.22 | E8: 500000 | F8: 1 | G8: 420000 | H8: 20 | I8: =IF(H8,G8/H8,0) -> 21000 | J8: =設備使用記錄表!AJ7 -> 1 | K8: =ROUND(I8*J8,0) -> 21000
A9: (3)8900033 | B9: 加工機 | C9: 加工機 | D9: 107.07.25 | E9: 400000 | F9: 1 | G9: 200000 | H9: 30 | I9: =IF(H9,G9/H9,0) -> 6666.6667 | J9: =設備使用記錄表!AJ8 -> 0.5 | K9: =ROUND(I9*J9,0) -> 3333
I10: =IF(H10,G10/H10,0) -> 0 | J10: =設備使用記錄表!AJ9 -> 0 | K10: =ROUND(I10*J10,0) -> 0
I11: =IF(H11,G11/H11,0) -> 0 | J11: =設備使用記錄表!AJ10 -> 0 | K11: =ROUND(I11*J11,0) -> 0
I12: =IF(H12,G12/H12,0) -> 0 | J12: =設備使用記錄表!AJ11 -> 0 | K12: =ROUND(I12*J12,0) -> 0
A13: 小計 | K13: =ROUND(SUM(K6:K12),0) -> 64833
A15: SIIR計畫－設備使用費(2)---新增設備(112年××月)
K16: 金額單位:元
A17: 財產編號 | B17: 設備名稱 | C17: 對照計畫書所列項目 | D17: 取得日期 | E17: 購入成本 (單套) | F17: 套數 B1 | G17: 投入時 單套帳面價值 （未折減餘額） B2 | I17: 每月攤提使用費 B3=B1*B2*/60 (詳如註3) | J17: 本期投入比率 B4 | K17: 本期使用費 B5=B3*B4
A19: (1)10404011 | B19: 電腦 | C19: 電腦 | D19: 112.04.03 | E19: 150000 | F19: 1 | G19: 150000 | I19: =F19*G19/60 -> 2500 | J19: =設備使用記錄表!AJ13 -> 1 | K19: =ROUND(I19*J19,0) -> 2500
A20: (2)10404025 | B20: 射出機 | C20: 射出機 | D20: 112.04.05 | E20: 600000 | F20: 1 | G20: 600000 | I20: =F20*G20/60 -> 10000 | J20: =設備使用記錄表!AJ14 -> 1 | K20: =ROUND(I20*J20,0) -> 10000
I21: =F21*G21/60 -> 0 | J21: =設備使用記錄表!AJ15 -> 0 | K21: =ROUND(I21*J21,0) -> 0
I22: =F22*G22/60 -> 0 | J22: =設備使用記錄表!AJ16 -> 0 | K22: =ROUND(I22*J22,0) -> 0
I23: =F23*G23/60 -> 0 | J23: =設備使用記錄表!AJ17 -> 0 | K23: =ROUND(I23*J23,0) -> 0
I24: =F24*G24/60 -> 0 | J24: =設備使用記錄表!AJ18 -> 0 | K24: =ROUND(I24*J24,0) -> 0
A25: 小計 | K25: =ROUND(SUM(K18:K24),0) -> 12500
A26: 合計 | K26: =K25+K13 -> 77333
A28: 註1： 「已有設備」及「新增設備」之名稱應與計畫書所列相符並依上表分開填列。
A29: 註2：「本期投入比率」應依據設備使用記錄表實際投入比率一致。
A30: 註3：帳務查核時應備妥下列文件備查:1.新增設備-請購單、採購單、驗收單、統一發票或收據、進口報關結匯單據與INVOICE。
A31: 2.已有設備-財產目錄。3.研發設備使用記錄表。4.若為分攤，應附分攤表及原始憑證影本。
B33: 計畫主持人: | E33: 主辦會計: | J33: 填表人：

Sheet 設備使用記錄表
A1: =計畫經費彙總表!A1 -> 五常物業規劃顧問股份(閉鎖型)有限公司
A2: SIIR計畫設備使用記錄表(112年××月)
B3: 設備名稱 | C3: 1 | D3: 2 | E3: 3 | F3: 4 | G3: 5 | H3: 6 | I3: 7 | J3: 8 | K3: 9 | L3: 10 | M3: 11 | N3: 12 | O3: 13 | P3: 14 | Q3: 15 | R3: 16 | S3: 17 | T3: 18 | U3: 19 | V3: 20 | W3: 21 | X3: 22 | Y3: 23 | Z3: 24 | AA3: 25 | AB3: 26 | AC3: 27 | AD3: 28 | AE3: 29 | AF3: 30 | AG3: 31 | AH3: 合計 | AI3: 正常使用時數 | AJ3: 投入 比率
A5: 已有設備
B6: =IF(設備使用費!C7<>"",設備使用費!C7,"") -> 成型機 | E6: 8 | F6: 8 | G6: 8 | H6: 8 | I6: 8 | L6: 8 | M6: 8 | N6: 8 | O6: 8 | P6: 4 | S6: 8 | T6: 8 | U6: 8 | V6: 4 | W6: 4 | AH6: =SUM(C6:AG6) -> 108 | AI6: 160 | AJ6: =AH6/AI6 -> 0.675
B7: =IF(設備使用費!C8<>"",設備使用費!C8,"") -> 磨石機 | E7: 8 | F7: 8 | G7: 8 | H7: 8 | I7: 8 | L7: 8 | M7: 8 | N7: 8 | O7: 8 | P7: 8 | S7: 8 | T7: 8 | U7: 8 | V7: 8 | W7: 8 | Z7: 8 | AA7: 8 | AB7: 8 | AC7: 8 | AD7: 8 | AH7: =SUM(C7:AG7) -> 160 | AI7: 160 | AJ7: =AH7/AI7 -> 1
B8: =IF(設備使用費!C9<>"",設備使用費!C9,"") -> 加工機 | E8: 4 | F8: 4 | G8: 4 | H8: 4 | I8: 4 | L8: 4 | M8: 4 | N8: 4 | O8: 4 | P8: 4 | S8: 4 | T8: 4 | U8: 4 | V8: 4 | W8: 4 | Z8: 4 | AA8: 4 | AB8: 4 | AC8: 4 | AD8: 4 | AH8: =SUM(C8:AG8) -> 80 | AI8: 160 | AJ8: =AH8/AI8 -> 0.5
B9: =IF(設備使用費!C10<>"",設備使用費!C10,"") | AH9: =SUM(C9:AG9) -> 0 | AI9: 160 | AJ9: =AH9/AI9 -> 0
B10: =IF(設備使用費!C11<>"",設備使用費!C11,"") | AH10: =SUM(C10:AG10) -> 0 | AI10: 160 | AJ10: =AH10/AI10 -> 0
B11: =IF(設備使用費!C12<>"",設備使用費!C12,"") | AH11: =SUM(C11:AG11) -> 0 | AI11: 160 | AJ11: =AH11/AI11 -> 0
A12: 新增設備
B13: =IF(設備使用費!C19<>"",設備使用費!C19,"") -> 電腦 | E13: 8 | F13: 8 | G13: 8 | H13: 8 | I13: 8 | L13: 8 | M13: 8 | N13: 8 | O13: 8 | P13: 8 | S13: 8 | T13: 8 | U13: 8 | V13: 8 | W13: 8 | Z13: 8 | AA13: 8 | AB13: 8 | AC13: 8 | AD13: 8 | AH13: =SUM(C13:AG13) -> 160 | AI13: 160 | AJ13: =AH13/AI13 -> 1
B14: =IF(設備使用費!C20<>"",設備使用費!C20,"") -> 射出機 | E14: 8 | F14: 8 | G14: 8 | H14: 8 | I14: 8 | L14: 8 | M14: 8 | N14: 8 | O14: 8 | P14: 8 | S14: 8 | T14: 8 | U14: 8 | V14: 8 | W14: 8 | Z14: 8 | AA14: 8 | AB14: 8 | AC14: 8 | AD14: 8 | AH14: =SUM(C14:AG14) -> 160 | AI14: 160 | AJ14: =AH14/AI14 -> 1
B15: =IF(設備使用費!C21<>"",設備使用費!C21,"") | AH15: =SUM(C15:AG15) -> 0 | AI15: 160 | AJ15: =AH15/AI15 -> 0
B16: =IF(設備使用費!C22<>"",設備使用費!C22,"") | AH16: =SUM(C16:AG16) -> 0 | AI16: 160 | AJ16: =AH16/AI16 -> 0
B17: =IF(設備使用費!C23<>"",設備使用費!C23,"") | AH17: =SUM(C17:AG17) -> 0 | AI17: 160 | AJ17: =AH17/AI17 -> 0
B18: =IF(設備使用費!C24<>"",設備使用費!C24,"") | AH18: =SUM(C18:AG18) -> 0 | AI18: 160 | AJ18: =AH18/AI18 -> 0
A20: 註1.當月正常使用總時數與人員上班時數相同；若設備為24小時開機者，則以24小時*當月日數，計算當月正常使用總時數。
A21: 註2.每月投入比率最高為1.00。
A22: 註3.攤提設備名稱請參照計畫書所編列設備。
C24: 計畫主持人: | O24: 主辦會計: | X24: 填表人：

Sheet 設備維護費
A1: =計畫經費彙總表!A1 -> 五常物業規劃顧問股份(閉鎖型)有限公司
A2: SIIR計畫設備維護費---已有設備(112年××月)
M3: 金額單位:元
A4: 財產編號 | C4: 設備名稱 | D4: 對照計畫書所列項目 | E4: 購入成本 | F4: 傳票日期 | G4: 傳票號碼 | H4: 發票日期 | I4: 發票編號 | J4: 品名 | K4: 數量 | L4: 單位 | M4: 金額
B6: (1)8800015 | C6: =設備使用記錄表!B6 -> 成型機 | D6: =設備使用記錄表!B6 -> 成型機 | E6: 800000 | F6: 112.05.15 | G6: 11205003 | H6: 112.05.01 | I6: CD200102 | J6: 螺絲 | K6: 1 | L6: 個 | M6: 500
B7: (2)8900032 | C7: =設備使用記錄表!B7 -> 磨石機 | D7: =設備使用記錄表!B7 -> 磨石機 | E7: 500000 | F7: 112.05.22 | G7: 11205009 | H7: 112.05.02 | I7: EF200305 | J7: 模具材料 | K7: 1 | L7: 個 | M7: 2500
A16: 小 計(A) | M16: =ROUND(SUM(M5:M15),0) -> 3000
A18: 註1：所列報之維護設備應與計畫書所列相符，並應出具維修廠商憑證，且所列維護費之金額應與原始憑證、費用分攤表相符。
A19: 註2：營業稅不得報支。新增設備保固期間內不得列報維護費。
A20: 註3：若屬廠商自行維修之設備，維護費不得超出原購入成本之5%。
A21: 註4：帳務查核時應備妥下列文件備查:1.請購單、驗收單、維護合約、發票或收據等。2.屬自行維修性質者應提供「設備維修時間記錄表」
A22: 及相關自行維修成本計算表。3.若為分攤，應附分攤表及原始憑證影本。4.涉及外幣支付時應附當時之外幣 匯率表。
B24: 計畫主持人: | F24: 主辦會計: | K24: 填表人：

Sheet 技術購買費
A1: =計畫經費彙總表!A1 -> 五常物業規劃顧問股份(閉鎖型)有限公司
A2: SIIR計畫－技術或智慧財產權購買費(112年××月)
A4: 1.技轉(委託)項目: | E4: 2.技轉(委託)對象：
A5: 3.合約期間:00年00月00日~00年00月00日 | E5: 4.合約總額：
A6: 5.付款方式： | F6: 金額單位:元
A7: 付款期數 | B7: 傳票日期 | C7: 傳票號碼 | D7: 發票日期 | E7: 發票編號 | F7: 金額
A8: 第 1 期 | E8: AV23182456 | F8: 150000
A9: 第 2 期 | E9: EW86973745 | F9: 150000
A15: 合 計 | F15: =ROUND(SUM(F8:F14),0) -> 300000
A17: 註1：營業稅不得報支。
A18: 註2：技術購買之對象應與計畫書所列相符，金額應與原始憑證（如：統一發票或收據）相符。
A19: 註3：帳務查核時應備妥下列文件備查:1.技術購買契約書。(2)統一發票（或收據）、或國外之INVOICE(或RECEIPT)及匯兌水單。
A21: 計畫主持人: | D21: 主辦會計: | F21: 填表人：

Sheet 委託研究費
A1: =計畫經費彙總表!A1 -> 五常物業規劃顧問股份(閉鎖型)有限公司
A2: SIIR計畫－委託研究費(112年××月)
A4: 1.技轉(委託)項目: | E4: 2.技轉(委託)對象：
A5: 3.合約期間:00年00月00日~00年00月00日 | E5: 4.合約總額：
A6: 5.付款方式： | F6: 金額單位:元
A7: 付款期數 | B7: 傳票日期 | C7: 傳票號碼 | D7: 發票日期 | E7: 發票編號 | F7: 金額
A8: 第 1 期 | E8: AV23182456 | F8: 200000
A9: 第 2 期 | E9: EW86973745 | F9: 150000
A15: 合 計 | F15: =ROUND(SUM(F8:F14),0) -> 350000
A17: 註1：營業稅不得報支。
A18: 註2：委託研究之對象應與計畫書所列相符，金額應與原始憑證（如：統一發票或收據）相符。
A19: 註3：帳務查核時應備妥下列文件備查:1.委託研究契約書。(2)統一發票（或收據）、或國外之INVOICE(或RECEIPT)及匯兌水單。
A21: 計畫主持人: | D21: 主辦會計: | F21: 填表人：

Sheet 委託勞務費
A1: =計畫經費彙總表!A1 -> 五常物業規劃顧問股份(閉鎖型)有限公司
A2: SIIR計畫－委託勞務費(112年××月)
A4: 1.技轉(委託)項目: | E4: 2.技轉(委託)對象：
A5: 3.合約期間:00年00月00日~00年00月00日 | E5: 4.合約總額：
A6: 5.付款方式： | F6: 金額單位:元
A7: 付款期數 | B7: 傳票日期 | C7: 傳票號碼 | D7: 發票日期 | E7: 發票編號 | F7: 金額
A8: 第 1 期 | E8: AV23182456 | F8: 300000
A9: 第 2 期 | E9: EW86973745 | F9: 100000
A15: 合 計 | F15: =ROUND(SUM(F8:F14),0) -> 400000
A17: 註1：營業稅不得報支。
A18: 註2：委託勞務之對象應與計畫書所列相符，金額應與原始憑證（如：統一發票或收據）相符。
A19: 註3：帳務查核時應備妥下列文件備查:1.委託勞務契約書。(2)統一發票（或收據）、或國外之INVOICE(或RECEIPT)及匯兌水單。
A21: 計畫主持人: | D21: 主辦會計: | F21: 填表人：

Sheet 國內差旅費
A1: =計畫經費彙總表!A1 -> 五常物業規劃顧問股份(閉鎖型)有限公司
A2: SIIR計畫－國內差旅費(112年××月)
N3: 金額單元:元
A4: 姓名 | B4: 職稱 | C4: 出差期間 | D4: 天數 | E4: 地點 | F4: 事 由 | G4: 傳票日期 | H4: 傳票號碼 | I4: 機票 | J4: 車資 | K4: 住宿費 | L4: 膳雜費 | M4: 其他 | N4: 合計
A6: 1.××× | B6: 經理 | C6: 3月14-15日 | D6: 2 | E6: 塑膠中心 | F6: 討論勞務規格 | J6: 300 | K6: 1000 | L6: 550 | N6: =ROUND(SUM(I6:M6),0) -> 1850
A7: 2.××× | B7: 工程師 | N7: =ROUND(SUM(I7:M7),0) -> 0
N8: =ROUND(SUM(I8:M8),0) -> 0
N9: =ROUND(SUM(I9:M9),0) -> 0
N10: =ROUND(SUM(I10:M10),0) -> 0
N11: =ROUND(SUM(I11:M11),0) -> 0
N12: =ROUND(SUM(I12:M12),0) -> 0
N13: =ROUND(SUM(I13:M13),0) -> 0
A14: 合 計 | N14: =ROUND(SUM(N5:N13),0) -> 1850
A16: 註1：出差人員僅限本計畫計畫人員，且出差事由應與本專案計畫有關。
A17: 註2：差旅費之膳雜費計算應不超過營利事業所得稅查核準則規定。
A18: 註3：帳務查核時應備妥下列文件備查:(1)搭乘飛機，應檢附機票票根或登機證存根及國際線航空機票購票證明單或旅行業代收轉付收據；
A19: 其餘交通費，應檢附原始單據或旅行業代收轉付 收據。(2)乘坐輪船，應提供船票或輪船公司出具之證明。
A20: (3)火車、汽車之車資，以經手人（即出差人）之證明為憑。但包租計程車應取具車行證明及經手人或出差人證明。(4)住宿費收據或發票。
A21: (5)出差報銷單及公司差旅費報銷規定。(6)涉及外幣支付時應附當時之外幣匯率表。
B22: 計畫主持人: | F22: 主辦會計: | K22: 填表人：

Sheet 國外差旅費
A1: =計畫經費彙總表!A1 -> 五常物業規劃顧問股份(閉鎖型)有限公司
A2: SIIR計畫－國外差旅費(112年××月)
N3: 金額單元:元
A4: 姓名 | B4: 職稱 | C4: 出差期間 | D4: 天數 | E4: 地點 | F4: 事 由 | G4: 傳票日期 | H4: 傳票號碼 | I4: 機票 | J4: 車資 | K4: 住宿費 | L4: 膳雜費 | M4: 其他 | N4: 合計
A6: 1.××× | B6: 經理 | C6: 3月17-18日 | D6: 2 | E6: XX | F6: 討論勞務規格 | I6: 1000 | K6: 450 | L6: 550 | N6: =ROUND(SUM(I6:M6),0) -> 2000
A7: 2.××× | B7: 工程師 | N7: =ROUND(SUM(I7:M7),0) -> 0
N8: =ROUND(SUM(I8:M8),0) -> 0
N9: =ROUND(SUM(I9:M9),0) -> 0
N10: =ROUND(SUM(I10:M10),0) -> 0
N11: =ROUND(SUM(I11:M11),0) -> 0
N12: =ROUND(SUM(I12:M12),0) -> 0
N13: =ROUND(SUM(I13:M13),0) -> 0
A14: 合 計 | N14: =ROUND(SUM(N5:N13),0) -> 2000
A16: 註1：出差人員僅限本計畫計畫人員，且出差事由應與本專案計畫有關。
A17: 註2：差旅費之膳雜費計算應不超過營利事業所得稅查核準則規定。
A18: 註3：帳務查核時應備妥下列文件備查:(1)搭乘飛機，應檢附機票票根或登機證存根及國際線航空機票購票證明單或旅行業代收轉付收據；
A19: 其餘交通費，應檢附原始單據或旅行業代收轉付 收據。(2)乘坐輪船，應提供船票或輪船公司出具之證明。
A20: (3)火車、汽車之車資，以經手人（即出差人）之證明為憑。但包租計程車應取具車行證明及經手人或出差人證明。(4)住宿費收據或發票。
A21: (5)出差報銷單及公司差旅費報銷規定。(6)涉及外幣支付時應附當時之外幣匯率表。
B22: 計畫主持人: | F22: 主辦會計: | K22: 填表人：

Sheet 市場驗證費
A1: =計畫經費彙總表!A1 -> 五常物業規劃顧問股份(閉鎖型)有限公司
A2: SIIR計畫－市場驗證費(112年××月)
J3: 金額單位:元
A4: 傳票日期 | B4: 傳票號碼 | C4: 發票日期 | D4: 發票編號 | E4: 供應商 | F4: 發票內容 (註2) | G4: 對照計畫書所列項目 (註1) | H4: 數量 | I4: 單價 | J4: 金額 (不含營業稅)
A6: 112.4.22 | D6: AB12345678 | E6: ×× | H6: 1 | J6: 1200
A7: 112.4.25 | D7: AB13145676 | E7: ×× | H7: 3 | J7: 6000
A18: 合 計 | J18: =ROUND(SUM(J5:J17),0) -> 7200
A20: 註1：「對照計畫書所列項目」名稱需與計畫書所列之項目名稱一致。
A21: 註2：「發票內容」請依發票填寫所列項目。
A22: 註3：營業稅不得報支。
A23: 註4：帳務查核時應備妥下列文件備查:1.應提供統一發票、收據或進口結匯單據與invoice。2.涉及外幣支付時應附當時之外幣匯率表。3、廣告樣張（樣張上應印有營利事業名稱
A24: 、品牌名或與計畫有相關之資訊)。
A25: 註5：贈送樣品或商品饋贈之項目上限不得逾本科目10%，單份不得逾新台幣500元。
A26: 註6：贊助公益或體育活動具有廣告性質之各項費用應取得統一發票或合法憑證，並檢附載有活動名稱及營利事業名稱之相關廣告品。
A27: 註7：活動臨時聘用人力費用須提供如人事費科目之查核資料。
A28: 註8：活動臨時聘用人力費用，時薪不得低於政府公告最低時薪標準，且不得超過本經費科目10%。
A30: 計畫主持人: | F30: 主辦會計: | I30: 填表人：

Sheet 工作表2
