Workbook

Sheet 2501現金日記帳 
A1: 聊閣咖啡重新店日記帳
A2: 日期 | B2: 營業收入 | C2: 現金收入 | D2: LINE PAY | E2: 街口支付 | F2: 外送平台 | G2: 點點付 | H2: 營業費用 | I2: 當日損益 | L2: 保管金額 | M2: 現金收支 | N2: 現金餘額 | O2: 溢領金額
A3: 45658 | B3: 4635 | C3: 4280 | D3: 100 | E3: 295 | H3: ='2501費用明細憑證'!E3 -> 5840 | I3: =B3-C3-D3-E3-F3-G3-H3+5840 -> -40 | K3: 吳献堂 | L3: =C27+C24+C21+C18+C15+C12+C9+C6 -> 38890 | M3: 11170 | N3: =L3-M3 -> 27720 | O3: =N3-(H36/2) -> 19016.833
A4: 45659 | B4: 4940 | C4: 3735 | D4: 290 | E4: 135 | F4: 735 | G4: 125 | H4: ='2501費用明細憑證'!E4 -> 0 | I4: =B4-C4-D4-E4-F4-G4-H4 -> -80 | K4: 江政隆 | L4: =C3+C4+C5+C7+C8+C10+C11+C13+C14+C16+C17+C19+C20+C22+C23+C25+C26+C28 -> 77810 | M4: =60000+10020 -> 70020 | N4: =L4-M4 -> 7790 | O4: =N4+N6-H36-H36 -> -14713.667
A5: 45660 | B5: 5375 | C5: 2815 | D5: 840 | E5: 55 | H5: ='2501費用明細憑證'!E5 -> 1750 | I5: =B5-C5-D5-E5-F5-G5-H5 -> -85 | K5: 林權松 | L5: =C9 -> 4400 | N5: =L5-M5 -> 4400 | O5: =N5-(H36/2) -> -4303.1667
A6: 45661 | B6: 6850 | C6: 6100 | D6: 265 | E6: 40 | H6: ='2501費用明細憑證'!E6 -> 11170 | I6: =B6-C6-D6-E6-F6-G6-H6+11170 -> 445 | K6: 銀行存款 | L6: 12309 | N6: =L6-M6 -> 12309
A7: 45662 | B7: 7730 | C7: 7005 | D7: 705 | E7: 40 | H7: ='2501費用明細憑證'!E7 -> 0 | I7: =B7-C7-D7-E7-F7-G7-H7 -> -20 | K7: 應付賬款 | N7: ='2409費用明細憑證'!E33 -> 0
A8: 45663 | B8: 4910 | C8: 3082 | D8: 510 | E8: 455 | G8: 125 | H8: ='2501費用明細憑證'!E8 -> 795 | I8: =B8-C8-D8-E8-F8-G8-H8 -> -57 | K8: 流動現金 | N8: =SUM(N3:N6)+M7 -> 52219
A9: 45664 | B9: 5245 | C9: 4400 | D9: 835 | E9: 70 | H9: ='2501費用明細憑證'!E9 -> 0 | I9: =B9-C9-D9-E9-F9-G9-H9 -> -60 | K9: 營運預備金 | N9: 6000
A10: 45665 | B10: 4245 | C10: 3425 | D10: 735 | E10: 155 | H10: ='2501費用明細憑證'!E10 -> 1590 | I10: =B10-C10-D10-E10-F10-G10-H10 -> -1660 | K10: 現金總計 | N10: =SUM(N8:N9) -> 58219
A11: 45666 | B11: 3530 | C11: 3220 | D11: 130 | E11: 205 | H11: ='2501費用明細憑證'!E11 -> 0 | I11: =B11-C11-D11-E11-F11-G11-H11 -> -25
A12: 45667 | B12: 5340 | C12: 3300 | D12: 1050 | E12: 185 | F12: 300 | H12: ='2501費用明細憑證'!E12 -> 768 | I12: =B12-C12-D12-E12-F12-G12-H12 -> -263
A13: 45668 | B13: 4245 | C13: 4000 | D13: 245 | E13: 40 | H13: ='2501費用明細憑證'!E13 -> 0 | I13: =B13-C13-D13-E13-F13-G13-H13 -> -40 | K13: 當日損益
A14: 45669 | B14: 7269 | C14: 5780 | D14: 540 | E14: 90 | F14: 900 | H14: ='2501費用明細憑證'!E14 -> 0 | I14: =B14-C14-D14-E14-F14-G14-H14 -> -41 | K14: 紅字→多錢
A15: 45670 | B15: 4280 | C15: 3480 | D15: 295 | E15: 545 | H15: ='2501費用明細憑證'!E15 -> 530 | I15: =B15-C15-D15-E15-F15-G15-H15 -> -570 | K15: 黑字→少錢
A16: 45671 | B16: 5640 | C16: 5260 | D16: 350 | E16: 55 | H16: ='2501費用明細憑證'!E16 -> 0 | I16: =B16-C16-D16-E16-F16-G16-H16 -> -25
A17: 45672 | B17: 4520 | C17: 3800 | D17: 500 | E17: 45 | F17: 210 | H17: ='2501費用明細憑證'!E17 -> 60530 | I17: =B17-C17-D17-E17-F17-G17-H17+60000 -> -565
A18: 45673 | B18: 4305 | C18: 3500 | D18: 70 | E18: 55 | H18: ='2501費用明細憑證'!E18 -> 0 | I18: =B18-C18-D18-E18-F18-G18-H18 -> 680
A19: 45674 | B19: 6165 | C19: 4514 | D19: 630 | E19: 240 | H19: ='2501費用明細憑證'!E19 -> 795 | I19: =B19-C19-D19-E19-F19-G19-H19 -> -14
A20: 45675 | B20: 6810 | C20: 5105 | D20: 420 | E20: 1030 | F20: 210 | G20: 85 | H20: ='2501費用明細憑證'!E20 -> 0 | I20: =B20-C20-D20-E20-F20-G20-H20 -> -40 | P20: 4514
A21: 45676 | B21: 7165 | C21: 6810 | D21: 885 | E21: 40 | H21: ='2501費用明細憑證'!E21 -> 0 | I21: =B21-C21-D21-E21-F21-G21-H21 -> -570 | P21: 5105
A22: 45677 | B22: 6275 | C22: 4605 | D22: 555 | E22: 95 | F22: 265 | H22: ='2501費用明細憑證'!E22 -> 795 | I22: =B22-C22-D22-E22-F22-G22-H22 -> -40 | P22: 6810
A23: 45678 | B23: 3480 | C23: 3220 | D23: 265 | E23: 80 | H23: ='2501費用明細憑證'!E23 -> 0 | I23: =B23-C23-D23-E23-F23-G23-H23 -> -85 | P23: 4605
A24: 45679 | B24: 6295 | C24: 4800 | D24: 980 | E24: 110 | H24: ='2501費用明細憑證'!E24 -> 795 | I24: =B24-C24-D24-E24-F24-G24-H24 -> -390 | P24: 3220
A25: 45680 | B25: 5870 | C25: 5221 | D25: 660 | E25: 100 | H25: ='2501費用明細憑證'!E25 -> 0 | I25: =B25-C25-D25-E25-F25-G25-H25 -> -111 | P25: 4800
A26: 45681 | B26: 7385 | C26: 5008 | D26: 1030 | E26: 40 | F26: 560 | H26: ='2501費用明細憑證'!E26 -> 795 | I26: =B26-C26-D26-E26-F26-G26-H26 -> -48 | P26: 5221
A27: 45682 | B27: 6637 | C27: 6500 | D27: 395 | E27: 115 | H27: ='2501費用明細憑證'!E27 -> 0 | I27: =B27-C27-D27-E27-F27-G27-H27 -> -373 | P27: 5008
A28: 45683 | B28: 4400 | C28: 3735 | D28: 560 | E28: 140 | H28: ='2501費用明細憑證'!E28 -> 0 | I28: =B28-C28-D28-E28-F28-G28-H28 -> -35 | P28: 6500
A29: 45684 | H29: ='2501費用明細憑證'!E29 -> 0 | I29: =B29-C29-D29-E29-F29-G29-H29 -> 0 | P29: 3735
A30: 45685 | H30: ='2501費用明細憑證'!E30 -> 0 | I30: =B30-C30-D30-E30-F30-G30-H30 -> 0
A31: 45686 | H31: ='2501費用明細憑證'!E31 -> 0 | I31: =B31-C31-D31-E31-F31-G31-H31 -> 0
A32: 45687 | H32: ='2501費用明細憑證'!E32 -> 0 | I32: =B32-C32-D32-E32-F32-G32-H32 -> 0
A33: 45688 | H33: ='2501費用明細憑證'!E33 -> 0 | I33: =B33-C33-D33-E33-F33-G33-H33 -> 0
C34: =SUM(C3:C33) -> 116700 | D34: =SUM(D3:D33) -> 13840 | E34: =SUM(E3:E33) -> 4455
A35: 項目 | B35: 月營業額 | C35: 費用總額 | D35: 毛利 | G35: 帳面餘絀 | H35: 每股可分淨額
A36: 小計 | B36: =SUM(B3:B34) -> 143541 | C36: ='2501費用明細憑證'!E34 -> 86153 | D36: =B36-C36 -> 57388 | G36: =C34-C36+L6 -> 42856 | H36: =N8/3 -> 17406.333

Sheet 2412現金日記帳  
A1: 聊閣咖啡重新店日記帳
A2: 日期 | B2: 營業收入 | C2: 現金收入 | D2: LINE PAY | E2: 街口支付 | F2: 外送平台 | G2: 點點付 | H2: 營業費用 | I2: 當日損益 | L2: 保管金額 | M2: 現金收支 | N2: 現金餘額 | O2: 溢領金額
A3: 45627 | B3: 7150 | C3: 5010 | D3: 2105 | H3: ='2412費用明細憑證 '!E3 -> 0 | I3: =B3-C3-D3-E3-F3-G3-H3 -> 35 | K3: 吳献堂 | L3: =C3+C4+C5+C6+C7+C8+C9+C10+C11+C12+C14+C16+C17+C18+C19+C22+C23+C28+C29+C31+C32+C33 -> 105505 | M3: =26000+14000+8125+14617+8350 -> 71092 | N3: =L3-M3 -> 34413 | O3: =N3-H36 -> 10676.333
A4: 45628 | B4: 6255 | C4: 3250 | D4: 353 | F4: 425 | H4: ='2412費用明細憑證 '!E4 -> 856 | I4: =B4-C4-D4-E4-F4-G4-H4 -> 1371 | K4: 江政隆 | L4: =C13+C15+C20+C21+C25+C24+C26+C27+C13 -> 36600 | M4: =34000-14617+1000+12000+790+120+560+30+5000+4000 -> 42883 | N4: =L4-M4 -> -6283 | O4: =N4+N6-H36 -> -3539.6667
A5: 45629 | B5: 5305 | C5: 4510 | D5: 960 | H5: ='2412費用明細憑證 '!E5 -> 0 | I5: =B5-C5-D5-E5-F5-G5-H5 -> -165 | K5: 林權松 | L5: =C20 -> 4600 | M5: -12000 | N5: =L5-M5 -> 16600 | O5: =N5-H36 -> -7136.6667
A6: 45630 | B6: 6245 | C6: 5750 | D6: 495 | H6: ='2412費用明細憑證 '!E6 -> 0 | I6: =B6-C6-D6-E6-F6-G6-H6 -> 0 | K6: 銀行存款 | L6: =26480 -> 26480 | N6: =L6-M6 -> 26480
A7: 45631 | B7: 6805 | C7: 3840 | D7: 565 | E7: 125 | H7: ='2412費用明細憑證 '!E7 -> 14000 | I7: =B7-C7-D7-E7-F7-G7-H7+14000 -> 2275 | K7: 應付賬款 | N7: ='2409費用明細憑證'!E33 -> 0
A8: 45632 | B8: 6335 | C8: 5200 | D8: 500 | E8: 125 | F8: 640 | H8: ='2412費用明細憑證 '!E8 -> 0 | I8: =B8-C8-D8-E8-F8-G8-H8 -> -130 | K8: 流動現金 | N8: =SUM(N3:N6)+M7 -> 71210
A9: 45633 | B9: 7765 | C9: 7350 | D9: 420 | E9: 55 | G9: 155 | H9: ='2412費用明細憑證 '!E9 -> 0 | I9: =B9-C9-D9-E9-F9-G9-H9 -> -215 | K9: 營運預備金 | N9: 6000
A10: 45634 | B10: 6335 | C10: 5380 | D10: 450 | E10: 0 | F10: 400 | H10: ='2412費用明細憑證 '!E10 -> 500 | I10: =B10-C10-D10-E10-F10-G10-H10 -> -395 | K10: 現金總計 | N10: =SUM(N8:N9) -> 77210
A11: 45635 | B11: 4420 | C11: 3000 | D11: 185 | E11: 45 | F11: 215 | H11: ='2412費用明細憑證 '!E11 -> 0 | I11: =B11-C11-D11-E11-F11-G11-H11 -> 975
A12: 45636 | B12: 5110 | C12: 4670 | D12: 435 | E12: 160 | H12: ='2412費用明細憑證 '!E12 -> 0 | I12: =B12-C12-D12-E12-F12-G12-H12 -> -155
A13: 45637 | B13: 4885 | C13: 4000 | D13: 790 | E13: 120 | H13: ='2412費用明細憑證 '!E13 -> 795 | I13: =B13-C13-D13-E13-F13-G13-H13 -> -820 | K13: 當日損益
A14: 45638 | B14: 5100 | C14: 4300 | D14: 505 | E14: 0 | F14: 315 | H14: ='2412費用明細憑證 '!E14 -> 0 | I14: =B14-C14-D14-E14-F14-G14-H14 -> -20 | K14: 紅字→多錢
A15: 45639 | B15: 4670 | C15: 3200 | D15: 1140 | E15: 70 | F15: 325 | H15: ='2412費用明細憑證 '!E15 -> 0 | I15: =B15-C15-D15-E15-F15-G15-H15 -> -65 | K15: 黑字→少錢
A16: 45640 | B16: 6715 | C16: 5440 | D16: 1025 | E16: 346 | F16: 215 | H16: ='2412費用明細憑證 '!E16 -> 4200 | I16: =B16-C16-D16-E16-F16-G16-H16+4000 -> -511
A17: 45641 | B17: 7090 | C17: 5500 | D17: 1125 | E17: 105 | H17: ='2412費用明細憑證 '!E17 -> 0 | I17: =B17-C17-D17-E17-F17-G17-H17 -> 360
A18: 45642 | B18: 7755 | C18: 6105 | D18: 590 | E18: 0 | H18: ='2412費用明細憑證 '!E18 -> 61060 | I18: =B18-C18-D18-E18-F18-G18-H18+60000 -> 0
A19: 45643 | B19: 6145 | C19: 5500 | D19: 615 | E19: 130 | G19: 355 | H19: ='2412費用明細憑證 '!E19 -> 8350 | I19: =B19-C19-D19-E19-F19-G19-H19+8350 -> -455
A20: 45644 | B20: 4955 | C20: 4600 | D20: 295 | E20: 0 | H20: ='2412費用明細憑證 '!E20 -> 0 | I20: =B20-C20-D20-E20-F20-G20-H20 -> 60
A21: 45645 | B21: 5850 | C21: 3800 | D21: 840 | E21: 450 | F21: 860 | H21: ='2412費用明細憑證 '!E21 -> 0 | I21: =B21-C21-D21-E21-F21-G21-H21 -> -100
A22: 45646 | B22: 4750 | C22: 3100 | D22: 790 | E22: 120 | F22: 340 | G22: 330 | H22: ='2412費用明細憑證 '!E22 -> 8125 | I22: =B22-C22-D22-E22-F22-G22-H22+8125 -> 70
A23: 45647 | B23: 6985 | C23: 5000 | D23: 1480 | E23: 0 | H23: ='2412費用明細憑證 '!E23 -> 530 | I23: =B23-C23-D23-E23-F23-G23-H23 -> -25
A24: 45648 | B24: 4550 | C24: 4800 | D24: 200 | E24: 155 | F24: 245 | G24: 0 | H24: ='2412費用明細憑證 '!E24 -> 5000 | I24: =B24-C24-D24-E24-F24-G24-H24+5000 -> -850
A25: 45649 | B25: 4840 | C25: 3700 | D25: 700 | E25: 55 | F25: 415 | H25: ='2412費用明細憑證 '!E25 -> 96 | I25: =B25-C25-D25-E25-F25-G25-H25 -> -126
A26: 45650 | B26: 5120 | C26: 4800 | D26: 485 | E26: 45 | H26: ='2412費用明細憑證 '!E26 -> 0 | I26: =B26-C26-D26-E26-F26-G26-H26 -> -210
A27: 45651 | B27: 4820 | C27: 3700 | D27: 1100 | E27: 55 | H27: ='2412費用明細憑證 '!E27 -> 0 | I27: =B27-C27-D27-E27-F27-G27-H27 -> -35
A28: 45652 | B28: 4565 | C28: 4300 | D28: 250 | E28: 0 | H28: ='2412費用明細憑證 '!E28 -> 87 | I28: =B28-C28-D28-E28-F28-G28-H28 -> -72
A29: 45653 | B29: 6885 | C29: 5600 | D29: 895 | E29: 120 | H29: ='2412費用明細憑證 '!E29 -> 530 | I29: =B29-C29-D29-E29-F29-G29-H29 -> -260
A30: 45654 | B30: 6490 | C30: 4380 | D30: 1535 | E30: 0 | F30: 425 | H30: ='2412費用明細憑證 '!E30 -> 0 | I30: =B30-C30-D30-E30-F30-G30-H30 -> 150
A31: 45655 | B31: 6690 | C31: 5600 | D31: 640 | E31: 155 | H31: ='2412費用明細憑證 '!E31 -> 430 | I31: =B31-C31-D31-E31-F31-G31-H31 -> -135
A32: 45656 | B32: 5105 | C32: 3000 | D32: 1380 | E32: 450 | F32: 440 | H32: ='2412費用明細憑證 '!E32 -> 0 | I32: =B32-C32-D32-E32-F32-G32-H32 -> -165
A33: 45657 | B33: 5380 | C33: 4100 | D33: 625 | E33: 55 | H33: ='2412費用明細憑證 '!E33 -> 1060 | I33: =B33-C33-D33-E33-F33-G33-H33 -> -460
C34: =SUM(C3:C33) -> 142485 | D34: =SUM(D3:D33) -> 23473 | E34: =SUM(E3:E33) -> 2941
A35: 項目 | B35: 月營業額 | C35: 費用總額 | D35: 毛利 | G35: 帳面餘絀 | H35: 每股可分淨額
A36: 小計 | B36: =SUM(B3:B34) -> 181070 | C36: ='2412費用明細憑證 '!E34 -> 104559 | D36: =B36-C36 -> 76511 | G36: =B36-C36-12620-12520 -> 51371 | H36: =N8/3 -> 23736.667

Sheet 2501費用明細憑證
A1: 聊閣咖啡重新店支出費用明細
A2: 費用明細表 | B2: 食材成本 | C2: 固定成本 | D2: 變動成本 | E2: 費用小計 | F2: 項目明細 | G2: 支付憑證
A3: 45658 | D3: 5840 | E3: =SUM(B3:D3) -> 5840 | F3: 營業稅金 | G3: 2410憑證
A4: 45659 | E4: =SUM(B4:D4) -> 0
A5: 45660 | D5: 1750 | E5: =SUM(B5:D5) -> 1750 | F5: 杯蓋
A6: 45661 | B6: 11170 | E6: =SUM(B6:D6) -> 11170 | F6: 咖啡豆
A7: 45662 | E7: =SUM(B7:D7) -> 0
A8: 45663 | B8: 795 | E8: =SUM(B8:D8) -> 795
A9: 45664 | E9: =SUM(B9:D9) -> 0
A10: 45665 | B10: 1590 | E10: =SUM(B10:D10) -> 1590
A11: 45666 | E11: =SUM(B11:D11) -> 0
A12: 45667 | C12: 768 | E12: =SUM(B12:D12) -> 768 | F12: 網路
A13: 45668 | E13: =SUM(B13:D13) -> 0
A14: 45669 | E14: =SUM(B14:D14) -> 0
A15: 45670 | B15: 530 | E15: =SUM(B15:D15) -> 530 | F15: 鮮奶
A16: 45671 | E16: =SUM(B16:D16) -> 0
A17: 45672 | B17: 530 | C17: 60000 | E17: =SUM(B17:D17) -> 60530 | F17: 房租
A18: 45673 | E18: =SUM(B18:D18) -> 0
A19: 45674 | B19: 795 | E19: =SUM(B19:D19) -> 795
A20: 45675 | E20: =SUM(B20:D20) -> 0
A21: 45676 | E21: =SUM(B21:D21) -> 0
A22: 45677 | B22: 795 | E22: =SUM(B22:D22) -> 795
A23: 45678 | E23: =SUM(B23:D23) -> 0
A24: 45679 | B24: 795 | E24: =SUM(B24:D24) -> 795 | F24: 鮮奶
A25: 45680 | E25: =SUM(B25:D25) -> 0
A26: 45681 | B26: 795 | E26: =SUM(B26:D26) -> 795
A27: 45682 | E27: =SUM(B27:D27) -> 0
A28: 45683 | E28: =SUM(B28:D28) -> 0
A29: 45684 | E29: =SUM(B29:D29) -> 0
A30: 45685 | E30: =SUM(B30:D30) -> 0
A31: 45686 | E31: =SUM(B31:D31) -> 0
A32: 45687 | E32: =SUM(B32:D32) -> 0
A33: 45688 | E33: =SUM(B33:D33) -> 0
B34: =SUM(B4:B33) -> 17795 | C34: =SUM(C4:C33) -> 60768 | D34: =SUM(D4:D33) -> 1750 | E34: =SUM(E3:E32) -> 86153

Sheet 2412費用明細憑證 
A1: 聊閣咖啡重新店支出費用明細
A2: 費用明細表 | B2: 食材成本 | C2: 固定成本 | D2: 變動成本 | E2: 費用小計 | F2: 項目明細 | G2: 支付憑證
A3: 45627 | E3: =SUM(B3:D3) -> 0 | G3: 2410憑證
A4: 45628 | D4: 856 | E4: =SUM(B4:D4) -> 856
A5: 45629 | E5: =SUM(B5:D5) -> 0
A6: 45630 | E6: =SUM(B6:D6) -> 0
A7: 45631 | B7: 14000 | E7: =SUM(B7:D7) -> 14000 | F7: 咖啡豆
A8: 45632 | E8: =SUM(B8:D8) -> 0
A9: 45633 | E9: =SUM(B9:D9) -> 0
A10: 45634 | B10: 500 | E10: =SUM(B10:D10) -> 500 | F10: 牛奶
A11: 45635 | E11: =SUM(B11:D11) -> 0
A12: 45636 | E12: =SUM(B12:D12) -> 0
A13: 45637 | B13: 795 | E13: =SUM(B13:D13) -> 795 | F13: 鮮奶
A14: 45638 | E14: =SUM(B14:D14) -> 0
A15: 45639 | E15: =SUM(B15:D15) -> 0
A16: 45640 | B16: 4200 | E16: =SUM(B16:D16) -> 4200 | F16: 果糖、奶精
A17: 45641 | E17: =SUM(B17:D17) -> 0
A18: 45642 | B18: 1060 | C18: 60000 | E18: =SUM(B18:D18) -> 61060 | F18: 房租、鮮奶
A19: 45643 | D19: 8350 | E19: =SUM(B19:D19) -> 8350 | F19: 電費
A20: 45644 | E20: =SUM(B20:D20) -> 0
A21: 45645 | E21: =SUM(B21:D21) -> 0
A22: 45646 | D22: 8125 | E22: =SUM(B22:D22) -> 8125 | F22: 杯子
A23: 45647 | B23: 530 | E23: =SUM(B23:D23) -> 530
A24: 45648 | B24: 5000 | E24: =SUM(B24:D24) -> 5000 | F24: 紅茶、綠茶
A25: 45649 | B25: 96 | E25: =SUM(B25:D25) -> 96 | F25: 補鮮奶
A26: 45650 | E26: =SUM(B26:D26) -> 0
A27: 45651 | E27: =SUM(B27:D27) -> 0
A28: 45652 | D28: 87 | E28: =SUM(B28:D28) -> 87 | F28: 電話費
A29: 45653 | B29: 530 | E29: =SUM(B29:D29) -> 530 | F29: 鮮奶
A30: 45654 | E30: =SUM(B30:D30) -> 0
A31: 45655 | B31: 430 | E31: =SUM(B31:D31) -> 430 | F31: 鮮奶
A32: 45656 | B32: 0 | E32: =SUM(B32:D32) -> 0
A33: 45657 | B33: 1060 | E33: =SUM(B33:D33) -> 1060 | F33: 鮮奶
B34: =SUM(B4:B33) -> 28201 | C34: =SUM(C4:C33) -> 60000 | D34: =SUM(D4:D33) -> 17418 | E34: =SUM(E3:E32) -> 104559

Sheet 2411費用明細憑證
A1: 聊閣咖啡重新店支出費用明細
A2: 費用明細表 | B2: 食材成本 | C2: 固定成本 | D2: 變動成本 | E2: 費用小計 | F2: 項目明細 | G2: 支付憑證
G3: 2410憑證
A4: 45597 | D4: 0 | E4: =SUM(B4:D4) -> 0
A5: 45598 | D5: 5700 | E5: =SUM(B5:D5) -> 5700 | F5: 咖啡機修理
A6: 45599 | B6: 457 | D6: 100 | E6: =SUM(B6:D6) -> 557 | F6: 肉桂、鮮奶、鬆緊帶
A7: 45600 | E7: =SUM(B7:D7) -> 0
A8: 45601 | B8: 712 | C8: 768 | E8: =SUM(B8:D8) -> 1480 | F8: 電話費768吐司712
A9: 45602 | B9: 530 | D9: 1000 | E9: =SUM(B9:D9) -> 1530 | F9: 鮮奶530電話1000
A10: 45603 | E10: =SUM(B10:D10) -> 0
A11: 45604 | B11: 530 | E11: =SUM(B11:D11) -> 530 | F11: 鮮奶530
A12: 45605 | E12: =SUM(B12:D12) -> 0
A13: 45606 | E13: =SUM(B13:D13) -> 0
A14: 45607 | B14: 530 | E14: =SUM(B14:D14) -> 530 | F14: 鮮奶530
A15: 45608 | B15: =12600+530 -> 13130 | E15: =SUM(B15:D15) -> 13130 | F15: 鮮奶530咖啡豆12600
A16: 45609 | B16: =3410 -> 3410 | E16: =SUM(B16:D16) -> 3410 | F16: 奶精果糖
A17: 45610 | B17: 530 | E17: =SUM(B17:D17) -> 530 | F17: 鮮奶530
A18: 45611 | E18: =SUM(B18:D18) -> 0
A19: 45612 | C19: 60000 | E19: =SUM(B19:D19) -> 60000 | F19: 房租
A20: 45613 | B20: 795 | E20: =SUM(B20:D20) -> 795 | F20: 鮮奶795
A21: 45614 | E21: =SUM(B21:D21) -> 0
A22: 45615 | E22: =SUM(B22:D22) -> 0
A23: 45616 | E23: =SUM(B23:D23) -> 0
A24: 45617 | B24: 530 | E24: =SUM(B24:D24) -> 530 | F24: 鮮奶
A25: 45618 | E25: =SUM(B25:D25) -> 0
A26: 45619 | B26: 530 | E26: =SUM(B26:D26) -> 530 | F26: 鮮奶
A27: 45620 | B27: 1000 | E27: =SUM(B27:D27) -> 1000 | F27: 話梅
A28: 45621 | B28: 530 | E28: =SUM(B28:D28) -> 530 | F28: 鮮奶
A29: 45622 | B29: 12620 | E29: =SUM(B29:D29) -> 12620 | F29: 豆子
A30: 45623 | E30: =SUM(B30:D30) -> 0
A31: 45624 | B31: 795 | E31: =SUM(B31:D31) -> 795 | F31: 鮮奶
A32: 45625 | E32: =SUM(B32:D32) -> 0
A33: 45626 | B33: 530 | E33: =SUM(B33:D33) -> 530 | F33: 鮮奶
B34: =SUM(B4:B33) -> 37159 | C34: =SUM(C4:C33) -> 60768 | D34: =SUM(D4:D33) -> 6800 | E34: =SUM(E4:E33) -> 104727

Sheet 2411現金日記帳 
A1: 聊閣咖啡重新店日記帳
A2: 日期 | B2: 營業收入 | C2: 現金收入 | E2: 街口支付 | F2: 外送平台 | G2: 點點付 | H2: 營業費用 | I2: 當日損益 | L2: 保管金額 | M2: 現金收支 | N2: 現金餘額 | O2: 溢領金額
A3: 45597 | B3: 6125 | C3: 4820 | D3: 930 | E3: 385 | F3: 0 | G3: 0 | H3: ='2411費用明細憑證'!E3 -> 0 | I3: =B3-C3-D3-E3-F3-G3-H3 -> -10 | K3: 吳献堂 | L3: =C4+C5+C7+C8+C10+C11+C13+C14+C17+C19+C23+C25+C26+C31+C32+C16 -> 69220 | M3: =40000+12620+12560 -> 65180 | N3: =L3-M3 -> 4040 | O3: =N3-H35 -> -14617.333
A4: 45598 | B4: 8350 | C4: 2950 | D4: 925 | E4: 165 | F4: 0 | G4: 0 | H4: ='2411費用明細憑證'!E5 -> 5700 | I4: =B4-C4-D4-E4-F4-G4-H4 -> -1390 | K4: 江政隆 | L4: =C3+C6+C9+C12+C15+C18+C21+C22+C24+C27+C28+C29+C30 -> 48495 | M4: =20000+3410+1000 -> 24410 | N4: =L4-M4 -> 24085 | O4: =N4+N6-H35 -> 30074.667
A5: 45599 | B5: 5960 | C5: 4900 | D5: 385 | E5: 185 | F5: 215 | G5: 0 | H5: ='2411費用明細憑證'!E6 -> 557 | I5: =B5-C5-D5-E5-F5-G5-H5 -> -282 | K5: 林權松 | L5: =C20 -> 3200 | M5: 0 | N5: =L5-M5 -> 3200 | O5: =N5-H35 -> -15457.333
A6: 45600 | B6: 3390 | C6: 2530 | D6: 625 | E6: 65 | F6: 260 | G6: 85 | H6: ='2411費用明細憑證'!E7 -> 0 | I6: =B6-C6-D6-E6-F6-G6-H6 -> -175 | K6: 銀行存款 | L6: =13538+11109 -> 24647 | N6: =L6-M6 -> 24647
A7: 45601 | B7: =1100+4005 -> 5105 | C7: 3000 | D7: 660 | E7: 65 | F7: 0 | G7: 0 | H7: ='2411費用明細憑證'!E8 -> 1480 | I7: =B7-C7-D7-E7-F7-G7-H7 -> -100 | K7: 應付賬款 | N7: ='2409費用明細憑證'!E33 -> 0
A8: 45602 | B8: =3730+1200 -> 4930 | C8: 2600 | D8: 835 | E8: 0 | F8: 0 | G8: 145 | H8: ='2411費用明細憑證'!E9 -> 1530 | I8: =B8-C8-D8-E8-F8-G8-H8 -> -180 | K8: 流動現金 | N8: =SUM(N3:N6)+M7 -> 55972
A9: 45603 | B9: 5660 | C9: 3605 | D9: 1910 | E9: 0 | F9: 0 | G9: 275 | H9: ='2411費用明細憑證'!E10 -> 0 | I9: =B9-C9-D9-E9-F9-G9-H9 -> -130 | K9: 營運預備金 | N9: 6000
A10: 45604 | B10: 6900 | C10: 5810 | D10: 715 | E10: 0 | F10: 340 | G10: 145 | H10: ='2411費用明細憑證'!E11 -> 530 | I10: =B10-C10-D10-E10-F10-G10-H10 -> -640 | K10: 現金總計 | N10: =SUM(N8:N9) -> 61972
A11: 45605 | B11: 5305 | C11: 4705 | D11: 560 | E11: 0 | F11: 595 | G11: 0 | H11: ='2411費用明細憑證'!E12 -> 0 | I11: =B11-C11-D11-E11-F11-G11-H11 -> -555
A12: 45606 | B12: 6500 | C12: 5400 | D12: 375 | E12: 140 | F12: 215 | G12: 505 | H12: ='2411費用明細憑證'!E13 -> 0 | I12: =B12-C12-D12-E12-F12-G12-H12 -> -135
A13: 45607 | B13: 6595 | C13: 4380 | D13: 585 | E13: 220 | F13: 0 | G13: 55 | H13: ='2411費用明細憑證'!E14 -> 530 | I13: =B13-C13-D13-E13-F13-G13-H13 -> 825 | K13: 當日損益
A14: 45608 | B14: 5470 | C14: 5050 | D14: 440 | E14: 0 | F14: 0 | G14: 0 | H14: ='2411費用明細憑證'!E15-12560 -> 570 | I14: =B14-C14-D14-E14-F14-G14-H14 -> -590 | K14: 紅字→多錢
A15: 45609 | B15: 3750 | C15: 2350 | D15: 995 | E15: 165 | F15: 0 | G15: 380 | H15: ='2411費用明細憑證'!E16-3410 -> 0 | I15: =B15-C15-D15-E15-F15-G15-H15 -> -140 | K15: 黑字→少錢
A16: 45610 | B16: 6430 | C16: 5775 | D16: 395 | E16: 260 | F16: 0 | G16: 0 | H16: ='2411費用明細憑證'!E17 -> 530 | I16: =B16-C16-D16-E16-F16-G16-H16 -> -530
A17: 45611 | B17: 7905 | C17: 6380 | D17: 700 | E17: 135 | F17: 225 | G17: 0 | H17: ='2411費用明細憑證'!E18 -> 0 | I17: =B17-C17-D17-E17-F17-G17-H17 -> 465
A18: 45612 | B18: 4610 | C18: 3750 | D18: 646 | E18: 40 | F18: 190 | G18: 0 | H18: ='2411費用明細憑證'!E19-60000 -> 0 | I18: =B18-C18-D18-E18-F18-G18-H18 -> -16
A19: 45613 | B19: 5690 | C19: 4630 | D19: 935 | E19: 140 | F19: 0 | G19: 0 | H19: ='2411費用明細憑證'!E20 -> 795 | I19: =B19-C19-D19-E19-F19-G19-H19 -> -810
A20: 45614 | B20: 4255 | C20: 3200 | D20: 215 | E20: 315 | F20: 0 | G20: 0 | H20: ='2411費用明細憑證'!E21 -> 0 | I20: =B20-C20-D20-E20-F20-G20-H20 -> 525
A21: 45615 | B21: 5235 | C21: 3800 | D21: 1275 | E21: 115 | F21: 0 | G21: 0 | H21: ='2411費用明細憑證'!E22 -> 0 | I21: =B21-C21-D21-E21-F21-G21-H21 -> 45
A22: 45616 | B22: 6830 | C22: 4525 | D22: 1485 | E22: 230 | G22: 0 | H22: ='2411費用明細憑證'!E23 -> 0 | I22: =B22-C22-D22-E22-F22-G22-H22 -> 590
A23: 45617 | B23: 5335 | C23: 4120 | D23: 210 | E23: 205 | G23: 0 | H23: ='2411費用明細憑證'!E24 -> 530 | I23: =B23-C23-D23-E23-F23-G23-H23 -> 270
A24: 45618 | B24: 4865 | C24: 3450 | D24: 420 | E24: 0 | G24: 0 | H24: 1000 | I24: =B24-C24-D24-E24-F24-G24-H24 -> -5
A25: 45619 | B25: 5516 | C25: 4100 | D25: 400 | E25: 95 | F25: 576 | G25: 375 | H25: ='2411費用明細憑證'!E26 -> 530 | I25: =B25-C25-D25-E25-F25-G25-H25 -> -560
A26: 45620 | B26: 5580 | C26: 4600 | D26: 450 | E26: 285 | F26: 220 | G26: 350 | H26: ='2411費用明細憑證'!E27 -> 1000 | I26: =B26-C26-D26-E26-F26-G26-H26 -> -1325
A27: 45621 | B27: 5530 | C27: 3725 | D27: 815 | E27: 120 | F27: 0 | G27: 350 | H27: ='2411費用明細憑證'!E28 -> 530 | I27: =B27-C27-D27-E27-F27-G27-H27 -> -10
A28: 45622 | B28: 4190 | C28: 3200 | D28: 995 | E28: 0 | F28: 0 | G28: 55 | H28: ='2411費用明細憑證'!E29-12620 -> 0 | I28: =B28-C28-D28-E28-F28-G28-H28 -> -60
A29: 45623 | B29: 4220 | C29: 3165 | D29: 700 | E29: 0 | F29: 440 | G29: 0 | H29: ='2411費用明細憑證'!E30 -> 0 | I29: =B29-C29-D29-E29-F29-G29-H29 -> -85
A30: 45624 | B30: 5350 | C30: 4175 | D30: 205 | E30: 0 | F30: 220 | G30: 0 | H30: ='2411費用明細憑證'!E31 -> 795 | I30: =B30-C30-D30-E30-F30-G30-H30 -> -45
A31: 45625 | B31: 4500 | C31: 2100 | D31: 780 | E31: 0 | F31: 0 | G31: 0 | H31: ='2411費用明細憑證'!E32 -> 0 | I31: =B31-C31-D31-E31-F31-G31-H31 -> 1620
A32: 45626 | B32: 4860 | C32: 4120 | D32: 690 | E32: 0 | F32: 300 | G32: 0 | H32: ='2411費用明細憑證'!E33 -> 530 | I32: =B32-C32-D32-E32-F32-G32-H32 -> -780
C33: =SUM(C3:C32) -> 120915 | D33: =SUM(D3:D32) -> 21256 | E33: =SUM(E3:E32) -> 3330
A34: 項目 | B34: 月營業額 | C34: 費用總額 | D34: 毛利 | G34: 帳面餘絀 | H34: 每股可分淨額
A35: 小計 | B35: =SUM(B3:B33) -> 164941 | C35: ='2411費用明細憑證'!E34 -> 104727 | D35: =B35-C35 -> 60214 | G35: =B35-C35-12620-12520 -> 35074 | H35: =N8/3 -> 18657.333

Sheet 2410現金日記帳
A1: 聊閣咖啡重新店日記帳
A2: 日期 | B2: 營業收入 | C2: 現金收入 | D2: linepay | E2: 街口支付 | F2: 點點付 | G2: 營業費用 | H2: 當日損益 | K2: 保管金額 | L2: 現金收支 | M2: 現金餘額 | N2: 溢領金額
A3: 45566 | B3: 5165 | C3: =3510 -> 3510 | D3: 990 | E3: 45 | F3: 0 | G3: ='2410費用明細憑證'!E3 -> 660 | H3: =(B3-D3-E3-F3-G3-C3) -> -40 | J3: 吳献堂 | K3: =C3+C5+C6+C8+C9+C10+C12+C14+C15+C17+C20+C21+C23+C24+C26+C27+C29+C30+C31+C33 -> 83515 | L3: =40000+11000+11715 -> 62715 | M3: =K3-L3 -> 20800 | N3: =M3-G35 -> 7061.6667
A4: 45567 | B4: 4995 | C4: 3730 | D4: 305 | E4: 165 | F4: 0 | G4: ='2410費用明細憑證'!E4 -> 795 | H4: =(B4-D4-E4-F4-G4-C4) -> 0 | J4: 江政隆 | K4: =C4+C7+C11+C13+C16+C19+C22+C25+C28+4830 -> 46566 | L4: =2348+15822+20030+530+855+700+1399+4831 -> 46515 | M4: =K4-L4 -> 51 | N4: =M4+M6-G35 -> 6541.6667
A5: 45568 | B5: 3790 | C5: 3450 | D5: 360 | E5: 0 | F5: 0 | G5: ='2410費用明細憑證'!E5 -> 11000 | H5: =(B5-D5-E5-F5-G5-C5)+11000 -> -20 | J5: 林權松 | K5: =C18+645 -> 5325 | L5: =1350+3840 -> 5190 | M5: =K5-L5 -> 135 | N5: =M5-G35 -> -13603.333
A6: 45569 | B6: 4790 | C6: 980 | D6: 610 | E6: 65 | F6: 0 | G6: ='2410費用明細憑證'!E6 -> 3120 | H6: =(B6-D6-E6-F6-G6-C6) -> 15 | J6: 銀行存款 | K6: =14037+12262 -> 26299 | L6: 6070 | M6: =K6-L6 -> 20229
A7: 45570 | B7: 6910 | C7: 6195 | D7: 660 | E7: 55 | F7: 0 | G7: ='2410費用明細憑證'!E7 -> 0 | H7: =(B7-D7-E7-F7-G7-C7) -> 0 | J7: 應付賬款 | M7: ='2409費用明細憑證'!E33 -> 0
A8: 45571 | B8: 6620 | C8: 5280 | D8: 875 | E8: 70 | F8: 770 | G8: ='2410費用明細憑證'!E8 -> 0 | H8: =(B8-D8-E8-F8-G8-C8) -> -375 | J8: 流動現金 | M8: =SUM(M3:M6)+L7 -> 41215
A9: 45572 | B9: 6795 | C9: 4100 | D9: 1100 | E9: 455 | F9: 275 | G9: ='2410費用明細憑證'!E9 -> 530 | H9: =(B9-D9-E9-F9-G9-C9) -> 335 | J9: 營運預備金 | M9: 6000
A10: 45573 | B10: 6655 | C10: 5010 | D10: 895 | E10: 0 | F10: 435 | G10: ='2410費用明細憑證'!E10 -> 570 | H10: =(B10-D10-E10-F10-G10-C10) -> -255 | J10: 現金總計 | M10: =SUM(M8:M9) -> 47215
A11: 45574 | B11: 5045 | C11: 3935 | D11: 315 | E11: 265 | F11: 0 | G11: ='2410費用明細憑證'!E11 -> 530 | H11: =(B11-D11-E11-F11-G11-C11) -> 0
A12: 45575 | B12: 7860 | C12: 5400 | D12: 895 | E12: 0 | F12: 1065 | G12: ='2410費用明細憑證'!E12 -> 0 | H12: =(B12-D12-E12-F12-G12-C12) -> 500
A13: 45576 | B13: 6635 | C13: 3870 | D13: 1020 | E13: 45 | F13: 905 | G13: ='2410費用明細憑證'!E13 -> 795 | H13: =(B13-D13-E13-F13-G13-C13) -> 0 | J13: 當日損益
A14: 45577 | B14: 8090 | C14: 8200 | D14: 360 | E14: 0 | F14: 0 | G14: ='2410費用明細憑證'!E14 -> 0 | H14: =(B14-D14-E14-F14-G14-C14) -> -470 | J14: 紅字→多錢
A15: 45578 | B15: 7550 | C15: 5865 | D15: 800 | E15: 0 | F15: =65+1050 -> 1115 | G15: ='2410費用明細憑證'!E15 -> 0 | H15: =(B15-D15-E15-F15-G15-C15) -> -230 | J15: 黑字→少錢
A16: 45579 | B16: 7305 | C16: 3816 | D16: 1150 | E16: 235 | F16: 0 | G16: ='2410費用明細憑證'!E16 -> 2104 | H16: =(B16-D16-E16-F16-G16-C16) -> 0
A17: 45580 | B17: 7930 | C17: 6510 | D17: 650 | E17: 175 | G17: ='2410費用明細憑證'!E17 -> 78941 | H17: =(B17-D17-E17-F17-G17-C17)+60030+18170 -> -146
A18: 45581 | B18: 5980 | C18: 4680 | D18: 355 | E18: 0 | F18: 245 | G18: ='2410費用明細憑證'!E18 -> 6865 | H18: =(B18-D18-E18-F18-G18-C18)+6070 -> -95
A19: 45582 | B19: 8375 | C19: 7135 | D19: 490 | E19: 120 | F19: 630 | G19: ='2410費用明細憑證'!E19 -> 0 | H19: =(B19-D19-E19-F19-G19-C19) -> 0
A20: 45583 | B20: 6365 | C20: 4800 | D20: 990 | E20: 65 | F20: 350 | G20: ='2410費用明細憑證'!E20 -> 12245 | H20: =(B20-D20-E20-F20-G20-C20)+11715 -> -370
A21: 45584 | B21: 4480 | C21: 3800 | D21: 380 | E21: 45 | F21: 380 | G21: ='2410費用明細憑證'!E21 -> 0 | H21: =(B21-D21-E21-F21-G21-C21) -> -125
A22: 45585 | B22: 6090 | C22: 4525 | D22: 1190 | E22: 0 | F22: 0 | G22: ='2410費用明細憑證'!E22 -> 0 | H22: =(B22-D22-E22-F22-G22-C22) -> 375
A23: 45586 | B23: 4855 | C23: 3000 | D23: 1175 | E23: 190 | F23: 200 | G23: ='2410費用明細憑證'!E23 -> 5720 | H23: =(B23-D23-E23-F23-G23-C23)+5190 -> -240
A24: 45587 | B24: 4945 | C24: 3000 | D24: 1050 | E24: 250 | F24: 0 | G24: ='2410費用明細憑證'!E24 -> 530 | H24: =(B24-D24-E24-F24-G24-C24) -> 115
A25: 45588 | B25: 4210 | C25: =3710+530 -> 4240 | D25: 500 | E25: 0 | F25: 0 | G25: ='2410費用明細憑證'!E25 -> 0 | H25: =(B25-D25-E25-F25-G25-C25)+530 -> 0
A26: 45589 | B26: 5580 | C26: 4900 | D26: 845 | E26: 0 | F26: 0 | G26: ='2410費用明細憑證'!E26 -> 0 | H26: =(B26-D26-E26-F26-G26-C26) -> -165
A27: 45590 | B27: 4970 | C27: 1230 | D27: 1540 | E27: 0 | F27: 0 | G27: ='2410費用明細憑證'!E27 -> 2519 | H27: =(B27-D27-E27-F27-G27-C27) -> -319
A28: 45591 | B28: 5165 | C28: 4290 | D28: 675 | E28: 0 | F28: 200 | G28: ='2410費用明細憑證'!E28 -> 0 | H28: =(B28-D28-E28-F28-G28-C28) -> 0
A29: 45592 | B29: 6425 | C29: 5000 | D29: 1095 | E29: 340 | F29: 495 | G29: ='2410費用明細憑證'!E29 -> 855 | H29: =(B29-D29-E29-F29-G29-C29)+855 -> -505
A30: 45593 | B30: 6965 | C30: 5100 | D30: 1010 | E30: 120 | F30: 0 | G30: ='2410費用明細憑證'!E30 -> 795 | H30: =(B30-D30-E30-F30-G30-C30) -> -60
A31: 45594 | B31: 4470 | C31: 3520 | D31: 415 | E31: 120 | F31: 0 | G31: ='2410費用明細憑證'!E31 -> 1038 | H31: =(B31-D31-E31-F31-G31-C31)+700 -> 77
A32: 45595 | B32: 5805 | C32: 4830 | D32: 275 | E32: 170 | F32: 0 | G32: ='2410費用明細憑證'!E32 -> 530 | H32: =(B32-D32-E32-F32-G32-C32) -> 0
A33: 45596 | B33: 860 | C33: 860 | D33: 180 | E33: 0 | F33: 0 | G33: ='2410費用明細憑證'!E33 -> 6230 | H33: =(B33-D33-E33-F33-G33-C33) -> -6410
A34: 項目 | B34: 月營業額 | C34: 費用總額 | D34: 毛利 | F34: 帳面餘絀 | G34: 每股可分淨額
A35: 小計 | B35: =SUM(B3:B33) -> 181675 | C35: =SUM(G3:G33) -> 136372 | D35: =B35-C35 -> 45303 | F35: =SUM(H3:H33) -> -8408 | G35: =M8/3 -> 13738.333

Sheet 2410費用明細憑證
A1: 聊閣咖啡重新店支出費用明細
A2: 費用明細表 | B2: 食材成本 | C2: 固定成本 | D2: 變動成本 | E2: 費用小計 | F2: 項目明細 | G2: 支付憑證
A3: 45566 | D3: 660 | E3: =SUM(B3:D3) -> 660 | F3: 瓦斯費 660 | G3: 2410憑證
A4: 45567 | B4: 795 | E4: =SUM(B4:D4) -> 795 | F4: 光泉 795
A5: 45568 | D5: 11000 | E5: =SUM(B5:D5) -> 11000 | F5: 修冰箱 11000
A6: 45569 | B6: =530+440 -> 970 | D6: 2150 | E6: =SUM(B6:D6) -> 3120 | F6: 鮮奶 530 紙杯 2150 厚片 440
A7: 45570 | E7: =SUM(B7:D7) -> 0
A8: 45571 | E8: =SUM(B8:D8) -> 0
A9: 45572 | B9: 530 | E9: =SUM(B9:D9) -> 530 | F9: 鮮奶 530
A10: 45573 | B10: 350 | D10: 220 | E10: =SUM(B10:D10) -> 570 | F10: 砂糖 350 電信費 220
A11: 45574 | B11: 530 | E11: =SUM(B11:D11) -> 530 | F11: 鮮奶 530
A12: 45575 | E12: =SUM(B12:D12) -> 0
A13: 45576 | B13: 795 | E13: =SUM(B13:D13) -> 795 | F13: 鮮奶 795
A14: 45577 | E14: =SUM(B14:D14) -> 0
A15: 45578 | E15: =SUM(B15:D15) -> 0
A16: 45579 | B16: =530+235 -> 765 | D16: =89+600+650 -> 1339 | E16: =SUM(B16:D16) -> 2104 | F16: 鮮奶 530 電話費 89 製冰機檢查費 600 製冰機材料費 650
A17: 45580 | B17: 741 | C17: 60000 | D17: =30+18170 -> 18200 | E17: =SUM(B17:D17) -> 78941 | F17: 房租 60000 匯費 30 麵包 741 電費 18170
A18: 45581 | B18: 795 | D18: 6070 | E18: =SUM(B18:D18) -> 6865 | F18: 鮮奶 795 保險 6070
A19: 45582 | E19: =SUM(B19:D19) -> 0
A20: 45583 | B20: 530 | D20: 11715 | E20: =SUM(B20:D20) -> 12245 | F20: 鮮奶 530 咖啡豆 11715
A21: 45584 | E21: =SUM(B21:D21) -> 0
A22: 45585 | E22: =SUM(B22:D22) -> 0
A23: 45586 | B23: =530+1350 -> 1880 | D23: 3840 | E23: =SUM(B23:D23) -> 5720 | F23: 光泉 530 焦糖糖漿2瓶 1350 十方 3840
A24: 45587 | B24: 530 | E24: =SUM(B24:D24) -> 530 | F24: 鮮奶 530
A25: 45588 | E25: =SUM(B25:D25) -> 0
A26: 45589 | E26: =SUM(B26:D26) -> 0
A27: 45590 | B27: =1900+530 -> 2430 | D27: 89 | E27: =SUM(B27:D27) -> 2519 | F27: 鮮奶 530 電話費 89 檸檬汁 1900
A28: 45591 | E28: =SUM(B28:D28) -> 0
A29: 45592 | D29: 855 | E29: =SUM(B29:D29) -> 855 | F29: 玻璃杯 855
A30: 45593 | B30: 795 | E30: =SUM(B30:D30) -> 795 | F30: 鮮奶 795
A31: 45594 | D31: =338+700 -> 1038 | E31: =SUM(B31:D31) -> 1038 | F31: 支架燈 338 標籤貼紙 700
A32: 45595 | B32: 530 | E32: =SUM(B32:D32) -> 530 | F32: 鮮奶 530
A33: 45596 | D33: =1399+4831 -> 6230 | E33: =SUM(B33:D33) -> 6230 | F33: 監視器鏡頭'營業稅
A34: 未結應付賬款 | E34: =SUM(B34:D34) -> 0
A35: 小計 | B35: =SUM(B4:B33) -> 12966 | C35: =SUM(C3:C33) -> 60000 | D35: =SUM(D3:D33) -> 63406 | E35: =SUM(E3:E33) -> 136372

Sheet 2409現金日記帳
A1: 聊閣咖啡重新店日記帳
A2: 日期 | B2: 營業收入 | C2: 現金收入 | D2: linepay | E2: 街口支付 | F2: 點點付 | G2: 營業費用 | H2: 當日損益 | K2: 保管金額 | L2: 現金收支 | M2: 現金餘額 | N2: 溢領金額
A3: 45536 | B3: 8383 | C3: 7200 | D3: 930 | E3: 0 | F3: 0 | G3: ='2409費用明細憑證'!E3 -> 0 | H3: =(B3-D3-E3-F3-G3-C3) -> 253 | J3: 吳献堂 | K3: =C3+C4+C5+C8+C9+C11+C12+C14+C15+C17+C18+C21+C26+C29+C30+C32 -> 80825 | L3: =10440+3800+32000+12165 -> 58405 | M3: =K3-L3 -> 22420 | N3: =M3-G34 -> 333
A4: 45537 | B4: 7305 | C4: 5330 | D4: 1115 | E4: 210 | F4: 0 | G4: ='2409費用明細憑證'!E4 -> 795 | H4: =(B4-D4-E4-F4-G4-C4) -> -145 | J4: 江政隆 | K4: =C6+C7+C10+C13+C16+C19+C22+C25+C28+C31+2000 -> 51246 | L4: =2070+7565+16000+550+88+1893+4700+1516+30 -> 34412 | M4: =K4-L4 -> 16834 | N4: =M4+M6-G34 -> 6019
A5: 45538 | B5: 6205 | C5: 5685 | D5: 560 | E5: 60 | F5: 0 | G5: ='2409費用明細憑證'!E5 -> 0 | H5: =(B5-D5-E5-F5-G5-C5) -> -100 | J5: 林權松 | K5: =4000+C24+C27+C20 -> 15735 | M5: =K5-L5 -> 15735 | N5: =M5-G34 -> -6352
A6: 45539 | B6: 6395 | C6: 5255 | D6: 610 | E6: 0 | F6: 0 | G6: ='2409費用明細憑證'!E6 -> 530 | H6: =(B6-D6-E6-F6-G6-C6) -> 0 | J6: 銀行存款 | K6: =15674+7598 -> 23272 | L6: 12000 | M6: =K6-L6 -> 11272
A7: 45540 | B7: 7245 | C7: 6330 | D7: 815 | E7: 100 | F7: 0 | G7: ='2409費用明細憑證'!E7 -> 2070 | H7: =(B7-D7-E7-F7-G7-C7)+2070 -> 0 | J7: 應付賬款 | M7: ='2409費用明細憑證'!E33 -> 0
A8: 45541 | B8: 6525 | C8: 3250 | D8: 1050 | E8: 80 | F8: 0 | G8: ='2409費用明細憑證'!E8 -> 2221 | H8: =(B8-D8-E8-F8-G8-C8) -> -76 | J8: 流動現金 | M8: =SUM(M3:M6)+L7 -> 66261
A9: 45542 | B9: 6235 | C9: 4750 | D9: 1300 | E9: 195 | F9: 0 | G9: ='2409費用明細憑證'!E9 -> 0 | H9: =(B9-D9-E9-F9-G9-C9) -> -10 | J9: 營運預備金 | M9: 6000
A10: 45543 | B10: 5680 | C10: 5345 | D10: 335 | E10: 0 | F10: 0 | G10: ='2409費用明細憑證'!E10 -> 0 | H10: =(B10-D10-E10-F10-G10-C10) -> 0 | J10: 現金總計 | M10: =SUM(M8:M9) -> 72261
A11: 45544 | B11: 6625 | C11: 5460 | D11: 575 | E11: 125 | F11: 0 | G11: ='2409費用明細憑證'!E11 -> 8095 | H11: =(B11-D11-E11-F11-G11-C11)+7565 -> -65 | K11: 18、21、22、25
A12: 45545 | B12: 6330 | C12: 5040 | D12: 205 | E12: 880 | F12: 0 | G12: ='2409費用明細憑證'!E12 -> 0 | H12: =(B12-D12-E12-F12-G12-C12) -> 205
A13: 45546 | B13: 6735 | C13: 5645 | D13: 515 | E13: 45 | F13: 0 | G13: ='2409費用明細憑證'!E13 -> 530 | H13: =(B13-D13-E13-F13-G13-C13) -> 0 | J13: 當日損益
A14: 45547 | B14: 6590 | C14: 5600 | D14: 280 | E14: 480 | F14: 225 | G14: ='2409費用明細憑證'!E14 -> 14290 | H14: =(B14-D14-E14-F14-G14-C14)+10440+3850 -> 5 | J14: 紅字→多錢
A15: 45548 | B15: 5795 | C15: 4015 | D15: 605 | E15: 455 | F15: 0 | G15: ='2409費用明細憑證'!E15 -> 530 | H15: =(B15-D15-E15-F15-G15-C15) -> 190 | J15: 黑字→少錢
A16: 45549 | B16: 4620 | C16: 4045 | D16: 575 | E16: 0 | F16: 0 | G16: ='2409費用明細憑證'!E16 -> 0 | H16: =(B16-D16-E16-F16-G16-C16) -> 0
A17: 45550 | B17: 5975 | C17: 5290 | D17: 625 | E17: 140 | F17: 0 | G17: ='2409費用明細憑證'!E17 -> 0 | H17: =(B17-D17-E17-F17-G17-C17) -> -80
A18: 45551 | B18: 4045 | C18: 2690 | D18: 560 | E18: 0 | F18: 0 | G18: ='2409費用明細憑證'!E18 -> 60530 | H18: =(B18-D18-E18-F18-G18-C18)+60000 -> 265
A19: 45552 | B19: 5185 | C19: 5009 | D19: 140 | E19: 0 | F19: 0 | G19: ='2409費用明細憑證'!E19 -> 36 | H19: =(B19-D19-E19-F19-G19-C19) -> 0
A20: 45553 | B20: 4750 | C20: 3900 | D20: 295 | E20: 165 | F20: 0 | G20: ='2409費用明細憑證'!E20 -> 530 | H20: =(B20-D20-E20-F20-G20-C20) -> -140
A21: 45554 | B21: 6315 | C21: 6050 | D21: 555 | E21: 0 | G21: ='2409費用明細憑證'!E21 -> 0 | H21: =(B21-D21-E21-F21-G21-C21) -> -290
A22: 45555 | B22: 5670 | C22: 4515 | D22: 475 | E22: 0 | F22: 150 | G22: ='2409費用明細憑證'!E22 -> 1168 | H22: =(B22-D22-E22-F22-G22-C22)+550+88 -> 0
A23: 45556 | B23: 4565 | C23: 4000 | D23: 960 | E23: 255 | F23: 0 | G23: ='2409費用明細憑證'!E23 -> 0 | H23: =(B23-D23-E23-F23-G23-C23) -> -650
A24: 45557 | B24: 4340 | C24: 4130 | D24: 210 | E24: 0 | F24: 175 | G24: ='2409費用明細憑證'!E24 -> 0 | H24: =(B24-D24-E24-F24-G24-C24) -> -175
A25: 45558 | B25: 5760 | C25: 2887 | D25: 865 | E25: 540 | F25: 170 | G25: ='2409費用明細憑證'!E25 -> 3191 | H25: =(B25-D25-E25-F25-G25-C25)+1893 -> 0
A26: 45559 | B26: 6015 | C26: 5320 | D26: 500 | E26: 220 | F26: 0 | G26: ='2409費用明細憑證'!E26 -> 0 | H26: =(B26-D26-E26-F26-G26-C26) -> -25
A27: 45560 | B27: 4605 | C27: 3705 | D27: 270 | E27: 100 | F27: 0 | G27: ='2409費用明細憑證'!E27 -> 530 | H27: =(B27-D27-E27-F27-G27-C27) -> 0
A28: 45561 | B28: 5350 | C28: 4645 | D28: 140 | E28: 65 | F28: 0 | G28: ='2409費用明細憑證'!E28 -> 500 | H28: =(B28-D28-E28-F28-G28-C28) -> 0
A29: 45562 | B29: 5420 | C29: 4500 | D29: 400 | E29: 65 | F29: 0 | G29: ='2409費用明細憑證'!E29 -> 530 | H29: =(B29-D29-E29-F29-G29-C29) -> -75
A30: 45563 | B30: 8010 | C30: 7025 | D30: 500 | E30: 65 | F30: 120 | G30: ='2409費用明細憑證'!E30 -> 300 | H30: =(B30-D30-E30-F30-G30-C30) -> 0
A31: 45564 | B31: 6885 | C31: 5570 | D31: 1315 | E31: 0 | F31: 0 | G31: ='2409費用明細憑證'!E31 -> 0 | H31: =(B31-D31-E31-F31-G31-C31) -> 0
A32: 45565 | B32: =6960+440 -> 7400 | C32: =3620 -> 3620 | D32: 670 | E32: 145 | F32: 0 | G32: ='2409費用明細憑證'!E32 -> 18941 | H32: =(B32-D32-E32-F32-G32-C32)+6216+12165 -> 2405
A33: 項目 | B33: 月營業額 | C33: 費用總額 | D33: 毛利 | F33: 帳面餘絀 | G33: 每股可分淨額
A34: 小計 | B34: =SUM(B3:B32) -> 180958 | C34: =SUM(G3:G32) -> 115317 | D34: =B34-C34 -> 65641 | F34: =SUM(H3:H32) -> 1492 | G34: =M8/3 -> 22087

Sheet 2409費用明細憑證
A1: 聊閣咖啡重新店支出費用明細
A2: 費用明細表 | B2: 食材成本 | C2: 固定成本 | D2: 變動成本 | E2: 費用小計 | F2: 項目明細 | G2: 支付憑證
A3: 45536 | E3: =SUM(B3:D3) -> 0 | G3: 2409憑證
A4: 45537 | B4: 795 | E4: =SUM(B4:D4) -> 795 | F4: 鮮奶 795
A5: 45538 | E5: =SUM(B5:D5) -> 0
A6: 45539 | B6: 530 | E6: =SUM(B6:D6) -> 530 | F6: 鮮奶 530
A7: 45540 | B7: 2070 | E7: =SUM(B7:D7) -> 2070 | F7: 8月開元帳單 2070
A8: 45541 | B8: =950+530+741 -> 2221 | E8: =SUM(B8:D8) -> 2221 | F8: 鮮奶 530 巧克力醬 950 麵包 741
A9: 45542 | E9: =SUM(B9:D9) -> 0
A10: 45543 | E10: =SUM(B10:D10) -> 0
A11: 45544 | B11: =530+7565 -> 8095 | E11: =SUM(B11:D11) -> 8095 | F11: 鮮奶 530 糖漿、奶精 7565
A12: 45545 | E12: =SUM(B12:D12) -> 0
A13: 45546 | B13: 530 | E13: =SUM(B13:D13) -> 530 | F13: 鮮奶 530
A14: 45547 | B14: 10440 | D14: 3850 | E14: =SUM(B14:D14) -> 14290 | F14: 咖啡豆 10440 杯子、衛生紙 3850
A15: 45548 | B15: 530 | E15: =SUM(B15:D15) -> 530 | F15: 鮮奶 530
A16: 45549 | E16: =SUM(B16:D16) -> 0
A17: 45550 | E17: =SUM(B17:D17) -> 0
A18: 45551 | B18: 530 | C18: 60000 | E18: =SUM(B18:D18) -> 60530 | F18: 鮮奶 530 房租 60000
A19: 45552 | B19: 36 | E19: =SUM(B19:D19) -> 36 | F19: 糖 36
A20: 45553 | B20: 530 | E20: =SUM(B20:D20) -> 530 | F20: 鮮奶 530
A21: 45554 | E21: =SUM(B21:D21) -> 0
A22: 45555 | B22: 530 | D22: =550+88 -> 638 | E22: =SUM(B22:D22) -> 1168 | F22: 水費 550 鮮奶 530 電話費88
A23: 45556 | E23: =SUM(B23:D23) -> 0
A24: 45557 | E24: =SUM(B24:D24) -> 0
A25: 45558 | B25: 530 | D25: =768+1893 -> 2661 | E25: =SUM(B25:D25) -> 3191 | F25: 鮮奶 530 網路費 768 營業稅 1893
A26: 45559 | E26: =SUM(B26:D26) -> 0
A27: 45560 | B27: 530 | E27: =SUM(B27:D27) -> 530 | F27: 鮮奶 530
A28: 45561 | B28: 500 | E28: =SUM(B28:D28) -> 500 | F28: 話梅 500
A29: 45562 | B29: 530 | E29: =SUM(B29:D29) -> 530 | F29: 鮮奶 530
A30: 45563 | D30: 300 | E30: =SUM(B30:D30) -> 300 | F30: 蓋子 300
A31: 45564 | E31: =SUM(B31:D31) -> 0
A32: 45565 | B32: 530 | D32: =4700+1516+30+12165 -> 18411 | E32: =SUM(B32:D32) -> 18941 | F32: 鮮奶 530 咖啡豆 12165 淨水器 6216 匯費 30
A33: 未結應付賬款 | E33: =SUM(B33:D33) -> 0
A34: 小計 | B34: =SUM(B4:B32) -> 29457 | C34: =SUM(C3:C32) -> 60000 | D34: =SUM(D3:D32) -> 25860 | E34: =SUM(E3:E32) -> 115317
B37: 咖啡豆10850
B38: 茶葉7000

Sheet 2408現金日記帳
A1: 聊閣咖啡重新店日記帳
A2: 日期 | B2: 營業收入 | C2: 現金收入 | D2: linepay | E2: 街口支付 | F2: 點點付 | G2: 營業費用 | H2: 當日損益 | K2: 保管金額 | L2: 現金收支 | M2: 現金餘額 | N2: 溢領金額
A3: 45505 | B3: 4520 | C3: 3610 | D3: 480 | E3: 440 | F3: 0 | G3: ='2408費用明細憑證 '!E3 -> 0 | H3: =(B3-D3-E3-F3-G3-C3) -> -10 | J3: 吳献堂 | K3: =C3+C4+C8+C6+C7+C10+C13+C11+C14+C15+C19+C18+C21+C22+C24+C25+C27+C28+C29+C31+C33 -> 100780 | L3: =16273+3500+23000+7000+10850+2000 -> 62623 | M3: =K3-L3 -> 38157 | N3: =M3-G35 -> 21016.333
A4: 45506 | B4: 7255 | C4: 5700 | D4: 380 | E4: 250 | F4: 0 | G4: ='2408費用明細憑證 '!E4 -> 0 | H4: =(B4-D4-E4-F4-G4-C4) -> 925 | J4: 江政隆 | K4: =C5+C9+C12+C16+C17+C20+C23+C26+C30+C32 -> 52364 | L4: =68+2250+11215+800+2050+250+23784+169+1180+2490+4851 -> 49107 | M4: =K4-L4 -> 3257 | N4: =M4+M6-G35 -> -5875.6667
A5: 45507 | B5: 5785 | C5: 5100 | D5: 695 | E5: 185 | F5: 0 | G5: ='2408費用明細憑證 '!E5 -> 68 | H5: =(B5-D5-E5-F5-G5-C5)+68 -> -195 | J5: 林權松 | K5: 2000 | M5: =K5-L5 -> 2000 | N5: =M5-G35 -> -15140.667
A6: 45508 | B6: 4285 | C6: 3450 | D6: 865 | E6: 65 | F6: 130 | G6: ='2408費用明細憑證 '!E6 -> 0 | H6: =(B6-D6-E6-F6-G6-C6) -> -225 | J6: 銀行存款 | K6: =13216+8008 -> 21224 | L6: 13216 | M6: =K6-L6 -> 8008
A7: 45509 | B7: 5650 | C7: 4990 | D7: 515 | E7: 265 | F7: 95 | G7: ='2408費用明細憑證 '!E7 -> 0 | H7: =(B7-D7-E7-F7-G7-C7) -> -215 | J7: 應付賬款 | M7: ='2408費用明細憑證 '!E34 -> 2070
A8: 45510 | B8: 3650 | C8: 3050 | D8: 385 | E8: 235 | F8: 0 | G8: ='2408費用明細憑證 '!E8 -> 0 | H8: =(B8-D8-E8-F8-G8-C8) -> -20 | J8: 流動現金 | M8: =SUM(M3:M6)+L7 -> 51422
A9: 45511 | B9: 7460 | C9: 6156 | D9: 585 | E9: 90 | F9: 0 | G9: ='2408費用明細憑證 '!E9 -> 13995 | H9: =(B9-D9-E9-F9-G9-C9)+13465 -> 99 | J9: 營運預備金 | M9: 6000
A10: 45512 | B10: 5715 | C10: 4700 | D10: 865 | E10: 255 | F10: 0 | G10: ='2408費用明細憑證 '!E10 -> 0 | H10: =(B10-D10-E10-F10-G10-C10) -> -105 | J10: 現金總計 | M10: =SUM(M8:M9) -> 57422
A11: 45513 | B11: 4585 | C11: 4100 | D11: 335 | E11: 225 | F11: 0 | G11: ='2408費用明細憑證 '!E11 -> 0 | H11: =(B11-D11-E11-F11-G11-C11) -> -75
A12: 45514 | B12: 7010 | C12: 5460 | D12: 710 | E12: 455 | F12: 385 | G12: ='2408費用明細憑證 '!E12 -> 0 | H12: =(B12-D12-E12-F12-G12-C12) -> 0
A13: 45515 | B13: 4780 | C13: 3720 | D13: 750 | E13: 50 | F13: 0 | G13: ='2408費用明細憑證 '!E13 -> 270 | H13: =(B13-D13-E13-F13-G13-C13) -> -10 | J13: 當日損益
A14: 45516 | B14: 6450 | C14: 5110 | D14: 380 | E14: 225 | F14: 0 | G14: ='2408費用明細憑證 '!E14 -> 530 | H14: =(B14-D14-E14-F14-G14-C14) -> 205 | J14: 紅字→多錢
A15: 45517 | B15: 7115 | C15: 5100 | D15: 560 | E15: 65 | F15: 90 | G15: ='2408費用明細憑證 '!E15 -> 21285 | H15: =(B15-D15-E15-F15-G15-C15)+16273+3500+800 -> 588 | J15: 黑字→少錢
A16: 45518 | B16: 6290 | C16: 4755 | D16: 555 | E16: 0 | F16: 200 | G16: ='2408費用明細憑證 '!E16 -> 2830 | H16: =(B16-D16-E16-F16-G16-C16)+2050 -> 0
A17: 45519 | B17: 7548 | C17: 7048 | D17: 420 | E17: 80 | F17: 0 | G17: ='2408費用明細憑證 '!E17 -> 60000 | H17: =(B17-D17-E17-F17-G17-C17)+60000 -> 0
A18: 45520 | B18: 6010 | C18: 4900 | D18: 410 | E18: 85 | F18: 0 | G18: ='2408費用明細憑證 '!E18 -> 530 | H18: =(B18-D18-E18-F18-G18-C18) -> 85
A19: 45521 | B19: 6055 | C19: 5600 | D19: 330 | E19: 60 | F19: 70 | G19: ='2408費用明細憑證 '!E19 -> 0 | H19: =(B19-D19-E19-F19-G19-C19) -> -5
A20: 45522 | B20: 6750 | C20: 6370 | D20: 130 | E20: 250 | F20: 0 | G20: ='2408費用明細憑證 '!E20 -> 169 | H20: =(B20-D20-E20-F20-G20-C20)+169 -> 0
A21: 45523 | B21: 6215 | C21: 5700 | D21: 510 | E21: 165 | F21: 0 | G21: ='2408費用明細憑證 '!E21 -> 0 | H21: =(B21-D21-E21-F21-G21-C21) -> -160
A22: 45524 | B22: 5410 | C22: 4700 | D22: 525 | E22: 145 | F22: 0 | G22: ='2408費用明細憑證 '!E22 -> 0 | H22: =(B22-D22-E22-F22-G22-C22) -> 40
A23: 45525 | B23: 5510 | C23: 4200 | D23: 210 | E23: 95 | F23: 210 | G23: ='2408費用明細憑證 '!E23 -> 18645 | H23: =(B23-D23-E23-F23-G23-C23)+10850+7000 -> 0
A24: 45526 | B24: 5190 | C24: 2650 | D24: 453 | E24: 85 | F24: 55 | G24: ='2408費用明細憑證 '!E24 -> 1947 | H24: =(B24-D24-E24-F24-G24-C24) -> 0
A25: 45527 | B25: 8186 | C25: 7050 | D25: 480 | E25: 185 | F25: 0 | G25: ='2408費用明細憑證 '!E25 -> 0 | H25: =(B25-D25-E25-F25-G25-C25) -> 471
A26: 45528 | B26: 5046 | C26: 4060 | D26: 505 | E26: 200 | F26: 281 | G26: ='2408費用明細憑證 '!E26 -> 0 | H26: =(B26-D26-E26-F26-G26-C26) -> 0
A27: 45529 | B27: 8660 | C27: 7200 | D27: 1495 | E27: 210 | F27: 0 | G27: ='2408費用明細憑證 '!E27 -> 0 | H27: =(B27-D27-E27-F27-G27-C27) -> -245
A28: 45530 | B28: 5960 | C28: 4400 | D28: 400 | E28: 120 | F28: 85 | G28: ='2408費用明細憑證 '!E28 -> 2130 | H28: =(B28-D28-E28-F28-G28-C28)+1180 -> 5
A29: 45531 | B29: 4540 | C29: 4210 | D29: 410 | E29: 0 | F29: 0 | G29: ='2408費用明細憑證 '!E29 -> 0 | H29: =(B29-D29-E29-F29-G29-C29) -> -80
A30: 45532 | B30: 5780 | C30: 4035 | D30: 415 | E30: 535 | F30: 0 | G30: ='2408費用明細憑證 '!E30 -> 3285 | H30: =(B30-D30-E30-F30-G30-C30)+2490 -> 0
A31: 45533 | B31: 6480 | C31: 5710 | D31: 575 | E31: 155 | F31: 0 | G31: ='2408費用明細憑證 '!E31 -> 0 | H31: =(B31-D31-E31-F31-G31-C31) -> 40
A32: 45534 | B32: 6840 | C32: 5180 | D32: 1530 | E32: 0 | F32: 130 | G32: ='2408費用明細憑證 '!E32 -> 4851 | H32: =(B32-D32-E32-F32-G32-C32)+4851 -> 0
A33: 45535 | B33: 5565 | C33: 5130 | D33: 465 | E33: 0 | F33: 0 | G33: ='2408費用明細憑證 '!E33 -> 0 | H33: =(B33-D33-E33-F33-G33-C33) -> -30
A34: 項目 | B34: 月營業額 | C34: 費用總額 | D34: 毛利 | F34: 帳面餘絀 | G34: 每股可分淨額
A35: 小計 | B35: =SUM(B3:B33) -> 186295 | C35: =SUM(G3:G33) -> 130535 | D35: =B35-C35 -> 55760 | F35: =SUM(H3:H33) -> 1083 | G35: =M8/3 -> 17140.667

Sheet 2408費用明細憑證 
A1: 聊閣咖啡重新店支出費用明細
A2: 費用明細表 | B2: 食材成本 | C2: 固定成本 | D2: 變動成本 | E2: 費用小計 | F2: 項目明細 | G2: 支付憑證
A3: 45505 | E3: =SUM(B3:D3) -> 0 | G3: 8月憑證
A4: 45506 | E4: =SUM(B4:D4) -> 0
A5: 45507 | D5: 68 | E5: =SUM(B5:D5) -> 68 | F5: 濾杯 68
A6: 45508 | E6: =SUM(B6:D6) -> 0
A7: 45509 | E7: =SUM(B7:D7) -> 0
A8: 45510 | E8: =SUM(B8:D8) -> 0
A9: 45511 | B9: =2250+11215+530 -> 13995 | E9: =SUM(B9:D9) -> 13995 | F9: 7月開元 2250 咖啡豆 11215 鮮奶530
A10: 45512
A11: 45513 | E11: =SUM(B11:D11) -> 0
A12: 45514 | E12: =SUM(B12:D12) -> 0
A13: 45515 | B13: 270 | E13: =SUM(B13:D13) -> 270 | F13: 鮮奶 270
A14: 45516 | B14: 530 | E14: =SUM(B14:D14) -> 530 | F14: 鮮奶530
A15: 45517 | B15: 712 | D15: =16273+3500+800 -> 20573 | E15: =SUM(B15:D15) -> 21285 | F15: 電費 16273 冷氣 3500 厚片貝果 712 封口膜 800
A16: 45518 | B16: 530 | D16: =2050+250 -> 2300 | E16: =SUM(B16:D16) -> 2830 | F16: 鮮奶 530 咖啡器具(整粉器) 2050 電池 250
A17: 45519 | C17: 60000 | E17: =SUM(B17:D17) -> 60000 | F17: 房租 60000
A18: 45520 | B18: 530 | E18: =SUM(B18:D18) -> 530 | F18: 鮮奶 530
A19: 45521 | E19: =SUM(B19:D19) -> 0
A20: 45522 | D20: 169 | E20: =SUM(B20:D20) -> 169 | F20: 咖啡器具(不鏽鋼冰塊) 169
A21: 45523 | E21: =SUM(B21:D21) -> 0
A22: 45524 | E22: =SUM(B22:D22) -> 0
A23: 45525 | B23: =795+10850+7000 -> 18645 | E23: =SUM(B23:D23) -> 18645 | F23: 鮮奶 795 咖啡豆10850 茶葉7000
A24: 45526 | D24: =1847+100 -> 1947 | E24: =SUM(B24:D24) -> 1947 | F24: 咖啡濾紙 1847 空盒 100
A25: 45527 | E25: =SUM(B25:D25) -> 0
A26: 45528 | E26: =SUM(B26:D26) -> 0
A27: 45529 | E27: =SUM(B27:D27) -> 0
A28: 45530 | B28: 1180 | D28: 950 | E28: =SUM(B28:D28) -> 2130 | F28: 杯子 1180 皮包 950
A29: 45531 | E29: =SUM(B29:D29) -> 0
A30: 45532 | B30: =795+2490 -> 3285 | E30: =SUM(B30:D30) -> 3285 | F30: 鮮奶 795 咖啡豆 2490
A31: 45533 | E31: =SUM(B31:D31) -> 0
A32: 45534 | D32: 4851 | E32: =SUM(B32:D32) -> 4851 | F32: 營業稅 4851
A33: 45535 | E33: =SUM(B33:D33) -> 0
A34: 未結應付賬款 | B34: =500+500+1070 -> 2070 | E34: =SUM(B34:D34) -> 2070 | F34: 0806 鮮奶 500 0813 1070 0820 鮮奶 500
A35: 小計 | B35: =SUM(B3:B33) -> 39677 | C35: =SUM(C3:C33) -> 60000 | D35: =SUM(D3:D33) -> 30858 | E35: =SUM(E3:E33) -> 130535

Sheet 2407現金日記帳
A1: 聊閣咖啡重新店日記帳
A2: 日期 | B2: 營業收入 | C2: 現金收入 | D2: linepay | E2: 街口支付 | F2: 點點付 | G2: 營業費用 | H2: 當日損益 | K2: 保管金額 | L2: 現金收支 | M2: 現金餘額 | N2: 溢領金額
A3: 45474 | B3: 4320 | C3: 2300 | D3: 0 | E3: 85 | F3: 0 | G3: ='2407費用明細憑證'!E3 -> 1988 | H3: =(B3-D3-E3-F3-G3-C3) -> -53 | J3: 吳献堂 | K3: =C3+C6+C10+C13+C14+C8+C11+C16+C20+C17-700+C21+C22-3500+C23+C27+C25+C28-1500+C29-4000+C31+C32 -> 73810 | L3: 34900 | M3: =K3-L3 -> 38910 | N3: =M3-G35 -> 17240.333
A4: 45475 | B4: 10640 | C4: 8810 | D4: 1515 | E4: 210 | F4: 0 | G4: ='2407費用明細憑證'!E4 -> 0 | H4: =(B4-D4-E4-F4-G4-C4) -> 105 | J4: 江政隆 | K4: =C4+C5+C7+C9+C12+C15+C18+C19+700+C24+C26+C30+C33 -> 65540 | L4: =2200+12700+1900+3750+710+14085+7565+463+12840+2200 -> 58413 | M4: =K4-L4 -> 7127 | N4: =M4+M6-G35 -> -4570.6667
A5: 45476 | B5: 7750 | C5: 6560 | D5: 85 | E5: 80 | F5: 245 | G5: ='2407費用明細憑證'!E5 -> 2730 | H5: =(B5-D5-E5-F5-G5-C5)+2200 -> 250 | J5: 林權松 | K5: =3500+1500+4000 -> 9000 | M5: =K5-L5 -> 9000 | N5: =M5-G35 -> -12669.667
A6: 45477 | B6: 6565 | C6: 5850 | D6: 645 | E6: 190 | F6: 0 | G6: ='2407費用明細憑證'!E6 -> 0 | H6: =(B6-D6-E6-F6-G6-C6) -> -120 | J6: 銀行存款 | K6: =11015+9972 -> 20987 | L6: 11015 | M6: =K6-L6 -> 9972
A7: 45478 | B7: 5700 | C7: 4543 | D7: 435 | E7: 55 | F7: 80 | G7: ='2407費用明細憑證'!E7 -> 530 | H7: =(B7-D7-E7-F7-G7-C7) -> 57 | J7: 應付賬款 | M7: ='2407費用明細憑證'!E34 -> 2250
A8: 45479 | B8: 6405 | C8: 5490 | D8: 560 | E8: 140 | F8: 515 | G8: ='2407費用明細憑證'!E8 -> 0 | H8: =(B8-D8-E8-F8-G8-C8) -> -300 | J8: 流動現金 | M8: =SUM(M3:M6)+L7 -> 65009
A9: 45480 | B9: 5860 | C9: 5740 | D9: 65 | E9: 0 | F9: 130 | G9: ='2407費用明細憑證'!E9 -> 0 | H9: =(B9-D9-E9-F9-G9-C9) -> -75 | J9: 營運預備金 | M9: 6000
A10: 45481 | B10: 4705 | C10: 3610 | D10: 500 | E10: 65 | F10: 0 | G10: ='2407費用明細憑證'!E10 -> 530 | H10: =(B10-D10-E10-F10-G10-C10) -> 0 | J10: 現金總計 | M10: =SUM(M8:M9) -> 71009
A11: 45482 | B11: 3985 | C11: 3020 | D11: 395 | E11: 0 | F11: 0 | G11: ='2407費用明細憑證'!E11 -> 712 | H11: =(B11-D11-E11-F11-G11-C11) -> -142
A12: 45483 | B12: 5385 | C12: 5043 | D12: 235 | E12: 65 | F12: 0 | G12: ='2407費用明細憑證'!E12 -> 0 | H12: =(B12-D12-E12-F12-G12-C12) -> 42
A13: 45484 | B13: 6215 | C13: 5005 | D13: 420 | E13: 495 | F13: 0 | G13: ='2407費用明細憑證'!E13 -> 15200 | H13: =(B13-D13-E13-F13-G13-C13)+12700+1900 -> -305
A14: 45485 | B14: 5980 | C14: 4720 | D14: 665 | E14: 115 | F14: 0 | G14: ='2407費用明細憑證'!E14 -> 4280 | H14: =(B14-D14-E14-F14-G14-C14)+3750 -> -50
A15: 45486 | B15: 6165 | C15: 5535 | D15: 595 | E15: 155 | F15: 0 | G15: ='2407費用明細憑證'!E15 -> 710 | H15: =(B15-D15-E15-F15-G15-C15)+710 -> -120
A16: 45487 | B16: 8331 | C16: 6080 | D16: 480 | E16: 210 | F16: 530 | G16: ='2407費用明細憑證'!E16 -> 0 | H16: =(B16-D16-E16-F16-G16-C16) -> 1031
A17: 45488 | B17: 4960 | C17: 4100 | D17: 615 | E17: 0 | F17: 0 | G17: ='2407費用明細憑證'!E17 -> 60530 | H17: =(B17-D17-E17-F17-G17-C17)+60000 -> -285
A18: 45489 | B18: 6655 | C18: 5810 | D18: 245 | E18: 125 | F18: 100 | G18: ='2407費用明細憑證'!E18 -> 0 | H18: =(B18-D18-E18-F18-G18-C18) -> 375
A19: 45490 | B19: 7060 | C19: 5173 | D19: 490 | E19: 910 | F19: 0 | G19: ='2407費用明細憑證'!E19 -> 530 | H19: =(B19-D19-E19-F19-G19-C19) -> -43
A20: 45491 | B20: 4130 | C20: 4025 | D20: 690 | E20: 45 | F20: 0 | G20: ='2407費用明細憑證'!E20 -> 7565 | H20: =(B20-D20-E20-F20-G20-C20)+7565 -> -630
A21: 45492 | B21: 5420 | C21: 3950 | D21: 765 | E21: 50 | F21: 0 | G21: ='2407費用明細憑證'!E21 -> 768 | H21: =(B21-D21-E21-F21-G21-C21) -> -113
A22: 45493 | B22: 9195 | C22: =2220+3500 -> 5720 | D22: 980 | E22: 0 | F22: 170 | G22: ='2407費用明細憑證'!E22 -> 2190 | H22: =(B22-D22-E22-F22-G22-C22) -> 135
A23: 45494 | B23: 5305 | C23: 4600 | D23: 475 | E23: 185 | F23: 65 | G23: ='2407費用明細憑證'!E23 -> 0 | H23: =(B23-D23-E23-F23-G23-C23) -> -20
A24: 45495 | B24: 4923 | C24: 4161 | D24: 198 | E24: 330 | F24: 0 | G24: ='2407費用明細憑證'!E24 -> 13833 | H24: =(B24-D24-E24-F24-G24-C24)+463+12840 -> -296
A25: 45496 | B25: 4310 | C25: 4100 | D25: 120 | E25: 120 | F25: 0 | G25: ='2407費用明細憑證'!E25 -> 0 | H25: =(B25-D25-E25-F25-G25-C25) -> -30
A26: 45497 | B26: 4090 | C26: 2700 | D26: 660 | E26: 150 | F26: 0 | G26: ='2407費用明細憑證'!E26 -> 530 | H26: =(B26-D26-E26-F26-G26-C26) -> 50
A27: 45498 | B27: 3320 | C27: 3010 | D27: 55 | E27: 65 | F27: 225 | G27: ='2407費用明細憑證'!E27 -> 0 | H27: =(B27-D27-E27-F27-G27-C27) -> -35
A28: 45499 | B28: 4995 | C28: 4050 | D28: 340 | E28: 70 | F28: 0 | G28: ='2407費用明細憑證'!E28 -> 530 | H28: =(B28-D28-E28-F28-G28-C28) -> 5
A29: 45500 | B29: 7040 | C29: =3050+4000 -> 7050 | D29: 435 | E29: 0 | F29: 110 | G29: ='2407費用明細憑證'!E29 -> 0 | H29: =(B29-D29-E29-F29-G29-C29) -> -555
A30: 45501 | B30: 7145 | C30: =4800-500 -> 4300 | D30: 1105 | E30: 0 | F30: 110 | G30: ='2407費用明細憑證'!E30 -> 1180 | H30: =(B30-D30-E30-F30-G30-C30) -> 450
A31: 45502 | B31: 5430 | C31: 3230 | D31: 455 | E31: 0 | F31: 335 | G31: ='2407費用明細憑證'!E31 -> 2920 | H31: =(B31-D31-E31-F31-G31-C31)+2200 -> 690
A32: 45503 | B32: 6270 | C32: 3600 | D32: 800 | E32: 185 | F32: 0 | G32: ='2407費用明細憑證'!E32 -> 1720 | H32: =(B32-D32-E32-F32-G32-C32) -> -35
A33: 45504 | B33: 6025 | C33: 6465 | D33: 480 | E33: 80 | F33: 0 | G33: ='2407費用明細憑證'!E33 -> 530 | H33: =(B33-D33-E33-F33-G33-C33) -> -1530
A34: 項目 | B34: 月營業額 | C34: 費用總額 | D34: 毛利 | F34: 帳面餘絀 | G34: 每股可分淨額
A35: 小計 | B35: =SUM(B3:B33) -> 184279 | C35: =SUM(G3:G33) -> 119506 | D35: =B35-C35 -> 64773 | F35: =SUM(H3:H33) -> -1547 | G35: =M8/3 -> 21669.667

Sheet 2407費用明細憑證
A1: 聊閣咖啡重新店支出費用明細
A2: 費用明細表 | B2: 食材成本 | C2: 固定成本 | D2: 變動成本 | E2: 費用小計 | F2: 項目明細 | G2: 支付憑證
A3: 45474 | D3: =1200+288+500 -> 1988 | E3: =SUM(B3:D3) -> 1988 | F3: 修理馬桶1200 材料288 裝冰袋子 500
A4: 45475 | E4: =SUM(B4:D4) -> 0
A5: 45476 | B5: 530 | D5: 2200 | E5: =SUM(B5:D5) -> 2730 | F5: 鮮奶 530 杯子2200 | G5: 0703光泉 | H5: 0703易達豐
A6: 45477 | E6: =SUM(B6:D6) -> 0
A7: 45478 | B7: 530 | E7: =SUM(B7:D7) -> 530 | F7: 鮮奶 530 | G7: 0705光泉
A8: 45479 | E8: =SUM(B8:D8) -> 0
A9: 45480 | E9: =SUM(B9:D9) -> 0
A10: 45481 | B10: 530 | E10: =SUM(B10:D10) -> 530 | F10: 鮮奶 530 | G10: 0708光泉
A11: 45482 | B11: 712 | E11: =SUM(B11:D11) -> 712 | F11: 厚片、貝果 712 | G11: 0709親民
A12: 45483 | E12: =SUM(B12:D12) -> 0
A13: 45484 | B13: 12700 | D13: =1900+600 -> 2500 | E13: =SUM(B13:D13) -> 15200 | F13: 咖啡豆 12700 衛生紙、吸管 1900 衛生紙 600 | G13: 0711易達豐 | H13: 0711光泉
A14: 45485 | B14: =3750+530 -> 4280 | E14: =SUM(B14:D14) -> 4280 | F14: 檸檬、金桔 3750 鮮奶 530 | G14: 0712光泉 | H14: 0712檸檬
A15: 45486 | B15: 710 | E15: =SUM(B15:D15) -> 710 | F15: 奶油 710 | G15: 0713奶油
A16: 45487 | E16: =SUM(B16:D16) -> 0
A17: 45488 | B17: 530 | C17: 60000 | E17: =SUM(B17:D17) -> 60530 | F17: 房租 60000 鮮奶 530 | G17: 0715房租1 | H17: 0715房租2
A18: 45489 | E18: =SUM(B18:D18) -> 0
A19: 45490 | B19: 530 | E19: =SUM(B19:D19) -> 530 | F19: 鮮奶 530 | G19: 0717光泉
A20: 45491 | B20: 7565 | E20: =SUM(B20:D20) -> 7565 | F20: 奶精、果糖 7565 | G20: 0718品皇
A21: 45492 | D21: 768 | E21: =SUM(B21:D21) -> 768 | F21: 網路 768 | G21: 0719網路
A22: 45493 | B22: 1590 | D22: 600 | E22: =SUM(B22:D22) -> 2190 | F22: su盤 600 抹茶粉 1590 | G22: 720
A23: 45494 | E23: =SUM(B23:D23) -> 0
A24: 45495 | B24: =530+12840 -> 13370 | D24: 463 | E24: =SUM(B24:D24) -> 13833 | F24: 水費 463 鮮奶 530 咖啡豆 12840 | G24: 0722水費 | H24: 0722光泉 | I24: 0722咖啡豆
A25: 45496 | E25: =SUM(B25:D25) -> 0
A26: 45497 | B26: 530 | E26: =SUM(B26:D26) -> 530 | F26: 鮮奶 530 | G26: 0724光泉
A27: 45498 | E27: =SUM(B27:D27) -> 0
A28: 45499 | B28: 530 | E28: =SUM(B28:D28) -> 530 | F28: 鮮奶 530
A29: 45500 | E29: =SUM(B29:D29) -> 0
A30: 45501 | B30: 72 | D30: =175+933 -> 1108 | E30: =SUM(B30:D30) -> 1180 | F30: 量杯 175 電話網路費933 糖72 | G30: 0728量杯 | H30: 0728電話網路
A31: 45502 | D31: =2200+720 -> 2920 | E31: =SUM(B31:D31) -> 2920 | F31: 杯子 2200 紙袋 720 | G31: 0729紙袋 | H31: 0729易達豐
A32: 45503 | B32: =712+890 -> 1602 | D32: 118 | E32: =SUM(B32:D32) -> 1720 | F32: 厚片、貝果 712 垃圾袋 118 花生醬 890 | G32: 0730親民 | H32: 0730垃圾袋
A33: 45504 | B33: 530 | E33: =SUM(B33:D33) -> 530 | F33: 鮮奶 530
A34: 未結應付賬款 | B34: =500+750+500+500 -> 2250 | E34: =SUM(B34:D34) -> 2250 | F34: 0702鮮奶 500 0709鮮奶 500 0716鮮奶、奶蓋 750 0726鮮奶 500 | G34: 0702開元 | H34: 716
A35: 小計 | B35: =SUM(B3:B33) -> 46841 | C35: =SUM(C3:C33) -> 60000 | D35: =SUM(D3:D33) -> 12665 | E35: =SUM(E3:E33) -> 119506

Sheet 2406現金日記帳
A1: 聊閣咖啡重新店日記帳
A2: 日期 | B2: 營業收入 | C2: 現金收入 | D2: linepay | E2: 街口支付 | F2: 點點付 | G2: 營業費用 | H2: 當日損益 | K2: 保管金額 | L2: 現金收支 | M2: 現金餘額 | N2: 溢領金額
A3: 45444 | B3: 7595 | C3: 7222 | D3: 315 | E3: 50 | F3: 65 | G3: ='2406費用明細憑證'!E3 -> 0 | H3: =(B3-D3-E3-F3-G3-C3) -> -57 | J3: 吳献堂 | K3: =C4+C5+C6+C8+C9+C11+C13+C15+C16+C19+C22+C23+C25+C26+C27+C29+C31+C32 -> 88731 | L3: =9153+30000+5000 -> 44153 | M3: =K3-L3 -> 44578 | N3: =M3-G34 -> 19432.333
A4: 45445 | B4: 5955 | C4: 5400 | D4: 520 | E4: 0 | F4: 0 | G4: ='2406費用明細憑證'!E4 -> 0 | H4: =(B4-D4-E4-F4-G4-C4) -> 35 | J4: 江政隆 | K4: =C3+C7+C10+C12+C14+C17+C18+C21+C24+C28+C30 -> 70803 | L4: =2774+427+30000+13790+999+10680+3570 -> 62240 | M4: =K4-L4 -> 8563 | N4: =M4+M6-G34 -> 713.33333
A5: 45446 | B5: 6115 | C5: 4400 | D5: 685 | E5: 125 | F5: 0 | G5: ='2406費用明細憑證'!E5 -> 957 | H5: =(B5-D5-E5-F5-G5-C5) -> -52 | J5: 林權松 | K5: 5000 | M5: =K5-L5 -> 5000 | N5: =M5-G35 -> 5000
A6: 45447 | B6: 5710 | C6: 5100 | D6: 620 | E6: 185 | F6: 0 | G6: ='2406費用明細憑證'!E6 -> 0 | H6: =(B6-D6-E6-F6-G6-C6) -> -195 | J6: 銀行存款 | K6: 17296 | M6: =K6-L6 -> 17296
A7: 45448 | B7: 5680 | C7: 5091 | D7: 365 | E7: 255 | F7: 0 | G7: ='2406費用明細憑證'!E7 -> 2774 | H7: =(B7-D7-E7-F7-G7-C7)+2774 -> -31 | J7: 應付賬款 | M7: ='2406費用明細憑證'!E33 -> 3570
A8: 45449 | B8: 5435 | C8: 1600 | D8: 425 | E8: 135 | F8: 0 | G8: ='2406費用明細憑證'!E8 -> 3650 | H8: =(B8-D8-E8-F8-G8-C8) -> -375 | J8: 流動現金 | M8: =SUM(M3:M6)+L7 -> 75437
A9: 45450 | B9: 6930 | C9: 5300 | D9: 770 | E9: 525 | F9: 0 | G9: ='2406費用明細憑證'!E9 -> 530 | H9: =(B9-D9-E9-F9-G9-C9) -> -195 | J9: 營運預備金 | M9: 15000
A10: 45451 | B10: 7408 | C10: 6952 | D10: 185 | E10: 150 | F10: 370 | G10: ='2406費用明細憑證'!E10 -> 0 | H10: =(B10-D10-E10-F10-G10-C10) -> -249 | J10: 現金總計 | M10: =SUM(M8:M9) -> 90437
A11: 45452 | B11: 5195 | C11: 4810 | D11: 490 | E11: 215 | F11: 320 | G11: ='2406費用明細憑證'!E11 -> 0 | H11: =(B11-D11-E11-F11-G11-C11) -> -640
A12: 45453 | B12: 7023 | C12: 5137 | D12: 315 | E12: 90 | F12: =250+210 -> 460 | G12: ='2406費用明細憑證'!E12 -> 1030 | H12: =(B12-D12-E12-F12-G12-C12) -> -9
A13: 45454 | B13: 6135 | C13: 3550 | D13: 870 | E13: 305 | F13: 0 | G13: ='2406費用明細憑證'!E13 -> 1180 | H13: =(B13-D13-E13-F13-G13-C13) -> 230
A14: 45455 | B14: =5558+110 -> 5668 | C14: 5298 | D14: 420 | E14: 45 | F14: 0 | G14: ='2406費用明細憑證'!E14 -> 0 | H14: =(B14-D14-E14-F14-G14-C14) -> -95
A15: 45456 | B15: 5860 | C15: 6200 | D15: 335 | E15: 175 | F15: 220 | G15: ='2406費用明細憑證'!E15 -> 0 | H15: =(B15-D15-E15-F15-G15-C15) -> -1070
A16: 45457 | B16: 7720 | C16: 6600 | D16: 1005 | E16: 0 | F16: 0 | G16: ='2406費用明細憑證'!E16 -> 10110 | H16: =(B16-D16-E16-F16-G16-C16)+9580 -> -415
A17: 45458 | B17: 8200 | C17: 8023 | D17: 500 | E17: 100 | F17: =165+173 -> 338 | G17: ='2406費用明細憑證'!E17 -> 60000 | H17: =(B17-D17-E17-F17-G17-C17)+60000 -> -761
A18: 45459 | B18: 9300 | C18: 7650 | D18: 760 | E18: 215 | F18: 320 | G18: ='2406費用明細憑證'!E18 -> 376 | H18: =(B18-D18-E18-F18-G18-C18) -> -21
A19: 45460 | B19: 4840 | C19: 4510 | D19: 420 | E19: 150 | F19: 0 | G19: ='2406費用明細憑證'!E19 -> 15319 | H19: =(B19-D19-E19-F19-G19-C19)+14789 -> -770
A20: 45461 | B20: 6830 | C20: 5220 | D20: 660 | E20: 210 | F20: 0 | G20: ='2406費用明細憑證'!E20 -> 1000 | H20: =(B20-D20-E20-F20-G20-C20) -> -260
A21: 45462 | B21: 7388 | C21: 6663 | D21: 215 | E21: 85 | F21: 0 | G21: ='2406費用明細憑證'!E21 -> 530 | H21: =(B21-D21-E21-F21-G21-C21) -> -105
A22: 45463 | B22: 8490 | C22: 6500 | D22: 1145 | E22: 110 | F22: 0 | G22: ='2406費用明細憑證'!E22 -> 764 | H22: =(B22-D22-E22-F22-G22-C22) -> -29
A23: 45464 | B23: 5490 | C23: 3700 | D23: 835 | E23: 320 | F23: 185 | G23: ='2406費用明細憑證'!E23 -> 530 | H23: =(B23-D23-E23-F23-G23-C23) -> -80
A24: 45465 | B24: 7359 | C24: 6335 | D24: 435 | E24: 255 | F24: =110+224 -> 334 | G24: ='2406費用明細憑證'!E24 -> 1000 | H24: =(B24-D24-E24-F24-G24-C24) -> -1000
A25: 45466 | B25: 5705 | C25: 4700 | D25: 550 | E25: 220 | F25: 0 | G25: ='2406費用明細憑證'!E25 -> 0 | H25: =(B25-D25-E25-F25-G25-C25) -> 235
A26: 45467 | B26: 5955 | C26: 4300 | D26: 810 | E26: 160 | F26: 225 | G26: ='2406費用明細憑證'!E26 -> 530 | H26: =(B26-D26-E26-F26-G26-C26) -> -70
A27: 45468 | B27: 5905 | C27: 5300 | D27: 560 | E27: 95 | F27: 0 | G27: ='2406費用明細憑證'!E27 -> 200 | H27: =(B27-D27-E27-F27-G27-C27) -> -250
A28: 45469 | B28: 7340 | C28: 6220 | D28: 385 | E28: 205 | F28: 0 | G28: ='2406費用明細憑證'!E28 -> 530 | H28: =(B28-D28-E28-F28-G28-C28) -> 0
A29: 45470 | B29: 5360 | C29: 5010 | D29: 380 | E29: 65 | F29: 0 | G29: ='2406費用明細憑證'!E29 -> 10680 | H29: =(B29-D29-E29-F29-G29-C29)+10680 -> -95
A30: 45471 | B30: 7080 | C30: 6212 | D30: 485 | E30: 0 | F30: 65 | G30: ='2406費用明細憑證'!E30 -> 530 | H30: =(B30-D30-E30-F30-G30-C30) -> -212
A31: 45472 | B31: 5811 | C31: 5551 | D31: 65 | E31: 85 | F31: 110 | G31: ='2406費用明細憑證'!E31 -> 0 | H31: =(B31-D31-E31-F31-G31-C31) -> 0
A32: 45473 | B32: 6783 | C32: 6200 | D32: 150 | E32: 0 | F32: 0 | G32: ='2406費用明細憑證'!E32 -> 150 | H32: =(B32-D32-E32-F32-G32-C32) -> 283
A33: 項目 | B33: 月營業額 | C33: 費用總額 | D33: 毛利 | F33: 帳面餘絀 | G33: 每股可分淨額
A34: 小計 | B34: =SUM(B3:B32) -> 196265 | C34: =SUM(G3:G32) -> 112370 | D34: =B34-C34 -> 83895 | F34: =SUM(H3:H32) -> -6253 | G34: =M8/3 -> 25145.667

Sheet 2406費用明細憑證
A1: 聊閣咖啡重新店支出費用明細
A2: 費用明細表 | B2: 食材成本 | C2: 固定成本 | D2: 變動成本 | E2: 費用小計 | F2: 項目明細 | G2: 支付憑證
A3: 45444 | E3: =SUM(B3:D3) -> 0
A4: 45445 | E4: =SUM(B4:D4) -> 0
A5: 45446 | B5: 530 | D5: 427 | E5: =SUM(B5:D5) -> 957 | F5: 鮮奶 530 水費 427 | G5: 0603光泉
A6: 45447 | E6: =SUM(B6:D6) -> 0
A7: 45448 | D7: =2774 -> 2774 | E7: =SUM(B7:D7) -> 2774 | F7: 營業器具一批詳如備註 | G7: 0605濾杯、濾布 | H7: 0605電動攪拌棒 | I7: 0605量杯 | J7: 0605拉花杯 | K7: 0605不鏽鋼濾紙、濾紙 | L7: 06051磅咖啡袋
A8: 45449 | D8: =1250+2400 -> 3650 | E8: =SUM(B8:D8) -> 3650 | F8: 中熱杯 1250 果糖機修理 2400 | G8: 0606易達豐 | H8: 0604果糖機修理
A9: 45450 | B9: 530 | E9: =SUM(B9:D9) -> 530 | F9: 鮮奶 530 | G9: 0607光泉
A10: 45451 | E10: =SUM(B10:D10) -> 0
A11: 45452 | E11: =SUM(B11:D11) -> 0
A12: 45453 | B12: =500+530 -> 1030 | E12: =SUM(B12:D12) -> 1030 | F12: 話梅 500 鮮奶 530 | G12: 0610光泉
A13: 45454 | B13: 1180 | E13: =SUM(B13:D13) -> 1180 | F13: 大杯透明杯 1180 | G13: 0611易達豐
A14: 45455 | E14: =SUM(B14:D14) -> 0
A15: 45456 | E15: =SUM(B15:D15) -> 0
A16: 45457 | B16: 530 | D16: =427+9153 -> 9580 | E16: =SUM(B16:D16) -> 10110 | F16: 鮮奶 530 水費 427 電費 9153 | G16: 0614光泉 | H16: 0614水費 | I16: 0614電費
A17: 45458 | C17: 60000 | E17: =SUM(B17:D17) -> 60000 | F17: 房租 60000 | G17: 0615房租(1) | H17: 0615房租(2)
A18: 45459 | B18: =36+170 -> 206 | D18: =150+20 -> 170 | E18: =SUM(B18:D18) -> 376 | F18: 糖 36 洗手乳 150 菜瓜布 20 鮮奶 170 | G18: 0616全聯 | H18: 0616蝦皮 | I18: 0616菜瓜布
A19: 45460 | B19: =13790+530 -> 14320 | D19: 999 | E19: =SUM(B19:D19) -> 15319 | F19: 咖啡豆 13790 藍芽音響 999 鮮奶 530 | G19: 0617 咖啡豆 | H19: 0617光泉
A20: 45461 | B20: 150 | D20: 850 | E20: =SUM(B20:D20) -> 1000 | F20: 電話、網路 850 糖 150 | G20: 0618電話、網路
A21: 45462 | B21: 530 | E21: =SUM(B21:D21) -> 530 | F21: 鮮奶 530 | G21: 0619光泉
A22: 45463 | B22: 764 | E22: =SUM(B22:D22) -> 764 | F22: 厚片、貝果 764 | G22: 0620親民
A23: 45464 | B23: 530 | E23: =SUM(B23:D23) -> 530 | F23: 鮮奶 530 | G23: 0621光泉
A24: 45465 | D24: 1000 | E24: =SUM(B24:D24) -> 1000 | F24: 營業損失 1000 | G24: 0622營業損失
A25: 45466 | E25: =SUM(B25:D25) -> 0
A26: 45467 | B26: 530 | E26: =SUM(B26:D26) -> 530 | F26: 鮮奶 530 | G26: 0624光泉
A27: 45468 | D27: 200 | E27: =SUM(B27:D27) -> 200 | F27: USB 200
A28: 45469 | B28: 530 | E28: =SUM(B28:D28) -> 530 | F28: 鮮奶 530 | G28: 0626光泉
A29: 45470 | B29: 10680 | E29: =SUM(B29:D29) -> 10680 | F29: 蔓越莓、巧克力 10680 | G29: 0627伂橙
A30: 45471 | B30: 530 | E30: =SUM(B30:D30) -> 530 | F30: 鮮奶 530 | G30: 0628光泉
A31: 45472 | E31: =SUM(B31:D31) -> 0
A32: 45473 | D32: 150 | E32: =SUM(B32:D32) -> 150 | F32: 垃圾袋 150
A33: 未結應付賬款 | B33: 3570 | E33: =SUM(B33:D33) -> 3570 | F33: 0604 鮮奶、奶蓋 750 0611 鮮奶、紅茶 820 0618鮮奶 750 0625鮮奶 500 | G33: 0604開元 | H33: 0611開元 | I33: 0618開元 | J33: 0625開元
A34: 小計 | B34: =SUM(B3:B33) -> 36140 | C34: =SUM(C3:C33) -> 60000 | D34: =SUM(D3:D33) -> 19800 | E34: =SUM(E3:E33) -> 115940

Sheet 2405現金日記帳
A1: 聊閣咖啡重新店日記帳
A2: 日期 | B2: 營業收入 | C2: 現金收入 | D2: linepay | E2: 街口支付 | F2: 點點付 | G2: 營業費用 | H2: 當日損益 | K2: 保管金額 | L2: 現金收支 | M2: 現金餘額 | N2: 溢領金額
