Workbook

Sheet 終版
A1: 【 遠雄未來家-芬蘭區 】成 本 分 析 試 算 表(202戶) | O1: 製 表 日 期
O2: 111.09.05
A4: NO | B4: 項 目 | D4: 內 部 成 本 統 計 | M4: 實際報價金額 (G) | N4: 差異金額(J)【H-G】 | O4: 備 註
D5: 薪資成本(A) | E5: 級距 | F5: 勞保費用(B) | G5: 健保費用（C） | H5: 6%勞退金(D) | I5: 年節及未休假獎金(E) | J5: 管消費用9%(F) | K5: 利潤5% | L5: 應報價金額(H)【A+B+C+D+E+F】
A6: 1 | B6: 社區經理 | D6: 55000 | E6: 30 | F6: =IF($B6="清潔員",0,IF(D6=0,0,IF(D6<20008,D6*0.08,INDEX(勞健保清單!$B$3:$B$32,$E6,1)))) -> 3526.6 | G6: =IF($B6="清潔員",0,IF(D6=0,0,IF(D6<20008,D6*0.08,INDEX(勞健保清單!$C$3:$C$32,$E6,1)))) -> 2074.9873 | H6: =IF($B6="清潔員",0,IF(D6=0,0,IF(D6<20008,D6*0.08,INDEX(勞健保清單!$D$3:$D$32,$E6,1)))) -> 2748 | I6: =IF($B6="清潔員",0,IF(D6=0,0,(((D6/30*7)+300+500+6000)/12))) -> 1636.1111 | J6: =IF($B6="清潔員",0,IF(D6=0,0,M6*0.09)) -> 6750 | K6: =IF($B6="清潔員",0,IF(D6=0,0,M6*0.05)) -> 3750 | L6: =IF(D6=0,0,SUM(D6,F6,G6,H6,I6,J6,K6)) -> 75485.698 | M6: 75000 | N6: =SUM(M6-L6) -> -485.69843
A7: 3 | B7: 日安管 | D7: 43000 | E7: =IF(D7>72800,19,IF(D7<20008,1,MATCH(D7,勞健保清單!$A$3:$A$32,1)+1)) -> 29 | F7: =IF($B7="清潔員",0,IF(D7=0,0,IF(D7<20008,D7*0.08,INDEX(勞健保清單!$B$3:$B$32,$E7,1)))) -> 3380.3 | G7: =IF($B7="清潔員",0,IF(D7=0,0,IF(D7<20008,D7*0.08,INDEX(勞健保清單!$C$3:$C$32,$E7,1)))) -> 1988.9071 | H7: =IF($B7="清潔員",0,IF(D7=0,0,IF(D7<20008,D7*0.08,INDEX(勞健保清單!$D$3:$D$32,$E7,1)))) -> 2634 | I7: =IF($B7="清潔員",0,IF(D7=0,0,(((D7/30*7)+300+500+6000)/12))) -> 1402.7778 | J7: =IF($B7="清潔員",0,IF(D7=0,0,M7*0.09)) -> 4950 | K7: =IF($B7="清潔員",0,IF(D7=0,0,M7*0.05)) -> 2750 | L7: =IF(D7=0,0,SUM(D7,F7,G7,H7,I7,J7,K7)) -> 60105.985 | M7: 55000 | N7: =SUM(M7-L7) -> -5105.9848
A8: 4 | B8: 夜安管 | D8: 43000 | E8: =IF(D8>72800,19,IF(D8<20008,1,MATCH(D8,勞健保清單!$A$3:$A$32,1)+1)) -> 29 | F8: =IF($B8="清潔員",0,IF(D8=0,0,IF(D8<20008,D8*0.08,INDEX(勞健保清單!$B$3:$B$32,$E8,1)))) -> 3380.3 | G8: =IF($B8="清潔員",0,IF(D8=0,0,IF(D8<20008,D8*0.08,INDEX(勞健保清單!$C$3:$C$32,$E8,1)))) -> 1988.9071 | H8: =IF($B8="清潔員",0,IF(D8=0,0,IF(D8<20008,D8*0.08,INDEX(勞健保清單!$D$3:$D$32,$E8,1)))) -> 2634 | I8: =IF($B8="清潔員",0,IF(D8=0,0,(((D8/30*7)+300+500+6000)/12))) -> 1402.7778 | J8: =IF($B8="清潔員",0,IF(D8=0,0,M8*0.09)) -> 4950 | K8: =IF($B8="清潔員",0,IF(D8=0,0,M8*0.05)) -> 2750 | L8: =IF(D8=0,0,SUM(D8,F8,G8,H8,I8,J8,K8)) -> 60105.985 | M8: 55000 | N8: =SUM(M8-L8) -> -5105.9848
A9: 4 | B9: 機動安管 | D9: 25000 | E9: =IF(D9>72800,19,IF(D9<20008,1,MATCH(D9,勞健保清單!$A$3:$A$32,1)+1)) -> 17 | F9: =IF($B9="清潔員",0,IF(D9=0,0,IF(D9<20008,D9*0.08,INDEX(勞健保清單!$B$3:$B$32,$E9,1)))) -> 1940.4 | G9: =IF($B9="清潔員",0,IF(D9=0,0,IF(D9<20008,D9*0.08,INDEX(勞健保清單!$C$3:$C$32,$E9,1)))) -> 1141.6961 | H9: =IF($B9="清潔員",0,IF(D9=0,0,IF(D9<20008,D9*0.08,INDEX(勞健保清單!$D$3:$D$32,$E9,1)))) -> 1512 | I9: =IF($B9="清潔員",0,IF(D9=0,0,(((D9/30*7)+300+500+6000)/12))) -> 1052.7778 | J9: =IF($B9="清潔員",0,IF(D9=0,0,M9*0.09)) -> 4950 | K9: =IF($B9="清潔員",0,IF(D9=0,0,M9*0.05)) -> 2750 | L9: =IF(D9=0,0,SUM(D9,F9,G9,H9,I9,J9,K9)) -> 38346.874 | M9: 55000 | N9: =SUM(M9-L9) -> 16653.126
A10: 5 | B10: 保潔1 | D10: 35000 | E10: =IF(D10>72800,19,IF(D10<20008,1,MATCH(D10,勞健保清單!$A$3:$A$32,1)+1)) -> 25 | F10: =IF($B10="清潔員",0,IF(D10=0,0,IF(D10<20008,D10*0.08,INDEX(勞健保清單!$B$3:$B$32,$E10,1)))) -> 2795.1 | G10: =IF($B10="清潔員",0,IF(D10=0,0,IF(D10<20008,D10*0.08,INDEX(勞健保清單!$C$3:$C$32,$E10,1)))) -> 1644.586 | H10: =IF($B10="清潔員",0,IF(D10=0,0,IF(D10<20008,D10*0.08,INDEX(勞健保清單!$D$3:$D$32,$E10,1)))) -> 2178 | I10: =IF($B10="清潔員",0,IF(D10=0,0,(((D10/30*7)+300+500+6000)/12))) -> 1247.2222 | J10: =IF($B10="清潔員",0,IF(D10=0,0,M10*0.09)) -> 4050 | K10: =IF($B10="清潔員",0,IF(D10=0,0,M10*0.05)) -> 2250 | L10: =IF(D10=0,0,SUM(D10,F10,G10,H10,I10,J10,K10)) -> 49164.908 | M10: 45000 | N10: =SUM(M10-L10) -> -4164.9082
A11: 6 | B11: 保潔2 | D11: 35000 | E11: =IF(D11>72800,19,IF(D11<20008,1,MATCH(D11,勞健保清單!$A$3:$A$32,1)+1)) -> 25 | F11: =IF($B11="清潔員",0,IF(D11=0,0,IF(D11<20008,D11*0.08,INDEX(勞健保清單!$B$3:$B$32,$E11,1)))) -> 2795.1 | G11: =IF($B11="清潔員",0,IF(D11=0,0,IF(D11<20008,D11*0.08,INDEX(勞健保清單!$C$3:$C$32,$E11,1)))) -> 1644.586 | H11: =IF($B11="清潔員",0,IF(D11=0,0,IF(D11<20008,D11*0.08,INDEX(勞健保清單!$D$3:$D$32,$E11,1)))) -> 2178 | I11: =IF($B11="清潔員",0,IF(D11=0,0,(((D11/30*7)+300+500+6000)/12))) -> 1247.2222 | J11: =IF($B11="清潔員",0,IF(D11=0,0,M11*0.09)) -> 4050 | K11: =IF($B11="清潔員",0,IF(D11=0,0,M11*0.05)) -> 2250 | L11: =IF(D11=0,0,SUM(D11,F11,G11,H11,I11,J11,K11)) -> 49164.908 | M11: 45000 | N11: =SUM(M11-L11) -> -4164.9082
B12: 回饋事項 | D12: =I25/12 -> 9166.6667 | L12: =D12 -> 9166.6667 | N12: =SUM(M12-L12) -> -9166.6667
A13: 合計金額 | D13: =SUM(D6:D12) -> 245166.67 | E13: =SUM(E6:E12) -> 155 | F13: =SUM(F6:F12) -> 17817.8 | G13: =SUM(G6:G12) -> 10483.67 | H13: =SUM(H6:H12) -> 13884 | I13: =SUM(I6:I12) -> 7988.8889 | J13: =SUM(J6:J12) -> 29700 | K13: =SUM(K6:K12) -> 16500 | ... N13: =SUM(N6:N12) -> -11541.025
A14: 稅 金 (5%) | M14: =SUM(M13*0.05) -> 16500
A15: 總 合 計 金 額 | M15: =SUM(M13:M14) -> 346500
A16: 說 明 | D16: 1 | E16: 本案未稅價格： | G16: =M13 -> 330000 | H16: 含稅價格： | I16: =M15 -> 346500
D17: 2 | E17: 合約期間管委會有人力增減調配權、人員核准後不得更換、如屬自願離職不在此限
D18: 3
A19: 回 饋 明 細 | C19: NO | D19: 項 目 | G19: 單 價 | H19: 次 數 | I19: 合 計 金 額 | J19: 注 意 事 項 備 註 欄
C20: 1 | D20: 每年社區環境消毒及清洗水塔2次 | G20: 8000 | H20: 2 | I20: =G20*H20 -> 16000
C21: 2 | D21: 每年高壓清洗外圍地坪2次 | G21: 4000 | H21: 2 | I21: =G21*H21 -> 8000
C22: 3 | D22: 大廳拋光晶化 | G22: 25000 | H22: 2 | I22: =G22*H22 -> 50000
C23: 4 | D23: 影印事務機費用 | G23: 2000 | H23: 12 | I23: =G23*H23 -> 24000 | J23: 額度：1000/黑白,100彩色 超過費用社區承擔
C24: 5 | D24: 區權會會場裝備及人力支援 | G24: 6000 | H24: 2 | I24: =G24*H24 -> 12000
C25: 總 合 計 費 用 金 額 | I25: =SUM(I20:I24) -> 110000
A27: 批 示 | K27: 董事長 | M27: 副總經理 | O27: 管 理 部
O29: 經理 | P29: 承 辦
P31: 1110905 簡弘益

Sheet 勞健保清單
A1: (本表需依勞健保局資料更新, 此檔僅為範例) | B1: 0.11 | C1: 0.0469 | D1: 0.06
A2: 薪資 | B2: 勞保費(公司) | C2: 健保費(公司) | D2: 勞退6%
A3: 11100 | B3: =SUM(A3*$B$1*0.7) -> 854.7 | C3: 1046.5547 | D3: =SUM(A3*$D$1) -> 666 | F3: 1
A4: 12540 | B4: =SUM(A4*$B$1*0.7) -> 965.58 | C4: 1046.5547 | D4: =SUM(A4*$D$1) -> 752.4 | F4: 2
A5: 13500 | B5: =SUM(A5*$B$1*0.7) -> 1039.5 | C5: 1046.5547 | D5: =SUM(A5*$D$1) -> 810 | F5: 3
A6: 15840 | B6: =SUM(A6*$B$1*0.7) -> 1219.68 | C6: 1046.5547 | D6: =SUM(A6*$D$1) -> 950.4 | F6: 4
A7: 16500 | B7: =SUM(A7*$B$1*0.7) -> 1270.5 | C7: 1046.5547 | D7: =SUM(A7*$D$1) -> 990 | F7: 5
A8: 17280 | B8: =SUM(A8*$B$1*0.7) -> 1330.56 | C8: 1046.5547 | D8: =SUM(A8*$D$1) -> 1036.8 | F8: 6
A9: 17880 | B9: =SUM(A9*$B$1*0.7) -> 1376.76 | C9: 1046.5547 | D9: =SUM(A9*$D$1) -> 1072.8 | F9: 7
A10: 19047 | B10: =SUM(A10*$B$1*0.7) -> 1466.619 | C10: 1046.5547 | D10: =SUM(A10*$D$1) -> 1142.82 | F10: 8
A11: 20008 | B11: =SUM(A11*$B$1*0.7) -> 1540.616 | C11: 1046.5547 | D11: =SUM(A11*$D$1) -> 1200.48 | F11: 9
A12: 20100 | B12: =SUM(A12*$B$1*0.7) -> 1547.7 | C12: 1046.5547 | D12: =SUM(A12*$D$1) -> 1206 | F12: 10
A13: 21000 | B13: =SUM(A13*$B$1*0.7) -> 1617 | C13: 1046.5547 | D13: =SUM(A13*$D$1) -> 1260 | F13: 11
A14: 21900 | B14: =SUM(A14*$B$1*0.7) -> 1686.3 | C14: 1046.5547 | D14: =SUM(A14*$D$1) -> 1314 | F14: 12
... A16: 22800 | B16: =SUM(A16*$B$1*0.7) -> 1755.6 | C16: 1046.5547 | D16: =SUM(A16*$D$1) -> 1368 | F16: 14
A17: 23100 | B17: =SUM(A17*$B$1*0.7) -> 1778.7 | C17: =SUM(A17*$C$1*1.61*0.6) -> 1046.5547 | D17: =SUM(A17*$D$1) -> 1386 | F17: 15
A18: 24000 | B18: =SUM(A18*$B$1*0.7) -> 1848 | C18: =SUM(A18*$C$1*1.61*0.6) -> 1087.3296 | D18: =SUM(A18*$D$1) -> 1440 | F18: 16
A19: 25200 | B19: =SUM(A19*$B$1*0.7) -> 1940.4 | C19: =SUM(A19*$C$1*1.61*0.6) -> 1141.6961 | D19: =SUM(A19*$D$1) -> 1512 | F19: 17
A20: 26400 | B20: =SUM(A20*$B$1*0.7) -> 2032.8 | C20: =SUM(A20*$C$1*1.61*0.6) -> 1196.0626 | D20: =SUM(A20*$D$1) -> 1584 | F20: 18
A21: 27600 | B21: =SUM(A21*$B$1*0.7) -> 2125.2 | C21: =SUM(A21*$C$1*1.61*0.6) -> 1250.429 | D21: =SUM(A21*$D$1) -> 1656 | F21: 19
A22: 28800 | B22: =SUM(A22*$B$1*0.7) -> 2217.6 | C22: =SUM(A22*$C$1*1.61*0.6) -> 1304.7955 | D22: =SUM(A22*$D$1) -> 1728 | F22: 20
A23: 30300 | B23: =SUM(A23*$B$1*0.7) -> 2333.1 | C23: =SUM(A23*$C$1*1.61*0.6) -> 1372.7536 | D23: =SUM(A23*$D$1) -> 1818 | F23: 21
A24: 31800 | B24: =SUM(A24*$B$1*0.7) -> 2448.6 | C24: =SUM(A24*$C$1*1.61*0.6) -> 1440.7117 | D24: =SUM(A24*$D$1) -> 1908 | F24: 22
A25: 33300 | B25: =SUM(A25*$B$1*0.7) -> 2564.1 | C25: =SUM(A25*$C$1*1.61*0.6) -> 1508.6698 | D25: =SUM(A25*$D$1) -> 1998 | F25: 23
A26: 34800 | B26: =SUM(A26*$B$1*0.7) -> 2679.6 | C26: =SUM(A26*$C$1*1.61*0.6) -> 1576.6279 | D26: =SUM(A26*$D$1) -> 2088 | F26: 24
A27: 36300 | B27: =SUM(A27*$B$1*0.7) -> 2795.1 | C27: =SUM(A27*$C$1*1.61*0.6) -> 1644.586 | D27: =SUM(A27*$D$1) -> 2178 | F27: 25
A28: 38200 | B28: =SUM(A28*$B$1*0.7) -> 2941.4 | C28: =SUM(A28*$C$1*1.61*0.6) -> 1730.6663 | D28: =SUM(A28*$D$1) -> 2292 | F28: 26
... A32: 45800 | B32: =SUM(A32*$B$1*0.7) -> 3526.6 | C32: =SUM(A32*$C$1*1.61*0.6) -> 2074.9873 | D32: =SUM(A32*$D$1) -> 2748 | F32: 30
A33: 48200 | B33: =SUM($B$44*$B$1*0.7) -> 3526.6 | C33: =SUM(A33*$C$1*1.61*0.6) -> 2183.7203 | D33: =SUM(A33*$D$1) -> 2892 | F33: 31
A34: 50600 | B34: =SUM($B$44*$B$1*0.7) -> 3526.6 | C34: =SUM(A34*$C$1*1.61*0.6) -> 2292.4532 | D34: =SUM(A34*$D$1) -> 3036 | F34: 32
A35: 53000 | B35: =SUM($B$44*$B$1*0.7) -> 3526.6 | C35: =SUM(A35*$C$1*1.61*0.6) -> 2401.1862 | D35: =SUM(A35*$D$1) -> 3180 | F35: 33
A36: 55400 | B36: =SUM($B$44*$B$1*0.7) -> 3526.6 | C36: =SUM(A36*$C$1*1.61*0.6) -> 2509.9192 | D36: =SUM(A36*$D$1) -> 3324 | F36: 34
A37: 57800 | B37: =SUM($B$44*$B$1*0.7) -> 3526.6 | C37: =SUM(A37*$C$1*1.61*0.6) -> 2618.6521 | D37: =SUM(A37*$D$1) -> 3468 | F37: 35
A38: 60800 | B38: =SUM($B$44*$B$1*0.7) -> 3526.6 | C38: =SUM(A38*$C$1*1.61*0.6) -> 2754.5683 | D38: =SUM(A38*$D$1) -> 3648 | F38: 36
A39: 63800 | B39: =SUM($B$44*$B$1*0.7) -> 3526.6 | C39: =SUM(A39*$C$1*1.61*0.6) -> 2890.4845 | D39: =SUM(A39*$D$1) -> 3828 | F39: 37
A40: 66800 | B40: =SUM($B$44*$B$1*0.7) -> 3526.6 | C40: =SUM(A40*$C$1*1.61*0.6) -> 3026.4007 | D40: =SUM(A40*$D$1) -> 4008 | F40: 38
A41: 69800 | B41: =SUM($B$44*$B$1*0.7) -> 3526.6 | C41: =SUM(A41*$C$1*1.61*0.6) -> 3162.3169 | D41: =SUM(A41*$D$1) -> 4188 | F41: 39
A42: 72800 | B42: =SUM($B$44*$B$1*0.7) -> 3526.6 | C42: =SUM(A42*$C$1*1.61*0.6) -> 3298.2331 | D42: =SUM(A42*$D$1) -> 4368 | F42: 40
A44: 勞保最高 | B44: 45800 | C44: 健保最低 | D44: 23100

Sheet 員工薪資
A2: 合計薪資 | B2: 22700 | C2: =INDEX([1]勞健保清單!B3:B21,B4,1) -> 1596 | D2: =INDEX([1]勞健保清單!C3:C21,B4,1) -> 1088 | E2: =INDEX([1]勞健保清單!D3:D21,B4,1) -> 1368
A4: 等級 | B4: =MATCH(B2,[1]勞健保清單!A3:A21,1)+1 -> 5 | C4: match(B9,'勞健保清單'!A3:A65535,1) | D4: 由於 27500 < 30000 但 27500 > 25000 , 所以在此案例中是等級 2
A5: 勞保負擔(公司) | B5: =INDEX([1]勞健保清單!B3:B21,B4,1) -> 1596 | C5: index('勞健保清單'!B3:B65535,B11,1)
A6: 健保負擔(公司) | B6: {=INDEX([1]勞健保清單!C3:C21,B4,1)} -> 1088 | C6: index('勞健保清單'!C3:C65535,B11,1)
A7: 勞退6% | B7: {=INDEX([1]勞健保清單!D3:D21,B4,1)} -> 1368

Sheet 報價單
A1: 齊家公寓大廈管理維護有限公司 HOME START PROPERTY MANAGEMENT COMPANY Tel.(02)2312-3588 Fax.(02)2312-3900 地址：台北市中正區中華路一段39號14F
E2: 報價單 | J2: 日期： | K2: =TODAY() -> 45293
B4: 客戶名稱： | D4: 玄泰ONE | H4: 聯絡人:黃家駒02-26009931
B5: 案場地址： | D5: 林口區民有街52號 | P5: 62000
B6: 服務報價 | D6: 職務 | F6: 工作內容 | H6: 人力 | I6: 單價 | J6: 總價 | P6: 43000
D7: =終版!B6 -> 社區經理 | F7: 物業管理維護 | H7: 1 | I7: =終版!M6 -> 75000 | J7: =I7*H7 -> 75000 | P7: 43000
D8: 安管 | F8: 安全維護 | H8: 3 | I8: =終版!#REF! -> #REF! | J8: =I8*H8 -> #REF! | P8: 43000
D9: 保潔 | F9: 環境維護 | H9: 2 | I9: =終版!M10 -> 45000 | J9: =I9*H9 -> 90000 | P9: 38000
D13: 未稅 | J13: =SUM(J7:J12) -> #REF!
D14: 稅金 | J14: =J13*0.05 -> #REF!
D15: 總計(含稅) | J15: =J13+J14 -> #REF!
B16: 說明 | D16: 1.合約起訖日自109.9.30晚上19:00起至110.9.30晚上19:00止結束。 2.上述報價皆含人員制服、勞健保、團險、訓練等費用。 3.甲方同意於契約期間內，若政府法令調整基本工資或勞健保費率或稅金費率等，依其成本變動，予以等幅調整契約報價)。 4.本報價單有效期限30天。 5.每年社區環境消毒及清洗水塔2次。 6.每年高壓清洗外圍地坪2次。 7.每年中庭景觀水池清洗2次。 8.每年一樓大廳挑高玻璃清潔2次。 9.每年2次請園藝公司整理，另派現場人員2次園藝維護。 10.影印事務機費用。 11.區權會會場裝備及人力支援。
B17: 業主確認章 | H17: 報價確認章
B19: 董事長： 執行長： 協理： 經辦人：1090807

Sheet 工作表1
A1: 長耀里 年度預算預估表(1坪50元)
A2: 一.收入部份:
A3: 編號 | B3: 科目 | D3: 摘要 | E3: 月收入 | F3: 說明 | G3: 次數 | H3: 年度收入 | I3: 備註
A4: 1 | B4: 管理費收入 | D4: 50元/坪 | E4: =5234.7*50 -> 261735 | F4: 50元/坪*總面積5234.7 | G4: 12 | H4: =E4*G4 -> 3140820 | I4: 詳細未知
A5: 2 | B5: 汽車位收入 | D5: 170位/$500/月 | E5: =170*500 -> 85000 | G5: 12 | H5: 0
A6: 3 | B6: 機車位收入 | D6: 157位/$100/月 | E6: =157*100 -> 15700 | G6: 12 | H6: 0
A7: 4 | B7: 腳踏車位收入 | D7: 未定 | E7: 0 | G7: 12 | H7: 0
A8: 5 | B8: 公共基金 | F8: 利息收入 | G8: 12 | H8: =SUM(D8*J8) -> 0 | I8: 年利率 | J8: 0.01
A9: 6 | B9: 其它收入 | G9: 12 | H9: 0 | I9: 施工清潔費……
B10: 月收入(A) | E10: =SUM(E3:E9) -> 362435 | G10: 12 | H10: =+E10*G10 -> 4349220
A11: 二.支出部份:(由社區總預算分配各細項百分比管控社區支出金額)
A12: 編號 | B12: 類別 | C12: 經常性 | J12: 月支出%
C13: 科目 | D13: 摘要 | E13: 單次支出 | F13: 說明 | G13: 次數 | H13: 年度支出 | I13: 平均月支出 | J13: 備註
A14: 1 | B14: 人事行政 | C14: 物業管理&環境清潔 | D14: 社區經理*1=65000 社區秘書*1-50000 安管員*3(1哨)=135000 清潔人員*1=40000 共計290000元 （以上未稅） 共304500元（含稅） | E14: 304500 | G14: 12 | H14: =E14*G14 -> 3654000 | I14: =H14/12 -> 304500 | J14: =I14/I41 -> 0.61479876 | K14: 0.65
A15: 2 | C15: 零用金 | D15: 含電話費/影印費/雜支 | E15: 5000 | G15: 12 | H15: =E15*G15 -> 60000 | I15: =H15/12 -> 5000 | J15: =I15/I41 -> 0.010095218 | K15: 0.04
A16: 3 | C16: 電話費（含ADSL） | E16: 3000 | G16: 12 | H16: =E16*G16 -> 36000 | I16: =H16/12 -> 3000 | J16: =I16/I41 -> 0.0060571307
A17: 4 | C17: 泳池救生員費用 | E17: 0 | G17: 0 | H17: =E17*G17 -> 0 | I17: =H17/12 -> 0 | J17: =I17/I41 -> 0
A18: 5 | C18: copy機影印費用 | E18: 2000 | G18: 12 | H18: =E18*G18 -> 24000 | I18: =H18/12 -> 2000 | J18: =I18/I41 -> 0.0040380871
A19: 6 | B19: 社區活動 | C19: 中元普渡 | E19: 20000 | F19: 包含搭帳棚以及桌椅費用,結束後拆除 | G19: 1 | H19: =E19*G19 -> 20000 | I19: =H19/12 -> 1666.6667 | J19: =I19/I41 -> 0.0033650726
A20: 7 | C20: 元旦party | E20: 5000 | G20: 1 | H20: =E20*G20 -> 5000 | I20: =H20/12 -> 416.66667 | J20: =I20/I41 -> 0.00084126815
A21: 8 | C21: 農曆新年佈置+party | E21: 10000 | G21: 1 | H21: =E21*G21 -> 10000 | I21: =H21/12 -> 833.33333 | J21: =I21/I41 -> 0.0016825363 | K21: 0.04
A22: 9 | C22: X'mas 佈置+party
A23: 10 | C23: 中秋節烤肉(晚會) | E23: 97000 | F23: 每戶餐費預計300元(可要可不要) | G23: 1 | H23: =E23*G23 -> 97000 | I23: =H23/12 -> 8083.3333 | J23: =I23/I41 -> 0.016320602
A24: 11 | B24: 機電維護 | C24: 消防安全檢查及申報 | E24: 30000 | G24: 1 | H24: =E24*G24 -> 30000 | I24: =H24/12 -> 2500 | J24: =I24/I41 -> 0.0050476089 | K24: 0.09
A25: 12 | C25: 機電巡檢 | E25: 10000 | G25: 12 | H25: =E25*G25 -> 120000 | I25: =H25/12 -> 10000 | J25: =I25/I41 -> 0.020190436
A26: 13 | C26: 機電耗材 | D26: 燈管類等 | E26: 10000 | G26: 12 | H26: =E26*G26 -> 120000 | I26: =H26/12 -> 10000 | J26: =I26/I41 -> 0.020190436 | K26: 0.01
A27: 14 | C27: 冷氣保養 | D27: 公共區域 | E27: 50000 | G27: 1 | H27: =E27*G27 -> 50000 | I27: =H27/12 -> 4166.6667 | J27: =I27/I41 -> 0.0084126815
A28: 15 | C28: 游泳池維護費用 | D28: 泳池過濾系統,PH質檢測 | E28: 0 | G28: 12 | H28: =E28*G28 -> 0 | I28: =H28/12 -> 0 | J28: =I28/I41 -> 0
A29: 16 | C29: 電梯保養 | D29: 每月保養一次 | E29: 25000 | F29: 共3部電梯 | G29: 12 | H29: =E29*G29 -> 300000 | I29: =H29/12 -> 25000 | J29: =I29/I41 -> 0.050476089 | K29: 0.05
A30: 17 | B30: 清潔維護 | C30: 清潔消毒與耗材 | D30: 安全梯.消毒 | E30: 5000 | G30: 12 | H30: =E30*G30 -> 60000 | I30: =H30/12 -> 5000 | J30: =I30/I41 -> 0.010095218
A31: 18 | C31: 清洗水塔 | D31: 一年兩次 | E31: 0 | F31: 物業管理公司回饋 | G31: 2 | H31: =E31*G31 -> 0 | I31: =H31/12 -> 0 | J31: =I31/I41 -> 0 | K31: 0.1
A32: 19 | C32: 垃圾清運 | E32: 70000 | G32: 12 | H32: =E32*G32 -> 840000 | I32: =H32/12 -> 70000 | J32: =I32/I41 -> 0.14133305
A33: 20 | C33: 石材保養 | E33: 50000 | F33: 一年一次 | G33: 1 | H33: =E33*G33 -> 50000 | I33: =H33/12 -> 4166.6667 | J33: =I33/I41 -> 0.0084126815
A34: 21 | C34: 園藝 | D34: 含修剪.雜草清除.施肥,植草 | E34: 30000 | F34: 兩個月修剪一次 | G34: 6 | H34: =E34*G34 -> 180000 | I34: =H34/12 -> 15000 | J34: =I34/I41 -> 0.030285653
A35: 22 | C35: 清洗泳池 | E35: 0 | G35: 1 | H35: =E35*G35 -> 0 | I35: =H35/12 -> 0 | J35: =I35/I41 -> 0
A36: 23 | C36: 外牆清洗 | D36: 每三年清洗一次 | E36: 140000 | F36: 預計40萬 | G36: 1 | H36: =E36*G36 -> 140000 | I36: =H36/12 -> 11666.667 | J36: =I36/I41 -> 0.023555508
A37: 24 | C37: 修繕與設備更新準備金 | E37: =E4*0.01 -> 2617.35 | F37: 預留1%社區預備金 | G37: 12 | H37: =E37*G37 -> 31408.2 | I37: =H37/12 -> 2617.35 | J37: =I37/I41 -> 0.0052845436 | K37: 0.05
A38: 25 | B38: 其他 | C38: 公共電費 | E38: 5000 | G38: 12 | H38: =E38*G38 -> 60000 | I38: =H38/12 -> 5000 | J38: =I38/I41 -> 0.010095218 | K38: 0.05
A39: 26 | C39: 公共水費 | E39: 3000 | G39: 12 | H39: =E39*G39 -> 36000 | I39: =H39/12 -> 3000 | J39: =I39/I41 -> 0.0060571307 | K39: 0.01
A40: 27 | C40: 保險 | D40: 公共意外責任險 | E40: 20000 | G40: 1 | H40: =E40*G40 -> 20000 | I40: =H40/12 -> 1666.6667 | J40: =I40/I41 -> 0.0033650726 | K40: 0.06
...
